### Default ###

I1216 15:36:05.136399       1 leaderelection.go:282] successfully renewed lease kube-system/green-k8s-scheduler
I1216 15:36:05.408016       1 scheduling_queue.go:830] About to try and schedule pod default/green-k8s-test-688d6758c6-dmncw
I1216 15:36:05.408666       1 scheduler.go:530] Attempting to schedule pod: default/green-k8s-test-688d6758c6-dmncw
I1216 15:36:05.408898       1 predicates.go:908] Schedule Pod default/green-k8s-test-688d6758c6-dmncw on Node ip-172-20-40-148.ec2.internal is allowed, Node is running only 9 out of 110 Pods.
I1216 15:36:05.409094       1 generic_scheduler.go:667] since alwaysCheckAllPredicates has not been set, the predicate evaluation is short circuited and there are chances of other predicates failing as well.
I1216 15:36:05.409021       1 predicates.go:908] Schedule Pod default/green-k8s-test-688d6758c6-dmncw on Node ip-172-20-58-134.ec2.internal is allowed, Node is running only 2 out of 110 Pods.
I1216 15:36:05.409041       1 predicates.go:908] Schedule Pod default/green-k8s-test-688d6758c6-dmncw on Node ip-172-20-45-201.ec2.internal is allowed, Node is running only 2 out of 110 Pods.
I1216 15:36:05.409058       1 predicates.go:908] Schedule Pod default/green-k8s-test-688d6758c6-dmncw on Node ip-172-20-49-41.ec2.internal is allowed, Node is running only 1 out of 110 Pods.
I1216 15:36:05.409073       1 predicates.go:908] Schedule Pod default/green-k8s-test-688d6758c6-dmncw on Node ip-172-20-61-178.ec2.internal is allowed, Node is running only 3 out of 110 Pods.
I1216 15:36:05.409716       1 resource_allocation.go:84] green-k8s-test-688d6758c6-dmncw -> ip-172-20-58-134.ec2.internal: BalancedResourceAllocation, map of allocatable resources map[cpu:1000 memory:1966559232], map of requested resources map[cpu:300 memory:492830720] ,score 9,
I1216 15:36:05.409905       1 resource_allocation.go:84] green-k8s-test-688d6758c6-dmncw -> ip-172-20-58-134.ec2.internal: LeastResourceAllocation, map of allocatable resources map[cpu:1000 memory:1966559232], map of requested resources map[cpu:300 memory:492830720] ,score 7,
I1216 15:36:05.409836       1 resource_allocation.go:84] green-k8s-test-688d6758c6-dmncw -> ip-172-20-45-201.ec2.internal: BalancedResourceAllocation, map of allocatable resources map[cpu:1000 memory:1966559232], map of requested resources map[cpu:300 memory:492830720] ,score 9,
I1216 15:36:05.410089       1 resource_allocation.go:84] green-k8s-test-688d6758c6-dmncw -> ip-172-20-45-201.ec2.internal: LeastResourceAllocation, map of allocatable resources map[cpu:1000 memory:1966559232], map of requested resources map[cpu:300 memory:492830720] ,score 7,
I1216 15:36:05.409862       1 resource_allocation.go:84] green-k8s-test-688d6758c6-dmncw -> ip-172-20-49-41.ec2.internal: BalancedResourceAllocation, map of allocatable resources map[cpu:1000 memory:1966559232], map of requested resources map[cpu:200 memory:419430400] ,score 9,
I1216 15:36:05.410294       1 resource_allocation.go:84] green-k8s-test-688d6758c6-dmncw -> ip-172-20-49-41.ec2.internal: LeastResourceAllocation, map of allocatable resources map[cpu:1000 memory:1966559232], map of requested resources map[cpu:200 memory:419430400] ,score 7,
I1216 15:36:05.409880       1 resource_allocation.go:84] green-k8s-test-688d6758c6-dmncw -> ip-172-20-61-178.ec2.internal: BalancedResourceAllocation, map of allocatable resources map[cpu:1000 memory:1966559232], map of requested resources map[cpu:320 memory:639631360] ,score 9,
I1216 15:36:05.410484       1 resource_allocation.go:84] green-k8s-test-688d6758c6-dmncw -> ip-172-20-61-178.ec2.internal: LeastResourceAllocation, map of allocatable resources map[cpu:1000 memory:1966559232], map of requested resources map[cpu:320 memory:639631360] ,score 6,
I1216 15:36:05.410674       1 selector_spreading.go:146] green-k8s-test-688d6758c6-dmncw -> ip-172-20-58-134.ec2.internal: SelectorSpreadPriority, Score: (10)
I1216 15:36:05.410805       1 selector_spreading.go:146] green-k8s-test-688d6758c6-dmncw -> ip-172-20-45-201.ec2.internal: SelectorSpreadPriority, Score: (10)
I1216 15:36:05.410886       1 selector_spreading.go:146] green-k8s-test-688d6758c6-dmncw -> ip-172-20-49-41.ec2.internal: SelectorSpreadPriority, Score: (10)
I1216 15:36:05.410974       1 selector_spreading.go:146] green-k8s-test-688d6758c6-dmncw -> ip-172-20-61-178.ec2.internal: SelectorSpreadPriority, Score: (10)
I1216 15:36:05.411049       1 generic_scheduler.go:773] green-k8s-test-688d6758c6-dmncw_default -> ip-172-20-58-134.ec2.internal: ServiceSpreadingPriority, Score: (10)
I1216 15:36:05.411114       1 generic_scheduler.go:773] green-k8s-test-688d6758c6-dmncw_default -> ip-172-20-45-201.ec2.internal: ServiceSpreadingPriority, Score: (10)
I1216 15:36:05.411192       1 generic_scheduler.go:773] green-k8s-test-688d6758c6-dmncw_default -> ip-172-20-49-41.ec2.internal: ServiceSpreadingPriority, Score: (10)
I1216 15:36:05.411256       1 generic_scheduler.go:773] green-k8s-test-688d6758c6-dmncw_default -> ip-172-20-61-178.ec2.internal: ServiceSpreadingPriority, Score: (10)
I1216 15:36:05.411373       1 generic_scheduler.go:838] Host ip-172-20-58-134.ec2.internal => Score 27
I1216 15:36:05.411452       1 generic_scheduler.go:838] Host ip-172-20-45-201.ec2.internal => Score 27
I1216 15:36:05.411545       1 generic_scheduler.go:838] Host ip-172-20-49-41.ec2.internal => Score 27
I1216 15:36:05.411609       1 generic_scheduler.go:838] Host ip-172-20-61-178.ec2.internal => Score 26
I1216 15:36:05.411728       1 scheduler_binder.go:256] AssumePodVolumes for pod "default/green-k8s-test-688d6758c6-dmncw", node "ip-172-20-58-134.ec2.internal"
I1216 15:36:05.411866       1 scheduler_binder.go:266] AssumePodVolumes for pod "default/green-k8s-test-688d6758c6-dmncw", node "ip-172-20-58-134.ec2.internal": all PVCs bound and nothing to do
I1216 15:36:05.412006       1 factory.go:610] Attempting to bind green-k8s-test-688d6758c6-dmncw to ip-172-20-58-134.ec2.internal

### green-k8s-scheduler ###

I1217 17:26:23.742907       1 leaderelection.go:282] successfully renewed lease kube-system/green-k8s-scheduler
I1217 17:26:24.229688       1 scheduling_queue.go:830] About to try and schedule pod default/green-k8s-test-688d6758c6-2d67h
I1217 17:26:24.229890       1 scheduler.go:530] Attempting to schedule pod: default/green-k8s-test-688d6758c6-2d67h
I1217 17:26:24.230842       1 metadata.go:238] Precompute: PredicateWithExtendedResourceOptions
I1217 17:26:24.231117       1 predicates.go:908] Schedule Pod default/green-k8s-test-688d6758c6-2d67h on Node ip-172-20-58-134.ec2.internal is allowed, Node is running only 2 out of 110 Pods.
I1217 17:26:24.231273       1 predicates.go:908] Schedule Pod default/green-k8s-test-688d6758c6-2d67h on Node ip-172-20-45-201.ec2.internal is allowed, Node is running only 2 out of 110 Pods.
I1217 17:26:24.231397       1 predicates.go:908] Schedule Pod default/green-k8s-test-688d6758c6-2d67h on Node ip-172-20-49-41.ec2.internal is allowed, Node is running only 1 out of 110 Pods.
I1217 17:26:24.233218       1 predicates.go:908] Schedule Pod default/green-k8s-test-688d6758c6-2d67h on Node ip-172-20-61-178.ec2.internal is allowed, Node is running only 3 out of 110 Pods.
I1217 17:26:24.233386       1 predicates.go:908] Schedule Pod default/green-k8s-test-688d6758c6-2d67h on Node ip-172-20-40-148.ec2.internal is allowed, Node is running only 9 out of 110 Pods.
I1217 17:26:24.233523       1 generic_scheduler.go:667] since alwaysCheckAllPredicates has not been set, the predicate evaluation is short circuited and there are chances of other predicates failing as well.
I1217 17:26:24.233906       1 resource_allocation.go:84] green-k8s-test-688d6758c6-2d67h -> ip-172-20-58-134.ec2.internal: BalancedResourceAllocation, map of allocatable resources map[cpu:1000 memory:1966559232], map of requested resources map[cpu:300 memory:492830720] ,score 9,
I1217 17:26:24.234084       1 resource_allocation.go:84] green-k8s-test-688d6758c6-2d67h -> ip-172-20-58-134.ec2.internal: LeastResourceAllocation, map of allocatable resources map[cpu:1000 memory:1966559232], map of requested resources map[cpu:300 memory:492830720] ,score 7,
I1217 17:26:24.235889       1 resource_allocation.go:84] green-k8s-test-688d6758c6-2d67h -> ip-172-20-45-201.ec2.internal: BalancedResourceAllocation, map of allocatable resources map[cpu:1000 memory:1966559232], map of requested resources map[cpu:300 memory:492830720] ,score 9,
I1217 17:26:24.236231       1 resource_allocation.go:84] green-k8s-test-688d6758c6-2d67h -> ip-172-20-45-201.ec2.internal: LeastResourceAllocation, map of allocatable resources map[cpu:1000 memory:1966559232], map of requested resources map[cpu:300 memory:492830720] ,score 7,
I1217 17:26:24.236406       1 resource_allocation.go:84] green-k8s-test-688d6758c6-2d67h -> ip-172-20-49-41.ec2.internal: BalancedResourceAllocation, map of allocatable resources map[cpu:1000 memory:1966559232], map of requested resources map[cpu:200 memory:419430400] ,score 9,
I1217 17:26:24.236526       1 resource_allocation.go:84] green-k8s-test-688d6758c6-2d67h -> ip-172-20-49-41.ec2.internal: LeastResourceAllocation, map of allocatable resources map[cpu:1000 memory:1966559232], map of requested resources map[cpu:200 memory:419430400] ,score 7,
I1217 17:26:24.236679       1 resource_allocation.go:84] green-k8s-test-688d6758c6-2d67h -> ip-172-20-61-178.ec2.internal: BalancedResourceAllocation, map of allocatable resources map[cpu:1000 memory:1966559232], map of requested resources map[cpu:320 memory:639631360] ,score 9,
I1217 17:26:24.236774       1 resource_allocation.go:84] green-k8s-test-688d6758c6-2d67h -> ip-172-20-61-178.ec2.internal: LeastResourceAllocation, map of allocatable resources map[cpu:1000 memory:1966559232], map of requested resources map[cpu:320 memory:639631360] ,score 6,
I1217 17:26:24.236938       1 selector_spreading.go:146] green-k8s-test-688d6758c6-2d67h -> ip-172-20-58-134.ec2.internal: SelectorSpreadPriority, Score: (10)
I1217 17:26:24.237070       1 selector_spreading.go:146] green-k8s-test-688d6758c6-2d67h -> ip-172-20-45-201.ec2.internal: SelectorSpreadPriority, Score: (10)
I1217 17:26:24.237169       1 selector_spreading.go:146] green-k8s-test-688d6758c6-2d67h -> ip-172-20-49-41.ec2.internal: SelectorSpreadPriority, Score: (10)
I1217 17:26:24.237285       1 selector_spreading.go:146] green-k8s-test-688d6758c6-2d67h -> ip-172-20-61-178.ec2.internal: SelectorSpreadPriority, Score: (10)
I1217 17:26:24.237363       1 generic_scheduler.go:773] green-k8s-test-688d6758c6-2d67h_default -> ip-172-20-58-134.ec2.internal: ServiceSpreadingPriority, Score: (10)
I1217 17:26:24.237486       1 generic_scheduler.go:773] green-k8s-test-688d6758c6-2d67h_default -> ip-172-20-45-201.ec2.internal: ServiceSpreadingPriority, Score: (10)
I1217 17:26:24.237645       1 generic_scheduler.go:773] green-k8s-test-688d6758c6-2d67h_default -> ip-172-20-49-41.ec2.internal: ServiceSpreadingPriority, Score: (10)
I1217 17:26:24.237732       1 generic_scheduler.go:773] green-k8s-test-688d6758c6-2d67h_default -> ip-172-20-61-178.ec2.internal: ServiceSpreadingPriority, Score: (10)
I1217 17:26:24.280147       1 generic_scheduler.go:822] green-k8s-test-688d6758c6-2d67h_default -> ip-172-20-58-134.ec2.internal: http://localhost:80, Score: (9)
I1217 17:26:24.280175       1 generic_scheduler.go:822] green-k8s-test-688d6758c6-2d67h_default -> ip-172-20-45-201.ec2.internal: http://localhost:80, Score: (0)
I1217 17:26:24.280181       1 generic_scheduler.go:822] green-k8s-test-688d6758c6-2d67h_default -> ip-172-20-49-41.ec2.internal: http://localhost:80, Score: (10)
I1217 17:26:24.280187       1 generic_scheduler.go:822] green-k8s-test-688d6758c6-2d67h_default -> ip-172-20-61-178.ec2.internal: http://localhost:80, Score: (6)
I1217 17:26:24.280212       1 generic_scheduler.go:838] Host ip-172-20-58-134.ec2.internal => Score 36
I1217 17:26:24.280226       1 generic_scheduler.go:838] Host ip-172-20-45-201.ec2.internal => Score 27
I1217 17:26:24.280231       1 generic_scheduler.go:838] Host ip-172-20-49-41.ec2.internal => Score 37
I1217 17:26:24.280237       1 generic_scheduler.go:838] Host ip-172-20-61-178.ec2.internal => Score 32
I1217 17:26:24.280356       1 scheduler_binder.go:256] AssumePodVolumes for pod "default/green-k8s-test-688d6758c6-2d67h", node "ip-172-20-49-41.ec2.internal"
I1217 17:26:24.280378       1 scheduler_binder.go:266] AssumePodVolumes for pod "default/green-k8s-test-688d6758c6-2d67h", node "ip-172-20-49-41.ec2.internal": all PVCs bound and nothing to do
I1217 17:26:24.280431       1 factory.go:610] Attempting to bind green-k8s-test-688d6758c6-2d67h to ip-172-20-49-41.ec2.internal

### Extender Log ###

2021/12/17 17:26:24 Calculating node priorities for pod green-k8s-test-688d6758c6-2d67h ...
2021/12/17 17:26:24 Renewable shares parsed from Node ip-172-20-58-134.ec2.internal: [66.7 225.2 418.4 635.7 736.7]
2021/12/17 17:26:24 Error parsing renewable share from node ip-172-20-45-201.ec2.internal: No values found. Assigning renewable energy shares of 0.
2021/12/17 17:26:24 Renewable shares parsed from Node ip-172-20-45-201.ec2.internal: [0 0 0 0 0]
2021/12/17 17:26:24 Renewable shares parsed from Node ip-172-20-49-41.ec2.internal: [568.6 219.5 428.8 568.6 716.7]
2021/12/17 17:26:24 Renewable shares parsed from Node ip-172-20-61-178.ec2.internal: [881 140.6 296.2 312 457.8]
W1217 17:26:24.250075       1 client_config.go:615] Neither --kubeconfig nor --master was specified.  Using the inClusterConfig.  This might not work.
2021/12/17 17:26:24 Node ip-172-20-45-201.ec2.internal with max input of 10000 W and current utilization of 1.3 % has a current consumption of 134.83 W
2021/12/17 17:26:24 Node ip-172-20-45-201.ec2.internal has a renewable energy excess share of: [-134.83 -134.83 -134.83 -134.83 -134.83] 
2021/12/17 17:26:24 Node ip-172-20-49-41.ec2.internal with max input of 10000 W and current utilization of 1.1 % has a current consumption of 109.01 W
2021/12/17 17:26:24 Node ip-172-20-49-41.ec2.internal has a renewable energy excess share of: [459.59 110.49 319.79 459.59 607.69] 
2021/12/17 17:26:24 Node ip-172-20-61-178.ec2.internal with max input of 10000 W and current utilization of 1.9 % has a current consumption of 187.06 W
2021/12/17 17:26:24 Node ip-172-20-61-178.ec2.internal has a renewable energy excess share of: [693.94 -46.46 109.14 124.94 270.74] 
2021/12/17 17:26:24 Node ip-172-20-58-134.ec2.internal with max input of 10000 W and current utilization of 1.5 % has a current consumption of 153.27 W
2021/12/17 17:26:24 Node ip-172-20-58-134.ec2.internal has a renewable energy excess share of: [-86.57 71.93 265.13 482.43 583.43] 
2021/12/17 17:26:24 Renewable share scores calculated for Node ip-172-20-45-201.ec2.internal: [0 0 0 0 0]
2021/12/17 17:26:24 Renewable share scores calculated for Node ip-172-20-49-41.ec2.internal: [7.17 10 10 9.63 10]
2021/12/17 17:26:24 Renewable share scores calculated for Node ip-172-20-61-178.ec2.internal: [10 3.6 5.37 4.21 5.46]
2021/12/17 17:26:24 Renewable share scores calculated for Node ip-172-20-58-134.ec2.internal: [0.58 8.43 8.8 10 9.67]
2021/12/17 17:26:24 Total weighted score calculated for Node ip-172-20-49-41.ec2.internal: 10
2021/12/17 17:26:24 Total weighted score calculated for Node ip-172-20-61-178.ec2.internal: 6
2021/12/17 17:26:24 Total weighted score calculated for Node ip-172-20-58-134.ec2.internal: 9
2021/12/17 17:26:24 Total weighted score calculated for Node ip-172-20-45-201.ec2.internal: 0