I1220 21:37:36.916537       1 leaderelection.go:282] successfully renewed lease kube-system/green-k8s-scheduler
I1220 21:37:38.601291       1 scheduling_queue.go:830] About to try and schedule pod default/green-k8s-test-65bb774986-v9mcc
I1220 21:37:38.601450       1 scheduler.go:530] Attempting to schedule pod: default/green-k8s-test-65bb774986-v9mcc
I1220 21:37:38.601659       1 metadata.go:238] Precompute: PredicateWithExtendedResourceOptions
I1220 21:37:38.601812       1 predicates.go:908] Schedule Pod default/green-k8s-test-65bb774986-v9mcc on Node ip-172-20-40-148.ec2.internal is allowed, Node is running only 9 out of 110 Pods.
I1220 21:37:38.602016       1 generic_scheduler.go:667] since alwaysCheckAllPredicates has not been set, the predicate evaluation is short circuited and there are chances of other predicates failing as well.
I1220 21:37:38.601940       1 predicates.go:908] Schedule Pod default/green-k8s-test-65bb774986-v9mcc on Node ip-172-20-58-134.ec2.internal is allowed, Node is running only 2 out of 110 Pods.
I1220 21:37:38.601960       1 predicates.go:908] Schedule Pod default/green-k8s-test-65bb774986-v9mcc on Node ip-172-20-45-201.ec2.internal is allowed, Node is running only 2 out of 110 Pods.
I1220 21:37:38.601976       1 predicates.go:908] Schedule Pod default/green-k8s-test-65bb774986-v9mcc on Node ip-172-20-49-41.ec2.internal is allowed, Node is running only 1 out of 110 Pods.
I1220 21:37:38.601993       1 predicates.go:908] Schedule Pod default/green-k8s-test-65bb774986-v9mcc on Node ip-172-20-61-178.ec2.internal is allowed, Node is running only 3 out of 110 Pods.
I1220 21:37:38.602786       1 resource_allocation.go:84] green-k8s-test-65bb774986-v9mcc -> ip-172-20-58-134.ec2.internal: BalancedResourceAllocation, map of allocatable resources map[cpu:1000 memory:1966559232], map of requested resources map[cpu:350 memory:492830720] ,score 9,
I1220 21:37:38.602984       1 resource_allocation.go:84] green-k8s-test-65bb774986-v9mcc -> ip-172-20-58-134.ec2.internal: LeastResourceAllocation, map of allocatable resources map[cpu:1000 memory:1966559232], map of requested resources map[cpu:350 memory:492830720] ,score 6,
I1220 21:37:38.602918       1 resource_allocation.go:84] green-k8s-test-65bb774986-v9mcc -> ip-172-20-45-201.ec2.internal: BalancedResourceAllocation, map of allocatable resources map[cpu:1000 memory:1966559232], map of requested resources map[cpu:350 memory:492830720] ,score 9,
I1220 21:37:38.603277       1 resource_allocation.go:84] green-k8s-test-65bb774986-v9mcc -> ip-172-20-45-201.ec2.internal: LeastResourceAllocation, map of allocatable resources map[cpu:1000 memory:1966559232], map of requested resources map[cpu:350 memory:492830720] ,score 6,
I1220 21:37:38.602941       1 resource_allocation.go:84] green-k8s-test-65bb774986-v9mcc -> ip-172-20-49-41.ec2.internal: BalancedResourceAllocation, map of allocatable resources map[cpu:1000 memory:1966559232], map of requested resources map[cpu:250 memory:419430400] ,score 9,
I1220 21:37:38.603562       1 resource_allocation.go:84] green-k8s-test-65bb774986-v9mcc -> ip-172-20-49-41.ec2.internal: LeastResourceAllocation, map of allocatable resources map[cpu:1000 memory:1966559232], map of requested resources map[cpu:250 memory:419430400] ,score 7,
I1220 21:37:38.602957       1 resource_allocation.go:84] green-k8s-test-65bb774986-v9mcc -> ip-172-20-61-178.ec2.internal: BalancedResourceAllocation, map of allocatable resources map[cpu:1000 memory:1966559232], map of requested resources map[cpu:370 memory:639631360] ,score 9,
I1220 21:37:38.603794       1 resource_allocation.go:84] green-k8s-test-65bb774986-v9mcc -> ip-172-20-61-178.ec2.internal: LeastResourceAllocation, map of allocatable resources map[cpu:1000 memory:1966559232], map of requested resources map[cpu:370 memory:639631360] ,score 6,
I1220 21:37:38.603931       1 selector_spreading.go:146] green-k8s-test-65bb774986-v9mcc -> ip-172-20-58-134.ec2.internal: SelectorSpreadPriority, Score: (10)
I1220 21:37:38.604049       1 selector_spreading.go:146] green-k8s-test-65bb774986-v9mcc -> ip-172-20-45-201.ec2.internal: SelectorSpreadPriority, Score: (10)
I1220 21:37:38.604208       1 selector_spreading.go:146] green-k8s-test-65bb774986-v9mcc -> ip-172-20-49-41.ec2.internal: SelectorSpreadPriority, Score: (10)
I1220 21:37:38.604307       1 selector_spreading.go:146] green-k8s-test-65bb774986-v9mcc -> ip-172-20-61-178.ec2.internal: SelectorSpreadPriority, Score: (10)
I1220 21:37:38.604388       1 generic_scheduler.go:773] green-k8s-test-65bb774986-v9mcc_default -> ip-172-20-58-134.ec2.internal: ServiceSpreadingPriority, Score: (10)
I1220 21:37:38.604505       1 generic_scheduler.go:773] green-k8s-test-65bb774986-v9mcc_default -> ip-172-20-45-201.ec2.internal: ServiceSpreadingPriority, Score: (10)
I1220 21:37:38.604584       1 generic_scheduler.go:773] green-k8s-test-65bb774986-v9mcc_default -> ip-172-20-49-41.ec2.internal: ServiceSpreadingPriority, Score: (10)
I1220 21:37:38.604682       1 generic_scheduler.go:773] green-k8s-test-65bb774986-v9mcc_default -> ip-172-20-61-178.ec2.internal: ServiceSpreadingPriority, Score: (10)
I1220 21:37:38.674150       1 generic_scheduler.go:822] green-k8s-test-65bb774986-v9mcc_default -> ip-172-20-58-134.ec2.internal: http://localhost:80, Score: (10)
I1220 21:37:38.674176       1 generic_scheduler.go:822] green-k8s-test-65bb774986-v9mcc_default -> ip-172-20-45-201.ec2.internal: http://localhost:80, Score: (0)
I1220 21:37:38.674183       1 generic_scheduler.go:822] green-k8s-test-65bb774986-v9mcc_default -> ip-172-20-49-41.ec2.internal: http://localhost:80, Score: (10)
I1220 21:37:38.674188       1 generic_scheduler.go:822] green-k8s-test-65bb774986-v9mcc_default -> ip-172-20-61-178.ec2.internal: http://localhost:80, Score: (6)
I1220 21:37:38.674201       1 generic_scheduler.go:838] Host ip-172-20-58-134.ec2.internal => Score 36
I1220 21:37:38.674207       1 generic_scheduler.go:838] Host ip-172-20-45-201.ec2.internal => Score 26
I1220 21:37:38.674213       1 generic_scheduler.go:838] Host ip-172-20-49-41.ec2.internal => Score 37
I1220 21:37:38.674218       1 generic_scheduler.go:838] Host ip-172-20-61-178.ec2.internal => Score 32
I1220 21:37:38.674399       1 scheduler_binder.go:256] AssumePodVolumes for pod "default/green-k8s-test-65bb774986-v9mcc", node "ip-172-20-49-41.ec2.internal"
I1220 21:37:38.674420       1 scheduler_binder.go:266] AssumePodVolumes for pod "default/green-k8s-test-65bb774986-v9mcc", node "ip-172-20-49-41.ec2.internal": all PVCs bound and nothing to do
I1220 21:37:38.674493       1 factory.go:610] Attempting to bind green-k8s-test-65bb774986-v9mcc to ip-172-20-49-41.ec2.internal
I1220 21:37:38.674549       1 request.go:966] Request Body:
00000000  6b 38 73 00 0a 0d 0a 02  76 31 12 07 42 69 6e 64  |k8s.....v1..Bind|
00000010  69 6e 67 12 8e 01 0a 5c  0a 1f 67 72 65 65 6e 2d  |ing....\..green-|
00000020  6b 38 73 2d 74 65 73 74  2d 36 35 62 62 37 37 34  |k8s-test-65bb774|
00000030  39 38 36 2d 76 39 6d 63  63 12 00 1a 07 64 65 66  |986-v9mcc....def|
00000040  61 75 6c 74 22 00 2a 24  33 32 38 31 31 66 33 35  |ault".*$32811f35|
00000050  2d 64 64 30 64 2d 34 61  35 63 2d 39 31 33 31 2d  |-dd0d-4a5c-9131-|
00000060  32 61 34 39 66 65 64 62  62 35 66 35 32 00 38 00  |2a49fedbb5f52.8.|
00000070  42 00 7a 00 12 2e 0a 04  4e 6f 64 65 12 00 1a 1c  |B.z.....Node....|
00000080  69 70 2d 31 37 32 2d 32  30 2d 34 39 2d 34 31 2e  |ip-172-20-49-41.|
00000090  65 63 32 2e 69 6e 74 65  72 6e 61 6c 22 00 2a 00  |ec2.internal".*.|
000000a0  32 00 3a 00 1a 00 22 00                           |2.:...".|
I1220 21:37:38.674755       1 round_trippers.go:423] curl -k -v -XPOST  -H "Content-Type: application/vnd.kubernetes.protobuf" -H "User-Agent: kube-scheduler/v1.16.3 (linux/amd64) kubernetes/b3cbbae/scheduler" -H "Accept: application/vnd.kubernetes.protobuf, */*" -H "Authorization: Bearer eyJhbGciOiJSUzI1NiIsImtpZCI6IkI2d0Zpc0Q2S2pFdmhUX3hsRG5GZFdLemMtRkhWWmxiQmszcGVmc3RsdjQifQ.eyJhdWQiOlsia3ViZXJuZXRlcy5zdmMuZGVmYXVsdCJdLCJleHAiOjE2NzE1NzE2OTYsImlhdCI6MTY0MDAzNTY5NiwiaXNzIjoiaHR0cHM6Ly9hcGkuaW50ZXJuYWwuaGEuZ3JlZW5rOHMuY29tIiwia3ViZXJuZXRlcy5pbyI6eyJuYW1lc3BhY2UiOiJrdWJlLXN5c3RlbSIsInBvZCI6eyJuYW1lIjoiZ3JlZW4tazhzLXNjaGVkdWxlci04Y2I3Zjc3NzktN2M0ZGwiLCJ1aWQiOiIyODMwY2IxNS05OTM2LTQ3YjAtYTlhOS0wNjVlOTdmZDU2NGIifSwic2VydmljZWFjY291bnQiOnsibmFtZSI6ImdyZWVuLWs4cy1zY2hlZHVsZXIiLCJ1aWQiOiI2NzgyMTEwNC01NGFiLTQ2YzctYTQ3NC00YjhlODI3M2UyZWYifSwid2FybmFmdGVyIjoxNjQwMDM5MzAzfSwibmJmIjoxNjQwMDM1Njk2LCJzdWIiOiJzeXN0ZW06c2VydmljZWFjY291bnQ6a3ViZS1zeXN0ZW06Z3JlZW4tazhzLXNjaGVkdWxlciJ9.QzO_AZGr2BvZ_-W2I_yCM5mU-rv4-LxvAuo3IXheOxojip-51tgqkELWPgYJgclwuIc5ftd3gEq-qU2_O5xtFjARjpRcNzgwZedg4Yl9ZTelqQG5ZpHsE2DpvOTBB8QlcKNAYkinz7g0SSnfBJsIa8ypV9k5eSwKNSH8-2xikYWnfE0tKV9fsJiQAO1BBDZt0L8eiChCiCh3yeR7cPykyfCSSdeLfG0Ycs7yTyo0rKEMWArzdw4ZqJzqtlyuof8EGT-lpcTkv2uHaX2qNfj_43700o-XR9H6N3mAJqgSQFPaZmN0b7VrokNngHR5PhPSzBUvcX0FYEvmV4qUAWsFuw" 'https://100.64.0.1:443/api/v1/namespaces/default/pods/green-k8s-test-65bb774986-v9mcc/binding'
I1220 21:37:38.675026       1 scheduling_queue.go:830] About to try and schedule pod default/green-k8s-test-65bb774986-xlcp9
I1220 21:37:38.675205       1 scheduler.go:530] Attempting to schedule pod: default/green-k8s-test-65bb774986-xlcp9
I1220 21:37:38.675359       1 metadata.go:238] Precompute: PredicateWithExtendedResourceOptions
I1220 21:37:38.675497       1 predicates.go:908] Schedule Pod default/green-k8s-test-65bb774986-xlcp9 on Node ip-172-20-40-148.ec2.internal is allowed, Node is running only 9 out of 110 Pods.
I1220 21:37:38.675593       1 generic_scheduler.go:667] since alwaysCheckAllPredicates has not been set, the predicate evaluation is short circuited and there are chances of other predicates failing as well.
I1220 21:37:38.675710       1 predicates.go:908] Schedule Pod default/green-k8s-test-65bb774986-xlcp9 on Node ip-172-20-58-134.ec2.internal is allowed, Node is running only 2 out of 110 Pods.
I1220 21:37:38.675800       1 predicates.go:908] Schedule Pod default/green-k8s-test-65bb774986-xlcp9 on Node ip-172-20-45-201.ec2.internal is allowed, Node is running only 2 out of 110 Pods.
I1220 21:37:38.675913       1 predicates.go:908] Schedule Pod default/green-k8s-test-65bb774986-xlcp9 on Node ip-172-20-49-41.ec2.internal is allowed, Node is running only 2 out of 110 Pods.
I1220 21:37:38.676002       1 predicates.go:908] Schedule Pod default/green-k8s-test-65bb774986-xlcp9 on Node ip-172-20-61-178.ec2.internal is allowed, Node is running only 3 out of 110 Pods.
I1220 21:37:38.676208       1 resource_allocation.go:84] green-k8s-test-65bb774986-xlcp9 -> ip-172-20-58-134.ec2.internal: BalancedResourceAllocation, map of allocatable resources map[cpu:1000 memory:1966559232], map of requested resources map[cpu:350 memory:492830720] ,score 9,
I1220 21:37:38.676348       1 resource_allocation.go:84] green-k8s-test-65bb774986-xlcp9 -> ip-172-20-58-134.ec2.internal: LeastResourceAllocation, map of allocatable resources map[cpu:1000 memory:1966559232], map of requested resources map[cpu:350 memory:492830720] ,score 6,
I1220 21:37:38.676446       1 resource_allocation.go:84] green-k8s-test-65bb774986-xlcp9 -> ip-172-20-45-201.ec2.internal: BalancedResourceAllocation, map of allocatable resources map[cpu:1000 memory:1966559232], map of requested resources map[cpu:350 memory:492830720] ,score 9,
I1220 21:37:38.676556       1 resource_allocation.go:84] green-k8s-test-65bb774986-xlcp9 -> ip-172-20-45-201.ec2.internal: LeastResourceAllocation, map of allocatable resources map[cpu:1000 memory:1966559232], map of requested resources map[cpu:350 memory:492830720] ,score 6,
I1220 21:37:38.676712       1 resource_allocation.go:84] green-k8s-test-65bb774986-xlcp9 -> ip-172-20-49-41.ec2.internal: BalancedResourceAllocation, map of allocatable resources map[cpu:1000 memory:1966559232], map of requested resources map[cpu:400 memory:629145600] ,score 9,
I1220 21:37:38.676820       1 resource_allocation.go:84] green-k8s-test-65bb774986-xlcp9 -> ip-172-20-49-41.ec2.internal: LeastResourceAllocation, map of allocatable resources map[cpu:1000 memory:1966559232], map of requested resources map[cpu:400 memory:629145600] ,score 6,
I1220 21:37:38.676950       1 resource_allocation.go:84] green-k8s-test-65bb774986-xlcp9 -> ip-172-20-61-178.ec2.internal: BalancedResourceAllocation, map of allocatable resources map[cpu:1000 memory:1966559232], map of requested resources map[cpu:370 memory:639631360] ,score 9,
I1220 21:37:38.677062       1 resource_allocation.go:84] green-k8s-test-65bb774986-xlcp9 -> ip-172-20-61-178.ec2.internal: LeastResourceAllocation, map of allocatable resources map[cpu:1000 memory:1966559232], map of requested resources map[cpu:370 memory:639631360] ,score 6,
I1220 21:37:38.677210       1 selector_spreading.go:146] green-k8s-test-65bb774986-xlcp9 -> ip-172-20-58-134.ec2.internal: SelectorSpreadPriority, Score: (3)
I1220 21:37:38.677347       1 selector_spreading.go:146] green-k8s-test-65bb774986-xlcp9 -> ip-172-20-45-201.ec2.internal: SelectorSpreadPriority, Score: (3)
I1220 21:37:38.677448       1 selector_spreading.go:146] green-k8s-test-65bb774986-xlcp9 -> ip-172-20-49-41.ec2.internal: SelectorSpreadPriority, Score: (0)
I1220 21:37:38.677553       1 selector_spreading.go:146] green-k8s-test-65bb774986-xlcp9 -> ip-172-20-61-178.ec2.internal: SelectorSpreadPriority, Score: (3)
I1220 21:37:38.677651       1 generic_scheduler.go:773] green-k8s-test-65bb774986-xlcp9_default -> ip-172-20-58-134.ec2.internal: ServiceSpreadingPriority, Score: (3)
I1220 21:37:38.677751       1 generic_scheduler.go:773] green-k8s-test-65bb774986-xlcp9_default -> ip-172-20-45-201.ec2.internal: ServiceSpreadingPriority, Score: (3)
I1220 21:37:38.677925       1 generic_scheduler.go:773] green-k8s-test-65bb774986-xlcp9_default -> ip-172-20-49-41.ec2.internal: ServiceSpreadingPriority, Score: (0)
I1220 21:37:38.678015       1 generic_scheduler.go:773] green-k8s-test-65bb774986-xlcp9_default -> ip-172-20-61-178.ec2.internal: ServiceSpreadingPriority, Score: (3)
I1220 21:37:38.678842       1 round_trippers.go:443] POST https://100.64.0.1:443/api/v1/namespaces/default/pods/green-k8s-test-65bb774986-v9mcc/binding 201 Created in 4 milliseconds
I1220 21:37:38.678974       1 round_trippers.go:449] Response Headers:
I1220 21:37:38.679069       1 round_trippers.go:452]     Date: Mon, 20 Dec 2021 21:37:38 GMT
I1220 21:37:38.679193       1 round_trippers.go:452]     Cache-Control: no-cache, private
I1220 21:37:38.679289       1 round_trippers.go:452]     Content-Type: application/vnd.kubernetes.protobuf
I1220 21:37:38.679736       1 round_trippers.go:452]     X-Kubernetes-Pf-Flowschema-Uid: 9fb2dc3c-3c29-42f2-bb88-3d0896e45310
I1220 21:37:38.679846       1 round_trippers.go:452]     X-Kubernetes-Pf-Prioritylevel-Uid: 0d11ff8b-ca59-4914-b971-4d6f623f711b
I1220 21:37:38.679951       1 round_trippers.go:452]     Content-Length: 48
I1220 21:37:38.680071       1 request.go:966] Response Body:
00000000  6b 38 73 00 0a 0c 0a 02  76 31 12 06 53 74 61 74  |k8s.....v1..Stat|
00000010  75 73 12 18 0a 06 0a 00  12 00 1a 00 12 07 53 75  |us............Su|
00000020  63 63 65 73 73 1a 00 22  00 30 c9 01 1a 00 22 00  |ccess..".0....".|
I1220 21:37:38.680220       1 cache.go:305] Finished binding for pod 32811f35-dd0d-4a5c-9131-2a49fedbb5f5. Can be expired.
I1220 21:37:38.680355       1 event_recorder.go:54] Could not construct reference to: '<nil>' due to: 'can't reference a nil object'.
I1220 21:37:38.680484       1 scheduler.go:667] pod default/green-k8s-test-65bb774986-v9mcc is bound successfully on node "ip-172-20-49-41.ec2.internal", 5 nodes evaluated, 4 nodes were found feasible. Bound node resource: "Capacity: CPU<1>|Memory<2022868Ki>|Pods<110>|StorageEphemeral<130045936Ki>; Allocatable: CPU<1>|Memory<1920468Ki>|Pods<110>|StorageEphemeral<119850334420>.".
I1220 21:37:38.680731       1 request.go:966] Request Body:
00000000  6b 38 73 00 0a 1e 0a 15  65 76 65 6e 74 73 2e 6b  |k8s.....events.k|
00000010  38 73 2e 69 6f 2f 76 31  62 65 74 61 31 12 05 45  |8s.io/v1beta1..E|
00000020  76 65 6e 74 12 a7 03 0a  49 0a 30 67 72 65 65 6e  |vent....I.0green|
00000030  2d 6b 38 73 2d 74 65 73  74 2d 36 35 62 62 37 37  |-k8s-test-65bb77|
00000040  34 39 38 36 2d 76 39 6d  63 63 2e 31 36 63 32 39  |4986-v9mcc.16c29|
00000050  34 34 39 62 39 36 38 64  31 35 32 12 00 1a 07 64  |449b968d152....d|
00000060  65 66 61 75 6c 74 22 00  2a 00 32 00 38 00 42 00  |efault".*.2.8.B.|
00000070  7a 00 12 0c 08 a2 ef 83  8e 06 10 8f dc b4 c4 02  |z...............|
00000080  22 13 67 72 65 65 6e 2d  6b 38 73 2d 73 63 68 65  |".green-k8s-sche|
00000090  64 75 6c 65 72 2a 37 67  72 65 65 6e 2d 6b 38 73  |duler*7green-k8s|
000000a0  2d 73 63 68 65 64 75 6c  65 72 2d 67 72 65 65 6e  |-scheduler-green|
000000b0  2d 6b 38 73 2d 73 63 68  65 64 75 6c 65 72 2d 38  |-k8s-scheduler-8|
000000c0  63 62 37 66 37 37 37 39  2d 37 63 34 64 6c 32 07  |cb7f7779-7c4dl2.|
000000d0  42 69 6e 64 69 6e 67 3a  09 53 63 68 65 64 75 6c  |Binding:.Schedul|
000000e0  65 64 42 64 0a 03 50 6f  64 12 07 64 65 66 61 75  |edBd..Pod..defau|
000000f0  6c 74 1a 1f 67 72 65 65  6e 2d 6b 38 73 2d 74 65  |lt..green-k8s-te|
00000100  73 74 2d 36 35 62 62 37  37 34 39 38 36 2d 76 39  |st-65bb774986-v9|
00000110  6d 63 63 22 24 33 32 38  31 31 66 33 35 2d 64 64  |mcc"$32811f35-dd|
00000120  30 64 2d 34 61 35 63 2d  39 31 33 31 2d 32 61 34  |0d-4a5c-9131-2a4|
00000130  39 66 65 64 62 62 35 66  35 2a 02 76 31 32 07 31  |9fedbb5f5*.v12.1|
00000140  34 31 37 32 35 31 3a 00  52 5d 53 75 63 63 65 73  |417251:.R]Succes|
00000150  73 66 75 6c 6c 79 20 61  73 73 69 67 6e 65 64 20  |sfully assigned |
00000160  64 65 66 61 75 6c 74 2f  67 72 65 65 6e 2d 6b 38  |default/green-k8|
00000170  73 2d 74 65 73 74 2d 36  35 62 62 37 37 34 39 38  |s-test-65bb77498|
00000180  36 2d 76 39 6d 63 63 20  74 6f 20 69 70 2d 31 37  |6-v9mcc to ip-17|
00000190  32 2d 32 30 2d 34 39 2d  34 31 2e 65 63 32 2e 69  |2-20-49-41.ec2.i|
000001a0  6e 74 65 72 6e 61 6c 5a  06 4e 6f 72 6d 61 6c 62  |nternalZ.Normalb|
000001b0  17 0a 13 67 72 65 65 6e  2d 6b 38 73 2d 73 63 68  |...green-k8s-sch|
000001c0  65 64 75 6c 65 72 12 00  6a 00 72 00 78 00 1a 00  |eduler..j.r.x...|
000001d0  22 00                                             |".|
I1220 21:37:38.681506       1 round_trippers.go:423] curl -k -v -XPOST  -H "Content-Type: application/vnd.kubernetes.protobuf" -H "User-Agent: kube-scheduler/v1.16.3 (linux/amd64) kubernetes/b3cbbae/scheduler" -H "Authorization: Bearer eyJhbGciOiJSUzI1NiIsImtpZCI6IkI2d0Zpc0Q2S2pFdmhUX3hsRG5GZFdLemMtRkhWWmxiQmszcGVmc3RsdjQifQ.eyJhdWQiOlsia3ViZXJuZXRlcy5zdmMuZGVmYXVsdCJdLCJleHAiOjE2NzE1NzE2OTYsImlhdCI6MTY0MDAzNTY5NiwiaXNzIjoiaHR0cHM6Ly9hcGkuaW50ZXJuYWwuaGEuZ3JlZW5rOHMuY29tIiwia3ViZXJuZXRlcy5pbyI6eyJuYW1lc3BhY2UiOiJrdWJlLXN5c3RlbSIsInBvZCI6eyJuYW1lIjoiZ3JlZW4tazhzLXNjaGVkdWxlci04Y2I3Zjc3NzktN2M0ZGwiLCJ1aWQiOiIyODMwY2IxNS05OTM2LTQ3YjAtYTlhOS0wNjVlOTdmZDU2NGIifSwic2VydmljZWFjY291bnQiOnsibmFtZSI6ImdyZWVuLWs4cy1zY2hlZHVsZXIiLCJ1aWQiOiI2NzgyMTEwNC01NGFiLTQ2YzctYTQ3NC00YjhlODI3M2UyZWYifSwid2FybmFmdGVyIjoxNjQwMDM5MzAzfSwibmJmIjoxNjQwMDM1Njk2LCJzdWIiOiJzeXN0ZW06c2VydmljZWFjY291bnQ6a3ViZS1zeXN0ZW06Z3JlZW4tazhzLXNjaGVkdWxlciJ9.QzO_AZGr2BvZ_-W2I_yCM5mU-rv4-LxvAuo3IXheOxojip-51tgqkELWPgYJgclwuIc5ftd3gEq-qU2_O5xtFjARjpRcNzgwZedg4Yl9ZTelqQG5ZpHsE2DpvOTBB8QlcKNAYkinz7g0SSnfBJsIa8ypV9k5eSwKNSH8-2xikYWnfE0tKV9fsJiQAO1BBDZt0L8eiChCiCh3yeR7cPykyfCSSdeLfG0Ycs7yTyo0rKEMWArzdw4ZqJzqtlyuof8EGT-lpcTkv2uHaX2qNfj_43700o-XR9H6N3mAJqgSQFPaZmN0b7VrokNngHR5PhPSzBUvcX0FYEvmV4qUAWsFuw" -H "Accept: application/vnd.kubernetes.protobuf, */*" 'https://100.64.0.1:443/apis/events.k8s.io/v1beta1/namespaces/default/events'
I1220 21:37:38.687582       1 round_trippers.go:443] POST https://100.64.0.1:443/apis/events.k8s.io/v1beta1/namespaces/default/events 201 Created in 5 milliseconds
I1220 21:37:38.687740       1 round_trippers.go:449] Response Headers:
I1220 21:37:38.687843       1 round_trippers.go:452]     Cache-Control: no-cache, private
I1220 21:37:38.687954       1 round_trippers.go:452]     Content-Type: application/vnd.kubernetes.protobuf
I1220 21:37:38.688055       1 round_trippers.go:452]     X-Kubernetes-Pf-Flowschema-Uid: 9fb2dc3c-3c29-42f2-bb88-3d0896e45310
I1220 21:37:38.688156       1 round_trippers.go:452]     X-Kubernetes-Pf-Prioritylevel-Uid: 0d11ff8b-ca59-4914-b971-4d6f623f711b
I1220 21:37:38.688251       1 round_trippers.go:452]     Content-Length: 863
I1220 21:37:38.688349       1 round_trippers.go:452]     Date: Mon, 20 Dec 2021 21:37:38 GMT
I1220 21:37:38.688521       1 request.go:966] Response Body:
00000000  6b 38 73 00 0a 1e 0a 15  65 76 65 6e 74 73 2e 6b  |k8s.....events.k|
00000010  38 73 2e 69 6f 2f 76 31  62 65 74 61 31 12 05 45  |8s.io/v1beta1..E|
00000020  76 65 6e 74 12 b4 06 0a  d5 03 0a 30 67 72 65 65  |vent.......0gree|
00000030  6e 2d 6b 38 73 2d 74 65  73 74 2d 36 35 62 62 37  |n-k8s-test-65bb7|
00000040  37 34 39 38 36 2d 76 39  6d 63 63 2e 31 36 63 32  |74986-v9mcc.16c2|
00000050  39 34 34 39 62 39 36 38  64 31 35 32 12 00 1a 07  |9449b968d152....|
00000060  64 65 66 61 75 6c 74 22  00 2a 24 32 30 38 39 65  |default".*$2089e|
00000070  31 32 35 2d 63 66 65 36  2d 34 32 31 34 2d 62 32  |125-cfe6-4214-b2|
00000080  39 37 2d 30 39 66 65 61  35 33 65 64 36 32 39 32  |97-09fea53ed6292|
00000090  04 32 37 30 37 38 00 42  08 08 a2 ef 83 8e 06 10  |.27078.B........|
000000a0  00 7a 00 8a 01 d8 02 0a  0e 6b 75 62 65 2d 73 63  |.z.......kube-sc|
000000b0  68 65 64 75 6c 65 72 12  06 55 70 64 61 74 65 1a  |heduler..Update.|
000000c0  15 65 76 65 6e 74 73 2e  6b 38 73 2e 69 6f 2f 76  |.events.k8s.io/v|
000000d0  31 62 65 74 61 31 22 08  08 a2 ef 83 8e 06 10 00  |1beta1".........|
000000e0  32 08 46 69 65 6c 64 73  56 31 3a 92 02 0a 8f 02  |2.FieldsV1:.....|
000000f0  7b 22 66 3a 61 63 74 69  6f 6e 22 3a 7b 7d 2c 22  |{"f:action":{},"|
00000100  66 3a 64 65 70 72 65 63  61 74 65 64 53 6f 75 72  |f:deprecatedSour|
00000110  63 65 22 3a 7b 22 66 3a  63 6f 6d 70 6f 6e 65 6e  |ce":{"f:componen|
00000120  74 22 3a 7b 7d 7d 2c 22  66 3a 65 76 65 6e 74 54  |t":{}},"f:eventT|
00000130  69 6d 65 22 3a 7b 7d 2c  22 66 3a 6e 6f 74 65 22  |ime":{},"f:note"|
00000140  3a 7b 7d 2c 22 66 3a 72  65 61 73 6f 6e 22 3a 7b  |:{},"f:reason":{|
00000150  7d 2c 22 66 3a 72 65 67  61 72 64 69 6e 67 22 3a  |},"f:regarding":|
00000160  7b 22 66 3a 61 70 69 56  65 72 73 69 6f 6e 22 3a  |{"f:apiVersion":|
00000170  7b 7d 2c 22 66 3a 6b 69  6e 64 22 3a 7b 7d 2c 22  |{},"f:kind":{},"|
00000180  66 3a 6e 61 6d 65 22 3a  7b 7d 2c 22 66 3a 6e 61  |f:name":{},"f:na|
00000190  6d 65 73 70 61 63 65 22  3a 7b 7d 2c 22 66 3a 72  |mespace":{},"f:r|
000001a0  65 73 6f 75 72 63 65 56  65 72 73 69 6f 6e 22 3a  |esourceVersion":|
000001b0  7b 7d 2c 22 66 3a 75 69  64 22 3a 7b 7d 7d 2c 22  |{},"f:uid":{}},"|
000001c0  66 3a 72 65 70 6f 72 74  69 6e 67 43 6f 6e 74 72  |f:reportingContr|
000001d0  6f 6c 6c 65 72 22 3a 7b  7d 2c 22 66 3a 72 65 70  |oller":{},"f:rep|
000001e0  6f 72 74 69 6e 67 49 6e  73 74 61 6e 63 65 22 3a  |ortingInstance":|
000001f0  7b 7d 2c 22 66 3a 74 79  70 65 22 3a 7b 7d 7d 12  |{},"f:type":{}}.|
00000200  0c 08 a2 ef 83 8e 06 10  8f dc b4 c4 02 22 13 67  |.............".g|
00000210  72 65 65 6e 2d 6b 38 73  2d 73 63 68 65 64 75 6c  |reen-k8s-schedul|
00000220  65 72 2a 37 67 72 65 65  6e 2d 6b 38 73 2d 73 63  |er*7green-k8s-sc|
00000230  68 65 64 75 6c 65 72 2d  67 72 65 65 6e 2d 6b 38  |heduler-green-k8|
00000240  73 2d 73 63 68 65 64 75  6c 65 72 2d 38 63 62 37  |s-scheduler-8cb7|
00000250  66 37 37 37 39 2d 37 63  34 64 6c 32 07 42 69 6e  |f7779-7c4dl2.Bin|
00000260  64 69 6e 67 3a 09 53 63  68 65 64 75 6c 65 64 42  |ding:.ScheduledB|
00000270  64 0a 03 50 6f 64 12 07  64 65 66 61 75 6c 74 1a  |d..Pod..default.|
00000280  1f 67 72 65 65 6e 2d 6b  38 73 2d 74 65 73 74 2d  |.green-k8s-test-|
00000290  36 35 62 62 37 37 34 39  38 36 2d 76 39 6d 63 63  |65bb774986-v9mcc|
000002a0  22 24 33 32 38 31 31 66  33 35 2d 64 64 30 64 2d  |"$32811f35-dd0d-|
000002b0  34 61 35 63 2d 39 31 33  31 2d 32 61 34 39 66 65  |4a5c-9131-2a49fe|
000002c0  64 62 62 35 66 35 2a 02  76 31 32 07 31 34 31 37  |dbb5f5*.v12.1417|
000002d0  32 35 31 3a 00 52 5d 53  75 63 63 65 73 73 66 75  |251:.R]Successfu|
000002e0  6c 6c 79 20 61 73 73 69  67 6e 65 64 20 64 65 66  |lly assigned def|
000002f0  61 75 6c 74 2f 67 72 65  65 6e 2d 6b 38 73 2d 74  |ault/green-k8s-t|
00000300  65 73 74 2d 36 35 62 62  37 37 34 39 38 36 2d 76  |est-65bb774986-v|
00000310  39 6d 63 63 20 74 6f 20  69 70 2d 31 37 32 2d 32  |9mcc to ip-172-2|
00000320  30 2d 34 39 2d 34 31 2e  65 63 32 2e 69 6e 74 65  |0-49-41.ec2.inte|
00000330  72 6e 61 6c 5a 06 4e 6f  72 6d 61 6c 62 17 0a 13  |rnalZ.Normalb...|
00000340  67 72 65 65 6e 2d 6b 38  73 2d 73 63 68 65 64 75  |green-k8s-schedu|
00000350  6c 65 72 12 00 6a 00 72  00 78 00 1a 00 22 00     |ler..j.r.x...".|
I1220 21:37:38.699652       1 generic_scheduler.go:822] green-k8s-test-65bb774986-xlcp9_default -> ip-172-20-58-134.ec2.internal: http://localhost:80, Score: (10)
I1220 21:37:38.699678       1 generic_scheduler.go:822] green-k8s-test-65bb774986-xlcp9_default -> ip-172-20-45-201.ec2.internal: http://localhost:80, Score: (0)
I1220 21:37:38.699685       1 generic_scheduler.go:822] green-k8s-test-65bb774986-xlcp9_default -> ip-172-20-49-41.ec2.internal: http://localhost:80, Score: (10)
I1220 21:37:38.699690       1 generic_scheduler.go:822] green-k8s-test-65bb774986-xlcp9_default -> ip-172-20-61-178.ec2.internal: http://localhost:80, Score: (6)
I1220 21:37:38.699737       1 generic_scheduler.go:838] Host ip-172-20-58-134.ec2.internal => Score 29
I1220 21:37:38.699750       1 generic_scheduler.go:838] Host ip-172-20-45-201.ec2.internal => Score 19
I1220 21:37:38.699756       1 generic_scheduler.go:838] Host ip-172-20-49-41.ec2.internal => Score 26
I1220 21:37:38.699761       1 generic_scheduler.go:838] Host ip-172-20-61-178.ec2.internal => Score 25
I1220 21:37:38.699808       1 scheduler_binder.go:256] AssumePodVolumes for pod "default/green-k8s-test-65bb774986-xlcp9", node "ip-172-20-58-134.ec2.internal"
I1220 21:37:38.699827       1 scheduler_binder.go:266] AssumePodVolumes for pod "default/green-k8s-test-65bb774986-xlcp9", node "ip-172-20-58-134.ec2.internal": all PVCs bound and nothing to do
I1220 21:37:38.699908       1 factory.go:610] Attempting to bind green-k8s-test-65bb774986-xlcp9 to ip-172-20-58-134.ec2.internal
I1220 21:37:38.699984       1 request.go:966] Request Body:
00000000  6b 38 73 00 0a 0d 0a 02  76 31 12 07 42 69 6e 64  |k8s.....v1..Bind|
00000010  69 6e 67 12 8f 01 0a 5c  0a 1f 67 72 65 65 6e 2d  |ing....\..green-|
00000020  6b 38 73 2d 74 65 73 74  2d 36 35 62 62 37 37 34  |k8s-test-65bb774|
00000030  39 38 36 2d 78 6c 63 70  39 12 00 1a 07 64 65 66  |986-xlcp9....def|
00000040  61 75 6c 74 22 00 2a 24  36 32 34 30 36 64 61 61  |ault".*$62406daa|
00000050  2d 39 64 65 37 2d 34 34  65 39 2d 39 62 64 39 2d  |-9de7-44e9-9bd9-|
00000060  64 32 63 63 61 39 62 36  66 34 31 36 32 00 38 00  |d2cca9b6f4162.8.|
00000070  42 00 7a 00 12 2f 0a 04  4e 6f 64 65 12 00 1a 1d  |B.z../..Node....|
00000080  69 70 2d 31 37 32 2d 32  30 2d 35 38 2d 31 33 34  |ip-172-20-58-134|
00000090  2e 65 63 32 2e 69 6e 74  65 72 6e 61 6c 22 00 2a  |.ec2.internal".*|
000000a0  00 32 00 3a 00 1a 00 22  00                       |.2.:...".|
I1220 21:37:38.700090       1 round_trippers.go:423] curl -k -v -XPOST  -H "Content-Type: application/vnd.kubernetes.protobuf" -H "User-Agent: kube-scheduler/v1.16.3 (linux/amd64) kubernetes/b3cbbae/scheduler" -H "Accept: application/vnd.kubernetes.protobuf, */*" -H "Authorization: Bearer eyJhbGciOiJSUzI1NiIsImtpZCI6IkI2d0Zpc0Q2S2pFdmhUX3hsRG5GZFdLemMtRkhWWmxiQmszcGVmc3RsdjQifQ.eyJhdWQiOlsia3ViZXJuZXRlcy5zdmMuZGVmYXVsdCJdLCJleHAiOjE2NzE1NzE2OTYsImlhdCI6MTY0MDAzNTY5NiwiaXNzIjoiaHR0cHM6Ly9hcGkuaW50ZXJuYWwuaGEuZ3JlZW5rOHMuY29tIiwia3ViZXJuZXRlcy5pbyI6eyJuYW1lc3BhY2UiOiJrdWJlLXN5c3RlbSIsInBvZCI6eyJuYW1lIjoiZ3JlZW4tazhzLXNjaGVkdWxlci04Y2I3Zjc3NzktN2M0ZGwiLCJ1aWQiOiIyODMwY2IxNS05OTM2LTQ3YjAtYTlhOS0wNjVlOTdmZDU2NGIifSwic2VydmljZWFjY291bnQiOnsibmFtZSI6ImdyZWVuLWs4cy1zY2hlZHVsZXIiLCJ1aWQiOiI2NzgyMTEwNC01NGFiLTQ2YzctYTQ3NC00YjhlODI3M2UyZWYifSwid2FybmFmdGVyIjoxNjQwMDM5MzAzfSwibmJmIjoxNjQwMDM1Njk2LCJzdWIiOiJzeXN0ZW06c2VydmljZWFjY291bnQ6a3ViZS1zeXN0ZW06Z3JlZW4tazhzLXNjaGVkdWxlciJ9.QzO_AZGr2BvZ_-W2I_yCM5mU-rv4-LxvAuo3IXheOxojip-51tgqkELWPgYJgclwuIc5ftd3gEq-qU2_O5xtFjARjpRcNzgwZedg4Yl9ZTelqQG5ZpHsE2DpvOTBB8QlcKNAYkinz7g0SSnfBJsIa8ypV9k5eSwKNSH8-2xikYWnfE0tKV9fsJiQAO1BBDZt0L8eiChCiCh3yeR7cPykyfCSSdeLfG0Ycs7yTyo0rKEMWArzdw4ZqJzqtlyuof8EGT-lpcTkv2uHaX2qNfj_43700o-XR9H6N3mAJqgSQFPaZmN0b7VrokNngHR5PhPSzBUvcX0FYEvmV4qUAWsFuw" 'https://100.64.0.1:443/api/v1/namespaces/default/pods/green-k8s-test-65bb774986-xlcp9/binding'
I1220 21:37:38.700237       1 scheduling_queue.go:830] About to try and schedule pod default/green-k8s-test-65bb774986-7jhjx
I1220 21:37:38.700372       1 scheduler.go:530] Attempting to schedule pod: default/green-k8s-test-65bb774986-7jhjx
I1220 21:37:38.700559       1 metadata.go:238] Precompute: PredicateWithExtendedResourceOptions
I1220 21:37:38.700734       1 predicates.go:908] Schedule Pod default/green-k8s-test-65bb774986-7jhjx on Node ip-172-20-40-148.ec2.internal is allowed, Node is running only 9 out of 110 Pods.
I1220 21:37:38.700860       1 generic_scheduler.go:667] since alwaysCheckAllPredicates has not been set, the predicate evaluation is short circuited and there are chances of other predicates failing as well.
I1220 21:37:38.701152       1 predicates.go:908] Schedule Pod default/green-k8s-test-65bb774986-7jhjx on Node ip-172-20-49-41.ec2.internal is allowed, Node is running only 2 out of 110 Pods.
I1220 21:37:38.701294       1 predicates.go:908] Schedule Pod default/green-k8s-test-65bb774986-7jhjx on Node ip-172-20-61-178.ec2.internal is allowed, Node is running only 3 out of 110 Pods.
I1220 21:37:38.701100       1 predicates.go:908] Schedule Pod default/green-k8s-test-65bb774986-7jhjx on Node ip-172-20-58-134.ec2.internal is allowed, Node is running only 3 out of 110 Pods.
I1220 21:37:38.701940       1 predicates.go:908] Schedule Pod default/green-k8s-test-65bb774986-7jhjx on Node ip-172-20-45-201.ec2.internal is allowed, Node is running only 2 out of 110 Pods.
I1220 21:37:38.703888       1 resource_allocation.go:84] green-k8s-test-65bb774986-7jhjx -> ip-172-20-49-41.ec2.internal: BalancedResourceAllocation, map of allocatable resources map[cpu:1000 memory:1966559232], map of requested resources map[cpu:400 memory:629145600] ,score 9,
I1220 21:37:38.703925       1 resource_allocation.go:84] green-k8s-test-65bb774986-7jhjx -> ip-172-20-49-41.ec2.internal: LeastResourceAllocation, map of allocatable resources map[cpu:1000 memory:1966559232], map of requested resources map[cpu:400 memory:629145600] ,score 6,
I1220 21:37:38.703941       1 resource_allocation.go:84] green-k8s-test-65bb774986-7jhjx -> ip-172-20-61-178.ec2.internal: BalancedResourceAllocation, map of allocatable resources map[cpu:1000 memory:1966559232], map of requested resources map[cpu:370 memory:639631360] ,score 9,
I1220 21:37:38.704038       1 resource_allocation.go:84] green-k8s-test-65bb774986-7jhjx -> ip-172-20-58-134.ec2.internal: BalancedResourceAllocation, map of allocatable resources map[cpu:1000 memory:1966559232], map of requested resources map[cpu:500 memory:702545920] ,score 8,
I1220 21:37:38.704064       1 resource_allocation.go:84] green-k8s-test-65bb774986-7jhjx -> ip-172-20-58-134.ec2.internal: LeastResourceAllocation, map of allocatable resources map[cpu:1000 memory:1966559232], map of requested resources map[cpu:500 memory:702545920] ,score 5,
I1220 21:37:38.704107       1 resource_allocation.go:84] green-k8s-test-65bb774986-7jhjx -> ip-172-20-45-201.ec2.internal: BalancedResourceAllocation, map of allocatable resources map[cpu:1000 memory:1966559232], map of requested resources map[cpu:350 memory:492830720] ,score 9,
I1220 21:37:38.704129       1 resource_allocation.go:84] green-k8s-test-65bb774986-7jhjx -> ip-172-20-45-201.ec2.internal: LeastResourceAllocation, map of allocatable resources map[cpu:1000 memory:1966559232], map of requested resources map[cpu:350 memory:492830720] ,score 6,
I1220 21:37:38.703985       1 resource_allocation.go:84] green-k8s-test-65bb774986-7jhjx -> ip-172-20-61-178.ec2.internal: LeastResourceAllocation, map of allocatable resources map[cpu:1000 memory:1966559232], map of requested resources map[cpu:370 memory:639631360] ,score 6,
I1220 21:37:38.704184       1 selector_spreading.go:146] green-k8s-test-65bb774986-7jhjx -> ip-172-20-49-41.ec2.internal: SelectorSpreadPriority, Score: (0)
I1220 21:37:38.704200       1 selector_spreading.go:146] green-k8s-test-65bb774986-7jhjx -> ip-172-20-61-178.ec2.internal: SelectorSpreadPriority, Score: (3)
I1220 21:37:38.704207       1 selector_spreading.go:146] green-k8s-test-65bb774986-7jhjx -> ip-172-20-58-134.ec2.internal: SelectorSpreadPriority, Score: (0)
I1220 21:37:38.704215       1 selector_spreading.go:146] green-k8s-test-65bb774986-7jhjx -> ip-172-20-45-201.ec2.internal: SelectorSpreadPriority, Score: (3)
I1220 21:37:38.704221       1 generic_scheduler.go:773] green-k8s-test-65bb774986-7jhjx_default -> ip-172-20-49-41.ec2.internal: ServiceSpreadingPriority, Score: (0)
I1220 21:37:38.704227       1 generic_scheduler.go:773] green-k8s-test-65bb774986-7jhjx_default -> ip-172-20-61-178.ec2.internal: ServiceSpreadingPriority, Score: (3)
I1220 21:37:38.704232       1 generic_scheduler.go:773] green-k8s-test-65bb774986-7jhjx_default -> ip-172-20-58-134.ec2.internal: ServiceSpreadingPriority, Score: (0)
I1220 21:37:38.704237       1 generic_scheduler.go:773] green-k8s-test-65bb774986-7jhjx_default -> ip-172-20-45-201.ec2.internal: ServiceSpreadingPriority, Score: (3)
I1220 21:37:38.705261       1 round_trippers.go:443] POST https://100.64.0.1:443/api/v1/namespaces/default/pods/green-k8s-test-65bb774986-xlcp9/binding 201 Created in 5 milliseconds
I1220 21:37:38.705416       1 round_trippers.go:449] Response Headers:
I1220 21:37:38.705545       1 round_trippers.go:452]     Cache-Control: no-cache, private
I1220 21:37:38.705645       1 round_trippers.go:452]     Content-Type: application/vnd.kubernetes.protobuf
I1220 21:37:38.705772       1 round_trippers.go:452]     X-Kubernetes-Pf-Flowschema-Uid: 9fb2dc3c-3c29-42f2-bb88-3d0896e45310
I1220 21:37:38.705907       1 round_trippers.go:452]     X-Kubernetes-Pf-Prioritylevel-Uid: 0d11ff8b-ca59-4914-b971-4d6f623f711b
I1220 21:37:38.705998       1 round_trippers.go:452]     Content-Length: 48
I1220 21:37:38.706131       1 round_trippers.go:452]     Date: Mon, 20 Dec 2021 21:37:38 GMT
I1220 21:37:38.708788       1 request.go:966] Response Body:
00000000  6b 38 73 00 0a 0c 0a 02  76 31 12 06 53 74 61 74  |k8s.....v1..Stat|
00000010  75 73 12 18 0a 06 0a 00  12 00 1a 00 12 07 53 75  |us............Su|
00000020  63 63 65 73 73 1a 00 22  00 30 c9 01 1a 00 22 00  |ccess..".0....".|
I1220 21:37:38.709046       1 cache.go:305] Finished binding for pod 62406daa-9de7-44e9-9bd9-d2cca9b6f416. Can be expired.
I1220 21:37:38.709118       1 event_recorder.go:54] Could not construct reference to: '<nil>' due to: 'can't reference a nil object'.
I1220 21:37:38.709615       1 scheduler.go:667] pod default/green-k8s-test-65bb774986-xlcp9 is bound successfully on node "ip-172-20-58-134.ec2.internal", 5 nodes evaluated, 4 nodes were found feasible. Bound node resource: "Capacity: CPU<1>|Memory<2022868Ki>|Pods<110>|StorageEphemeral<130045936Ki>; Allocatable: CPU<1>|Memory<1920468Ki>|Pods<110>|StorageEphemeral<119850334420>.".
I1220 21:37:38.709752       1 request.go:966] Request Body:
00000000  6b 38 73 00 0a 1e 0a 15  65 76 65 6e 74 73 2e 6b  |k8s.....events.k|
00000010  38 73 2e 69 6f 2f 76 31  62 65 74 61 31 12 05 45  |8s.io/v1beta1..E|
00000020  76 65 6e 74 12 a8 03 0a  49 0a 30 67 72 65 65 6e  |vent....I.0green|
00000030  2d 6b 38 73 2d 74 65 73  74 2d 36 35 62 62 37 37  |-k8s-test-65bb77|
00000040  34 39 38 36 2d 78 6c 63  70 39 2e 31 36 63 32 39  |4986-xlcp9.16c29|
00000050  34 34 39 62 62 32 34 65  34 64 61 12 00 1a 07 64  |449bb24e4da....d|
00000060  65 66 61 75 6c 74 22 00  2a 00 32 00 38 00 42 00  |efault".*.2.8.B.|
00000070  7a 00 12 0c 08 a2 ef 83  8e 06 10 fe ba 90 d2 02  |z...............|
00000080  22 13 67 72 65 65 6e 2d  6b 38 73 2d 73 63 68 65  |".green-k8s-sche|
00000090  64 75 6c 65 72 2a 37 67  72 65 65 6e 2d 6b 38 73  |duler*7green-k8s|
000000a0  2d 73 63 68 65 64 75 6c  65 72 2d 67 72 65 65 6e  |-scheduler-green|
000000b0  2d 6b 38 73 2d 73 63 68  65 64 75 6c 65 72 2d 38  |-k8s-scheduler-8|
000000c0  63 62 37 66 37 37 37 39  2d 37 63 34 64 6c 32 07  |cb7f7779-7c4dl2.|
000000d0  42 69 6e 64 69 6e 67 3a  09 53 63 68 65 64 75 6c  |Binding:.Schedul|
000000e0  65 64 42 64 0a 03 50 6f  64 12 07 64 65 66 61 75  |edBd..Pod..defau|
000000f0  6c 74 1a 1f 67 72 65 65  6e 2d 6b 38 73 2d 74 65  |lt..green-k8s-te|
00000100  73 74 2d 36 35 62 62 37  37 34 39 38 36 2d 78 6c  |st-65bb774986-xl|
00000110  63 70 39 22 24 36 32 34  30 36 64 61 61 2d 39 64  |cp9"$62406daa-9d|
00000120  65 37 2d 34 34 65 39 2d  39 62 64 39 2d 64 32 63  |e7-44e9-9bd9-d2c|
00000130  63 61 39 62 36 66 34 31  36 2a 02 76 31 32 07 31  |ca9b6f416*.v12.1|
00000140  34 31 37 32 35 32 3a 00  52 5e 53 75 63 63 65 73  |417252:.R^Succes|
00000150  73 66 75 6c 6c 79 20 61  73 73 69 67 6e 65 64 20  |sfully assigned |
00000160  64 65 66 61 75 6c 74 2f  67 72 65 65 6e 2d 6b 38  |default/green-k8|
00000170  73 2d 74 65 73 74 2d 36  35 62 62 37 37 34 39 38  |s-test-65bb77498|
00000180  36 2d 78 6c 63 70 39 20  74 6f 20 69 70 2d 31 37  |6-xlcp9 to ip-17|
00000190  32 2d 32 30 2d 35 38 2d  31 33 34 2e 65 63 32 2e  |2-20-58-134.ec2.|
000001a0  69 6e 74 65 72 6e 61 6c  5a 06 4e 6f 72 6d 61 6c  |internalZ.Normal|
000001b0  62 17 0a 13 67 72 65 65  6e 2d 6b 38 73 2d 73 63  |b...green-k8s-sc|
000001c0  68 65 64 75 6c 65 72 12  00 6a 00 72 00 78 00 1a  |heduler..j.r.x..|
000001d0  00 22 00                                          |.".|
I1220 21:37:38.709876       1 round_trippers.go:423] curl -k -v -XPOST  -H "Accept: application/vnd.kubernetes.protobuf, */*" -H "Content-Type: application/vnd.kubernetes.protobuf" -H "User-Agent: kube-scheduler/v1.16.3 (linux/amd64) kubernetes/b3cbbae/scheduler" -H "Authorization: Bearer eyJhbGciOiJSUzI1NiIsImtpZCI6IkI2d0Zpc0Q2S2pFdmhUX3hsRG5GZFdLemMtRkhWWmxiQmszcGVmc3RsdjQifQ.eyJhdWQiOlsia3ViZXJuZXRlcy5zdmMuZGVmYXVsdCJdLCJleHAiOjE2NzE1NzE2OTYsImlhdCI6MTY0MDAzNTY5NiwiaXNzIjoiaHR0cHM6Ly9hcGkuaW50ZXJuYWwuaGEuZ3JlZW5rOHMuY29tIiwia3ViZXJuZXRlcy5pbyI6eyJuYW1lc3BhY2UiOiJrdWJlLXN5c3RlbSIsInBvZCI6eyJuYW1lIjoiZ3JlZW4tazhzLXNjaGVkdWxlci04Y2I3Zjc3NzktN2M0ZGwiLCJ1aWQiOiIyODMwY2IxNS05OTM2LTQ3YjAtYTlhOS0wNjVlOTdmZDU2NGIifSwic2VydmljZWFjY291bnQiOnsibmFtZSI6ImdyZWVuLWs4cy1zY2hlZHVsZXIiLCJ1aWQiOiI2NzgyMTEwNC01NGFiLTQ2YzctYTQ3NC00YjhlODI3M2UyZWYifSwid2FybmFmdGVyIjoxNjQwMDM5MzAzfSwibmJmIjoxNjQwMDM1Njk2LCJzdWIiOiJzeXN0ZW06c2VydmljZWFjY291bnQ6a3ViZS1zeXN0ZW06Z3JlZW4tazhzLXNjaGVkdWxlciJ9.QzO_AZGr2BvZ_-W2I_yCM5mU-rv4-LxvAuo3IXheOxojip-51tgqkELWPgYJgclwuIc5ftd3gEq-qU2_O5xtFjARjpRcNzgwZedg4Yl9ZTelqQG5ZpHsE2DpvOTBB8QlcKNAYkinz7g0SSnfBJsIa8ypV9k5eSwKNSH8-2xikYWnfE0tKV9fsJiQAO1BBDZt0L8eiChCiCh3yeR7cPykyfCSSdeLfG0Ycs7yTyo0rKEMWArzdw4ZqJzqtlyuof8EGT-lpcTkv2uHaX2qNfj_43700o-XR9H6N3mAJqgSQFPaZmN0b7VrokNngHR5PhPSzBUvcX0FYEvmV4qUAWsFuw" 'https://100.64.0.1:443/apis/events.k8s.io/v1beta1/namespaces/default/events'
I1220 21:37:38.714202       1 round_trippers.go:443] POST https://100.64.0.1:443/apis/events.k8s.io/v1beta1/namespaces/default/events 201 Created in 4 milliseconds
I1220 21:37:38.714263       1 round_trippers.go:449] Response Headers:
I1220 21:37:38.714391       1 round_trippers.go:452]     Cache-Control: no-cache, private
I1220 21:37:38.714434       1 round_trippers.go:452]     Content-Type: application/vnd.kubernetes.protobuf
I1220 21:37:38.714460       1 round_trippers.go:452]     X-Kubernetes-Pf-Flowschema-Uid: 9fb2dc3c-3c29-42f2-bb88-3d0896e45310
I1220 21:37:38.714479       1 round_trippers.go:452]     X-Kubernetes-Pf-Prioritylevel-Uid: 0d11ff8b-ca59-4914-b971-4d6f623f711b
I1220 21:37:38.714498       1 round_trippers.go:452]     Content-Length: 864
I1220 21:37:38.714516       1 round_trippers.go:452]     Date: Mon, 20 Dec 2021 21:37:38 GMT
I1220 21:37:38.714574       1 request.go:966] Response Body:
00000000  6b 38 73 00 0a 1e 0a 15  65 76 65 6e 74 73 2e 6b  |k8s.....events.k|
00000010  38 73 2e 69 6f 2f 76 31  62 65 74 61 31 12 05 45  |8s.io/v1beta1..E|
00000020  76 65 6e 74 12 b5 06 0a  d5 03 0a 30 67 72 65 65  |vent.......0gree|
00000030  6e 2d 6b 38 73 2d 74 65  73 74 2d 36 35 62 62 37  |n-k8s-test-65bb7|
00000040  37 34 39 38 36 2d 78 6c  63 70 39 2e 31 36 63 32  |74986-xlcp9.16c2|
00000050  39 34 34 39 62 62 32 34  65 34 64 61 12 00 1a 07  |9449bb24e4da....|
00000060  64 65 66 61 75 6c 74 22  00 2a 24 33 65 32 61 38  |default".*$3e2a8|
00000070  31 34 34 2d 35 65 37 38  2d 34 30 30 30 2d 38 35  |144-5e78-4000-85|
00000080  65 38 2d 65 39 32 61 34  33 64 35 32 33 66 32 32  |e8-e92a43d523f22|
00000090  04 32 37 30 38 38 00 42  08 08 a2 ef 83 8e 06 10  |.27088.B........|
000000a0  00 7a 00 8a 01 d8 02 0a  0e 6b 75 62 65 2d 73 63  |.z.......kube-sc|
000000b0  68 65 64 75 6c 65 72 12  06 55 70 64 61 74 65 1a  |heduler..Update.|
000000c0  15 65 76 65 6e 74 73 2e  6b 38 73 2e 69 6f 2f 76  |.events.k8s.io/v|
000000d0  31 62 65 74 61 31 22 08  08 a2 ef 83 8e 06 10 00  |1beta1".........|
000000e0  32 08 46 69 65 6c 64 73  56 31 3a 92 02 0a 8f 02  |2.FieldsV1:.....|
000000f0  7b 22 66 3a 61 63 74 69  6f 6e 22 3a 7b 7d 2c 22  |{"f:action":{},"|
00000100  66 3a 64 65 70 72 65 63  61 74 65 64 53 6f 75 72  |f:deprecatedSour|
00000110  63 65 22 3a 7b 22 66 3a  63 6f 6d 70 6f 6e 65 6e  |ce":{"f:componen|
00000120  74 22 3a 7b 7d 7d 2c 22  66 3a 65 76 65 6e 74 54  |t":{}},"f:eventT|
00000130  69 6d 65 22 3a 7b 7d 2c  22 66 3a 6e 6f 74 65 22  |ime":{},"f:note"|
00000140  3a 7b 7d 2c 22 66 3a 72  65 61 73 6f 6e 22 3a 7b  |:{},"f:reason":{|
00000150  7d 2c 22 66 3a 72 65 67  61 72 64 69 6e 67 22 3a  |},"f:regarding":|
00000160  7b 22 66 3a 61 70 69 56  65 72 73 69 6f 6e 22 3a  |{"f:apiVersion":|
00000170  7b 7d 2c 22 66 3a 6b 69  6e 64 22 3a 7b 7d 2c 22  |{},"f:kind":{},"|
00000180  66 3a 6e 61 6d 65 22 3a  7b 7d 2c 22 66 3a 6e 61  |f:name":{},"f:na|
00000190  6d 65 73 70 61 63 65 22  3a 7b 7d 2c 22 66 3a 72  |mespace":{},"f:r|
000001a0  65 73 6f 75 72 63 65 56  65 72 73 69 6f 6e 22 3a  |esourceVersion":|
000001b0  7b 7d 2c 22 66 3a 75 69  64 22 3a 7b 7d 7d 2c 22  |{},"f:uid":{}},"|
000001c0  66 3a 72 65 70 6f 72 74  69 6e 67 43 6f 6e 74 72  |f:reportingContr|
000001d0  6f 6c 6c 65 72 22 3a 7b  7d 2c 22 66 3a 72 65 70  |oller":{},"f:rep|
000001e0  6f 72 74 69 6e 67 49 6e  73 74 61 6e 63 65 22 3a  |ortingInstance":|
000001f0  7b 7d 2c 22 66 3a 74 79  70 65 22 3a 7b 7d 7d 12  |{},"f:type":{}}.|
00000200  0c 08 a2 ef 83 8e 06 10  fe ba 90 d2 02 22 13 67  |.............".g|
00000210  72 65 65 6e 2d 6b 38 73  2d 73 63 68 65 64 75 6c  |reen-k8s-schedul|
00000220  65 72 2a 37 67 72 65 65  6e 2d 6b 38 73 2d 73 63  |er*7green-k8s-sc|
00000230  68 65 64 75 6c 65 72 2d  67 72 65 65 6e 2d 6b 38  |heduler-green-k8|
00000240  73 2d 73 63 68 65 64 75  6c 65 72 2d 38 63 62 37  |s-scheduler-8cb7|
00000250  66 37 37 37 39 2d 37 63  34 64 6c 32 07 42 69 6e  |f7779-7c4dl2.Bin|
00000260  64 69 6e 67 3a 09 53 63  68 65 64 75 6c 65 64 42  |ding:.ScheduledB|
00000270  64 0a 03 50 6f 64 12 07  64 65 66 61 75 6c 74 1a  |d..Pod..default.|
00000280  1f 67 72 65 65 6e 2d 6b  38 73 2d 74 65 73 74 2d  |.green-k8s-test-|
00000290  36 35 62 62 37 37 34 39  38 36 2d 78 6c 63 70 39  |65bb774986-xlcp9|
000002a0  22 24 36 32 34 30 36 64  61 61 2d 39 64 65 37 2d  |"$62406daa-9de7-|
000002b0  34 34 65 39 2d 39 62 64  39 2d 64 32 63 63 61 39  |44e9-9bd9-d2cca9|
000002c0  62 36 66 34 31 36 2a 02  76 31 32 07 31 34 31 37  |b6f416*.v12.1417|
000002d0  32 35 32 3a 00 52 5e 53  75 63 63 65 73 73 66 75  |252:.R^Successfu|
000002e0  6c 6c 79 20 61 73 73 69  67 6e 65 64 20 64 65 66  |lly assigned def|
000002f0  61 75 6c 74 2f 67 72 65  65 6e 2d 6b 38 73 2d 74  |ault/green-k8s-t|
00000300  65 73 74 2d 36 35 62 62  37 37 34 39 38 36 2d 78  |est-65bb774986-x|
00000310  6c 63 70 39 20 74 6f 20  69 70 2d 31 37 32 2d 32  |lcp9 to ip-172-2|
00000320  30 2d 35 38 2d 31 33 34  2e 65 63 32 2e 69 6e 74  |0-58-134.ec2.int|
00000330  65 72 6e 61 6c 5a 06 4e  6f 72 6d 61 6c 62 17 0a  |ernalZ.Normalb..|
00000340  13 67 72 65 65 6e 2d 6b  38 73 2d 73 63 68 65 64  |.green-k8s-sched|
00000350  75 6c 65 72 12 00 6a 00  72 00 78 00 1a 00 22 00  |uler..j.r.x...".|
I1220 21:37:38.720924       1 generic_scheduler.go:822] green-k8s-test-65bb774986-7jhjx_default -> ip-172-20-49-41.ec2.internal: http://localhost:80, Score: (10)
I1220 21:37:38.720949       1 generic_scheduler.go:822] green-k8s-test-65bb774986-7jhjx_default -> ip-172-20-61-178.ec2.internal: http://localhost:80, Score: (6)
I1220 21:37:38.720957       1 generic_scheduler.go:822] green-k8s-test-65bb774986-7jhjx_default -> ip-172-20-58-134.ec2.internal: http://localhost:80, Score: (10)
I1220 21:37:38.720962       1 generic_scheduler.go:822] green-k8s-test-65bb774986-7jhjx_default -> ip-172-20-45-201.ec2.internal: http://localhost:80, Score: (0)
I1220 21:37:38.721067       1 generic_scheduler.go:838] Host ip-172-20-49-41.ec2.internal => Score 26
I1220 21:37:38.721087       1 generic_scheduler.go:838] Host ip-172-20-61-178.ec2.internal => Score 25
I1220 21:37:38.721094       1 generic_scheduler.go:838] Host ip-172-20-58-134.ec2.internal => Score 24
I1220 21:37:38.721100       1 generic_scheduler.go:838] Host ip-172-20-45-201.ec2.internal => Score 19
I1220 21:37:38.721189       1 scheduler_binder.go:256] AssumePodVolumes for pod "default/green-k8s-test-65bb774986-7jhjx", node "ip-172-20-49-41.ec2.internal"
I1220 21:37:38.721211       1 scheduler_binder.go:266] AssumePodVolumes for pod "default/green-k8s-test-65bb774986-7jhjx", node "ip-172-20-49-41.ec2.internal": all PVCs bound and nothing to do
I1220 21:37:38.721286       1 factory.go:610] Attempting to bind green-k8s-test-65bb774986-7jhjx to ip-172-20-49-41.ec2.internal
I1220 21:37:38.721407       1 request.go:966] Request Body:
00000000  6b 38 73 00 0a 0d 0a 02  76 31 12 07 42 69 6e 64  |k8s.....v1..Bind|
00000010  69 6e 67 12 8e 01 0a 5c  0a 1f 67 72 65 65 6e 2d  |ing....\..green-|
00000020  6b 38 73 2d 74 65 73 74  2d 36 35 62 62 37 37 34  |k8s-test-65bb774|
00000030  39 38 36 2d 37 6a 68 6a  78 12 00 1a 07 64 65 66  |986-7jhjx....def|
00000040  61 75 6c 74 22 00 2a 24  39 64 62 36 30 32 34 31  |ault".*$9db60241|
00000050  2d 37 38 63 39 2d 34 30  39 39 2d 61 64 39 62 2d  |-78c9-4099-ad9b-|
00000060  61 66 65 38 66 35 63 33  66 34 39 35 32 00 38 00  |afe8f5c3f4952.8.|
00000070  42 00 7a 00 12 2e 0a 04  4e 6f 64 65 12 00 1a 1c  |B.z.....Node....|
00000080  69 70 2d 31 37 32 2d 32  30 2d 34 39 2d 34 31 2e  |ip-172-20-49-41.|
00000090  65 63 32 2e 69 6e 74 65  72 6e 61 6c 22 00 2a 00  |ec2.internal".*.|
000000a0  32 00 3a 00 1a 00 22 00                           |2.:...".|
I1220 21:37:38.721552       1 round_trippers.go:423] curl -k -v -XPOST  -H "Accept: application/vnd.kubernetes.protobuf, */*" -H "Content-Type: application/vnd.kubernetes.protobuf" -H "User-Agent: kube-scheduler/v1.16.3 (linux/amd64) kubernetes/b3cbbae/scheduler" -H "Authorization: Bearer eyJhbGciOiJSUzI1NiIsImtpZCI6IkI2d0Zpc0Q2S2pFdmhUX3hsRG5GZFdLemMtRkhWWmxiQmszcGVmc3RsdjQifQ.eyJhdWQiOlsia3ViZXJuZXRlcy5zdmMuZGVmYXVsdCJdLCJleHAiOjE2NzE1NzE2OTYsImlhdCI6MTY0MDAzNTY5NiwiaXNzIjoiaHR0cHM6Ly9hcGkuaW50ZXJuYWwuaGEuZ3JlZW5rOHMuY29tIiwia3ViZXJuZXRlcy5pbyI6eyJuYW1lc3BhY2UiOiJrdWJlLXN5c3RlbSIsInBvZCI6eyJuYW1lIjoiZ3JlZW4tazhzLXNjaGVkdWxlci04Y2I3Zjc3NzktN2M0ZGwiLCJ1aWQiOiIyODMwY2IxNS05OTM2LTQ3YjAtYTlhOS0wNjVlOTdmZDU2NGIifSwic2VydmljZWFjY291bnQiOnsibmFtZSI6ImdyZWVuLWs4cy1zY2hlZHVsZXIiLCJ1aWQiOiI2NzgyMTEwNC01NGFiLTQ2YzctYTQ3NC00YjhlODI3M2UyZWYifSwid2FybmFmdGVyIjoxNjQwMDM5MzAzfSwibmJmIjoxNjQwMDM1Njk2LCJzdWIiOiJzeXN0ZW06c2VydmljZWFjY291bnQ6a3ViZS1zeXN0ZW06Z3JlZW4tazhzLXNjaGVkdWxlciJ9.QzO_AZGr2BvZ_-W2I_yCM5mU-rv4-LxvAuo3IXheOxojip-51tgqkELWPgYJgclwuIc5ftd3gEq-qU2_O5xtFjARjpRcNzgwZedg4Yl9ZTelqQG5ZpHsE2DpvOTBB8QlcKNAYkinz7g0SSnfBJsIa8ypV9k5eSwKNSH8-2xikYWnfE0tKV9fsJiQAO1BBDZt0L8eiChCiCh3yeR7cPykyfCSSdeLfG0Ycs7yTyo0rKEMWArzdw4ZqJzqtlyuof8EGT-lpcTkv2uHaX2qNfj_43700o-XR9H6N3mAJqgSQFPaZmN0b7VrokNngHR5PhPSzBUvcX0FYEvmV4qUAWsFuw" 'https://100.64.0.1:443/api/v1/namespaces/default/pods/green-k8s-test-65bb774986-7jhjx/binding'
I1220 21:37:38.724948       1 scheduling_queue.go:830] About to try and schedule pod default/green-k8s-test-65bb774986-rv9l7
I1220 21:37:38.724975       1 scheduler.go:530] Attempting to schedule pod: default/green-k8s-test-65bb774986-rv9l7
I1220 21:37:38.725134       1 metadata.go:238] Precompute: PredicateWithExtendedResourceOptions
I1220 21:37:38.725195       1 predicates.go:908] Schedule Pod default/green-k8s-test-65bb774986-rv9l7 on Node ip-172-20-40-148.ec2.internal is allowed, Node is running only 9 out of 110 Pods.
I1220 21:37:38.725217       1 generic_scheduler.go:667] since alwaysCheckAllPredicates has not been set, the predicate evaluation is short circuited and there are chances of other predicates failing as well.
I1220 21:37:38.725233       1 predicates.go:908] Schedule Pod default/green-k8s-test-65bb774986-rv9l7 on Node ip-172-20-58-134.ec2.internal is allowed, Node is running only 3 out of 110 Pods.
I1220 21:37:38.725310       1 predicates.go:908] Schedule Pod default/green-k8s-test-65bb774986-rv9l7 on Node ip-172-20-45-201.ec2.internal is allowed, Node is running only 2 out of 110 Pods.
I1220 21:37:38.725332       1 predicates.go:908] Schedule Pod default/green-k8s-test-65bb774986-rv9l7 on Node ip-172-20-49-41.ec2.internal is allowed, Node is running only 3 out of 110 Pods.
I1220 21:37:38.725343       1 predicates.go:908] Schedule Pod default/green-k8s-test-65bb774986-rv9l7 on Node ip-172-20-61-178.ec2.internal is allowed, Node is running only 3 out of 110 Pods.
I1220 21:37:38.725498       1 resource_allocation.go:84] green-k8s-test-65bb774986-rv9l7 -> ip-172-20-58-134.ec2.internal: BalancedResourceAllocation, map of allocatable resources map[cpu:1000 memory:1966559232], map of requested resources map[cpu:500 memory:702545920] ,score 8,
I1220 21:37:38.725528       1 resource_allocation.go:84] green-k8s-test-65bb774986-rv9l7 -> ip-172-20-58-134.ec2.internal: LeastResourceAllocation, map of allocatable resources map[cpu:1000 memory:1966559232], map of requested resources map[cpu:500 memory:702545920] ,score 5,
I1220 21:37:38.725545       1 resource_allocation.go:84] green-k8s-test-65bb774986-rv9l7 -> ip-172-20-45-201.ec2.internal: BalancedResourceAllocation, map of allocatable resources map[cpu:1000 memory:1966559232], map of requested resources map[cpu:350 memory:492830720] ,score 9,
I1220 21:37:38.725586       1 resource_allocation.go:84] green-k8s-test-65bb774986-rv9l7 -> ip-172-20-45-201.ec2.internal: LeastResourceAllocation, map of allocatable resources map[cpu:1000 memory:1966559232], map of requested resources map[cpu:350 memory:492830720] ,score 6,
I1220 21:37:38.725655       1 resource_allocation.go:84] green-k8s-test-65bb774986-rv9l7 -> ip-172-20-49-41.ec2.internal: BalancedResourceAllocation, map of allocatable resources map[cpu:1000 memory:1966559232], map of requested resources map[cpu:550 memory:838860800] ,score 8,
I1220 21:37:38.725685       1 resource_allocation.go:84] green-k8s-test-65bb774986-rv9l7 -> ip-172-20-49-41.ec2.internal: LeastResourceAllocation, map of allocatable resources map[cpu:1000 memory:1966559232], map of requested resources map[cpu:550 memory:838860800] ,score 4,
I1220 21:37:38.725709       1 resource_allocation.go:84] green-k8s-test-65bb774986-rv9l7 -> ip-172-20-61-178.ec2.internal: BalancedResourceAllocation, map of allocatable resources map[cpu:1000 memory:1966559232], map of requested resources map[cpu:370 memory:639631360] ,score 9,
I1220 21:37:38.725723       1 resource_allocation.go:84] green-k8s-test-65bb774986-rv9l7 -> ip-172-20-61-178.ec2.internal: LeastResourceAllocation, map of allocatable resources map[cpu:1000 memory:1966559232], map of requested resources map[cpu:370 memory:639631360] ,score 6,
I1220 21:37:38.725762       1 selector_spreading.go:146] green-k8s-test-65bb774986-rv9l7 -> ip-172-20-58-134.ec2.internal: SelectorSpreadPriority, Score: (1)
I1220 21:37:38.725826       1 selector_spreading.go:146] green-k8s-test-65bb774986-rv9l7 -> ip-172-20-45-201.ec2.internal: SelectorSpreadPriority, Score: (3)
I1220 21:37:38.725833       1 selector_spreading.go:146] green-k8s-test-65bb774986-rv9l7 -> ip-172-20-49-41.ec2.internal: SelectorSpreadPriority, Score: (0)
I1220 21:37:38.725839       1 selector_spreading.go:146] green-k8s-test-65bb774986-rv9l7 -> ip-172-20-61-178.ec2.internal: SelectorSpreadPriority, Score: (3)
I1220 21:37:38.725846       1 generic_scheduler.go:773] green-k8s-test-65bb774986-rv9l7_default -> ip-172-20-58-134.ec2.internal: ServiceSpreadingPriority, Score: (1)
I1220 21:37:38.725853       1 generic_scheduler.go:773] green-k8s-test-65bb774986-rv9l7_default -> ip-172-20-45-201.ec2.internal: ServiceSpreadingPriority, Score: (3)
I1220 21:37:38.725859       1 generic_scheduler.go:773] green-k8s-test-65bb774986-rv9l7_default -> ip-172-20-49-41.ec2.internal: ServiceSpreadingPriority, Score: (0)
I1220 21:37:38.725866       1 generic_scheduler.go:773] green-k8s-test-65bb774986-rv9l7_default -> ip-172-20-61-178.ec2.internal: ServiceSpreadingPriority, Score: (3)
I1220 21:37:38.726917       1 round_trippers.go:443] POST https://100.64.0.1:443/api/v1/namespaces/default/pods/green-k8s-test-65bb774986-7jhjx/binding 201 Created in 5 milliseconds
I1220 21:37:38.726976       1 round_trippers.go:449] Response Headers:
I1220 21:37:38.726983       1 round_trippers.go:452]     Cache-Control: no-cache, private
I1220 21:37:38.727010       1 round_trippers.go:452]     Content-Type: application/vnd.kubernetes.protobuf
I1220 21:37:38.727024       1 round_trippers.go:452]     X-Kubernetes-Pf-Flowschema-Uid: 9fb2dc3c-3c29-42f2-bb88-3d0896e45310
I1220 21:37:38.727029       1 round_trippers.go:452]     X-Kubernetes-Pf-Prioritylevel-Uid: 0d11ff8b-ca59-4914-b971-4d6f623f711b
I1220 21:37:38.727034       1 round_trippers.go:452]     Content-Length: 48
I1220 21:37:38.727039       1 round_trippers.go:452]     Date: Mon, 20 Dec 2021 21:37:38 GMT
I1220 21:37:38.727062       1 request.go:966] Response Body:
00000000  6b 38 73 00 0a 0c 0a 02  76 31 12 06 53 74 61 74  |k8s.....v1..Stat|
00000010  75 73 12 18 0a 06 0a 00  12 00 1a 00 12 07 53 75  |us............Su|
00000020  63 63 65 73 73 1a 00 22  00 30 c9 01 1a 00 22 00  |ccess..".0....".|
I1220 21:37:38.727189       1 cache.go:305] Finished binding for pod 9db60241-78c9-4099-ad9b-afe8f5c3f495. Can be expired.
I1220 21:37:38.727265       1 event_recorder.go:54] Could not construct reference to: '<nil>' due to: 'can't reference a nil object'.
I1220 21:37:38.727379       1 scheduler.go:667] pod default/green-k8s-test-65bb774986-7jhjx is bound successfully on node "ip-172-20-49-41.ec2.internal", 5 nodes evaluated, 4 nodes were found feasible. Bound node resource: "Capacity: CPU<1>|Memory<2022868Ki>|Pods<110>|StorageEphemeral<130045936Ki>; Allocatable: CPU<1>|Memory<1920468Ki>|Pods<110>|StorageEphemeral<119850334420>.".
I1220 21:37:38.727473       1 request.go:966] Request Body:
00000000  6b 38 73 00 0a 1e 0a 15  65 76 65 6e 74 73 2e 6b  |k8s.....events.k|
00000010  38 73 2e 69 6f 2f 76 31  62 65 74 61 31 12 05 45  |8s.io/v1beta1..E|
00000020  76 65 6e 74 12 a7 03 0a  49 0a 30 67 72 65 65 6e  |vent....I.0green|
00000030  2d 6b 38 73 2d 74 65 73  74 2d 36 35 62 62 37 37  |-k8s-test-65bb77|
00000040  34 39 38 36 2d 37 6a 68  6a 78 2e 31 36 63 32 39  |4986-7jhjx.16c29|
00000050  34 34 39 62 63 33 33 34  33 32 37 12 00 1a 07 64  |449bc334327....d|
00000060  65 66 61 75 6c 74 22 00  2a 00 32 00 38 00 42 00  |efault".*.2.8.B.|
00000070  7a 00 12 0c 08 a2 ef 83  8e 06 10 e9 89 e4 da 02  |z...............|
00000080  22 13 67 72 65 65 6e 2d  6b 38 73 2d 73 63 68 65  |".green-k8s-sche|
00000090  64 75 6c 65 72 2a 37 67  72 65 65 6e 2d 6b 38 73  |duler*7green-k8s|
000000a0  2d 73 63 68 65 64 75 6c  65 72 2d 67 72 65 65 6e  |-scheduler-green|
000000b0  2d 6b 38 73 2d 73 63 68  65 64 75 6c 65 72 2d 38  |-k8s-scheduler-8|
000000c0  63 62 37 66 37 37 37 39  2d 37 63 34 64 6c 32 07  |cb7f7779-7c4dl2.|
000000d0  42 69 6e 64 69 6e 67 3a  09 53 63 68 65 64 75 6c  |Binding:.Schedul|
000000e0  65 64 42 64 0a 03 50 6f  64 12 07 64 65 66 61 75  |edBd..Pod..defau|
000000f0  6c 74 1a 1f 67 72 65 65  6e 2d 6b 38 73 2d 74 65  |lt..green-k8s-te|
00000100  73 74 2d 36 35 62 62 37  37 34 39 38 36 2d 37 6a  |st-65bb774986-7j|
00000110  68 6a 78 22 24 39 64 62  36 30 32 34 31 2d 37 38  |hjx"$9db60241-78|
00000120  63 39 2d 34 30 39 39 2d  61 64 39 62 2d 61 66 65  |c9-4099-ad9b-afe|
00000130  38 66 35 63 33 66 34 39  35 2a 02 76 31 32 07 31  |8f5c3f495*.v12.1|
00000140  34 31 37 32 35 33 3a 00  52 5d 53 75 63 63 65 73  |417253:.R]Succes|
00000150  73 66 75 6c 6c 79 20 61  73 73 69 67 6e 65 64 20  |sfully assigned |
00000160  64 65 66 61 75 6c 74 2f  67 72 65 65 6e 2d 6b 38  |default/green-k8|
00000170  73 2d 74 65 73 74 2d 36  35 62 62 37 37 34 39 38  |s-test-65bb77498|
00000180  36 2d 37 6a 68 6a 78 20  74 6f 20 69 70 2d 31 37  |6-7jhjx to ip-17|
00000190  32 2d 32 30 2d 34 39 2d  34 31 2e 65 63 32 2e 69  |2-20-49-41.ec2.i|
000001a0  6e 74 65 72 6e 61 6c 5a  06 4e 6f 72 6d 61 6c 62  |nternalZ.Normalb|
000001b0  17 0a 13 67 72 65 65 6e  2d 6b 38 73 2d 73 63 68  |...green-k8s-sch|
000001c0  65 64 75 6c 65 72 12 00  6a 00 72 00 78 00 1a 00  |eduler..j.r.x...|
000001d0  22 00                                             |".|
I1220 21:37:38.727590       1 round_trippers.go:423] curl -k -v -XPOST  -H "Accept: application/vnd.kubernetes.protobuf, */*" -H "Content-Type: application/vnd.kubernetes.protobuf" -H "User-Agent: kube-scheduler/v1.16.3 (linux/amd64) kubernetes/b3cbbae/scheduler" -H "Authorization: Bearer eyJhbGciOiJSUzI1NiIsImtpZCI6IkI2d0Zpc0Q2S2pFdmhUX3hsRG5GZFdLemMtRkhWWmxiQmszcGVmc3RsdjQifQ.eyJhdWQiOlsia3ViZXJuZXRlcy5zdmMuZGVmYXVsdCJdLCJleHAiOjE2NzE1NzE2OTYsImlhdCI6MTY0MDAzNTY5NiwiaXNzIjoiaHR0cHM6Ly9hcGkuaW50ZXJuYWwuaGEuZ3JlZW5rOHMuY29tIiwia3ViZXJuZXRlcy5pbyI6eyJuYW1lc3BhY2UiOiJrdWJlLXN5c3RlbSIsInBvZCI6eyJuYW1lIjoiZ3JlZW4tazhzLXNjaGVkdWxlci04Y2I3Zjc3NzktN2M0ZGwiLCJ1aWQiOiIyODMwY2IxNS05OTM2LTQ3YjAtYTlhOS0wNjVlOTdmZDU2NGIifSwic2VydmljZWFjY291bnQiOnsibmFtZSI6ImdyZWVuLWs4cy1zY2hlZHVsZXIiLCJ1aWQiOiI2NzgyMTEwNC01NGFiLTQ2YzctYTQ3NC00YjhlODI3M2UyZWYifSwid2FybmFmdGVyIjoxNjQwMDM5MzAzfSwibmJmIjoxNjQwMDM1Njk2LCJzdWIiOiJzeXN0ZW06c2VydmljZWFjY291bnQ6a3ViZS1zeXN0ZW06Z3JlZW4tazhzLXNjaGVkdWxlciJ9.QzO_AZGr2BvZ_-W2I_yCM5mU-rv4-LxvAuo3IXheOxojip-51tgqkELWPgYJgclwuIc5ftd3gEq-qU2_O5xtFjARjpRcNzgwZedg4Yl9ZTelqQG5ZpHsE2DpvOTBB8QlcKNAYkinz7g0SSnfBJsIa8ypV9k5eSwKNSH8-2xikYWnfE0tKV9fsJiQAO1BBDZt0L8eiChCiCh3yeR7cPykyfCSSdeLfG0Ycs7yTyo0rKEMWArzdw4ZqJzqtlyuof8EGT-lpcTkv2uHaX2qNfj_43700o-XR9H6N3mAJqgSQFPaZmN0b7VrokNngHR5PhPSzBUvcX0FYEvmV4qUAWsFuw" 'https://100.64.0.1:443/apis/events.k8s.io/v1beta1/namespaces/default/events'
I1220 21:37:38.730234       1 round_trippers.go:443] POST https://100.64.0.1:443/apis/events.k8s.io/v1beta1/namespaces/default/events 201 Created in 2 milliseconds
I1220 21:37:38.730692       1 round_trippers.go:449] Response Headers:
I1220 21:37:38.730711       1 round_trippers.go:452]     Cache-Control: no-cache, private
I1220 21:37:38.730795       1 round_trippers.go:452]     Content-Type: application/vnd.kubernetes.protobuf
I1220 21:37:38.730801       1 round_trippers.go:452]     X-Kubernetes-Pf-Flowschema-Uid: 9fb2dc3c-3c29-42f2-bb88-3d0896e45310
I1220 21:37:38.730807       1 round_trippers.go:452]     X-Kubernetes-Pf-Prioritylevel-Uid: 0d11ff8b-ca59-4914-b971-4d6f623f711b
I1220 21:37:38.730812       1 round_trippers.go:452]     Content-Length: 863
I1220 21:37:38.730817       1 round_trippers.go:452]     Date: Mon, 20 Dec 2021 21:37:38 GMT
I1220 21:37:38.731097       1 request.go:966] Response Body:
00000000  6b 38 73 00 0a 1e 0a 15  65 76 65 6e 74 73 2e 6b  |k8s.....events.k|
00000010  38 73 2e 69 6f 2f 76 31  62 65 74 61 31 12 05 45  |8s.io/v1beta1..E|
00000020  76 65 6e 74 12 b4 06 0a  d5 03 0a 30 67 72 65 65  |vent.......0gree|
00000030  6e 2d 6b 38 73 2d 74 65  73 74 2d 36 35 62 62 37  |n-k8s-test-65bb7|
00000040  37 34 39 38 36 2d 37 6a  68 6a 78 2e 31 36 63 32  |74986-7jhjx.16c2|
00000050  39 34 34 39 62 63 33 33  34 33 32 37 12 00 1a 07  |9449bc334327....|
00000060  64 65 66 61 75 6c 74 22  00 2a 24 36 66 31 30 66  |default".*$6f10f|
00000070  32 34 61 2d 38 32 39 33  2d 34 35 35 61 2d 61 64  |24a-8293-455a-ad|
00000080  39 36 2d 33 66 33 33 65  32 36 61 65 62 32 33 32  |96-3f33e26aeb232|
00000090  04 32 37 30 39 38 00 42  08 08 a2 ef 83 8e 06 10  |.27098.B........|
000000a0  00 7a 00 8a 01 d8 02 0a  0e 6b 75 62 65 2d 73 63  |.z.......kube-sc|
000000b0  68 65 64 75 6c 65 72 12  06 55 70 64 61 74 65 1a  |heduler..Update.|
000000c0  15 65 76 65 6e 74 73 2e  6b 38 73 2e 69 6f 2f 76  |.events.k8s.io/v|
000000d0  31 62 65 74 61 31 22 08  08 a2 ef 83 8e 06 10 00  |1beta1".........|
000000e0  32 08 46 69 65 6c 64 73  56 31 3a 92 02 0a 8f 02  |2.FieldsV1:.....|
000000f0  7b 22 66 3a 61 63 74 69  6f 6e 22 3a 7b 7d 2c 22  |{"f:action":{},"|
00000100  66 3a 64 65 70 72 65 63  61 74 65 64 53 6f 75 72  |f:deprecatedSour|
00000110  63 65 22 3a 7b 22 66 3a  63 6f 6d 70 6f 6e 65 6e  |ce":{"f:componen|
00000120  74 22 3a 7b 7d 7d 2c 22  66 3a 65 76 65 6e 74 54  |t":{}},"f:eventT|
00000130  69 6d 65 22 3a 7b 7d 2c  22 66 3a 6e 6f 74 65 22  |ime":{},"f:note"|
00000140  3a 7b 7d 2c 22 66 3a 72  65 61 73 6f 6e 22 3a 7b  |:{},"f:reason":{|
00000150  7d 2c 22 66 3a 72 65 67  61 72 64 69 6e 67 22 3a  |},"f:regarding":|
00000160  7b 22 66 3a 61 70 69 56  65 72 73 69 6f 6e 22 3a  |{"f:apiVersion":|
00000170  7b 7d 2c 22 66 3a 6b 69  6e 64 22 3a 7b 7d 2c 22  |{},"f:kind":{},"|
00000180  66 3a 6e 61 6d 65 22 3a  7b 7d 2c 22 66 3a 6e 61  |f:name":{},"f:na|
00000190  6d 65 73 70 61 63 65 22  3a 7b 7d 2c 22 66 3a 72  |mespace":{},"f:r|
000001a0  65 73 6f 75 72 63 65 56  65 72 73 69 6f 6e 22 3a  |esourceVersion":|
000001b0  7b 7d 2c 22 66 3a 75 69  64 22 3a 7b 7d 7d 2c 22  |{},"f:uid":{}},"|
000001c0  66 3a 72 65 70 6f 72 74  69 6e 67 43 6f 6e 74 72  |f:reportingContr|
000001d0  6f 6c 6c 65 72 22 3a 7b  7d 2c 22 66 3a 72 65 70  |oller":{},"f:rep|
000001e0  6f 72 74 69 6e 67 49 6e  73 74 61 6e 63 65 22 3a  |ortingInstance":|
000001f0  7b 7d 2c 22 66 3a 74 79  70 65 22 3a 7b 7d 7d 12  |{},"f:type":{}}.|
00000200  0c 08 a2 ef 83 8e 06 10  e9 89 e4 da 02 22 13 67  |.............".g|
00000210  72 65 65 6e 2d 6b 38 73  2d 73 63 68 65 64 75 6c  |reen-k8s-schedul|
00000220  65 72 2a 37 67 72 65 65  6e 2d 6b 38 73 2d 73 63  |er*7green-k8s-sc|
00000230  68 65 64 75 6c 65 72 2d  67 72 65 65 6e 2d 6b 38  |heduler-green-k8|
00000240  73 2d 73 63 68 65 64 75  6c 65 72 2d 38 63 62 37  |s-scheduler-8cb7|
00000250  66 37 37 37 39 2d 37 63  34 64 6c 32 07 42 69 6e  |f7779-7c4dl2.Bin|
00000260  64 69 6e 67 3a 09 53 63  68 65 64 75 6c 65 64 42  |ding:.ScheduledB|
00000270  64 0a 03 50 6f 64 12 07  64 65 66 61 75 6c 74 1a  |d..Pod..default.|
00000280  1f 67 72 65 65 6e 2d 6b  38 73 2d 74 65 73 74 2d  |.green-k8s-test-|
00000290  36 35 62 62 37 37 34 39  38 36 2d 37 6a 68 6a 78  |65bb774986-7jhjx|
000002a0  22 24 39 64 62 36 30 32  34 31 2d 37 38 63 39 2d  |"$9db60241-78c9-|
000002b0  34 30 39 39 2d 61 64 39  62 2d 61 66 65 38 66 35  |4099-ad9b-afe8f5|
000002c0  63 33 66 34 39 35 2a 02  76 31 32 07 31 34 31 37  |c3f495*.v12.1417|
000002d0  32 35 33 3a 00 52 5d 53  75 63 63 65 73 73 66 75  |253:.R]Successfu|
000002e0  6c 6c 79 20 61 73 73 69  67 6e 65 64 20 64 65 66  |lly assigned def|
000002f0  61 75 6c 74 2f 67 72 65  65 6e 2d 6b 38 73 2d 74  |ault/green-k8s-t|
00000300  65 73 74 2d 36 35 62 62  37 37 34 39 38 36 2d 37  |est-65bb774986-7|
00000310  6a 68 6a 78 20 74 6f 20  69 70 2d 31 37 32 2d 32  |jhjx to ip-172-2|
00000320  30 2d 34 39 2d 34 31 2e  65 63 32 2e 69 6e 74 65  |0-49-41.ec2.inte|
00000330  72 6e 61 6c 5a 06 4e 6f  72 6d 61 6c 62 17 0a 13  |rnalZ.Normalb...|
00000340  67 72 65 65 6e 2d 6b 38  73 2d 73 63 68 65 64 75  |green-k8s-schedu|
00000350  6c 65 72 12 00 6a 00 72  00 78 00 1a 00 22 00     |ler..j.r.x...".|
I1220 21:37:38.739627       1 generic_scheduler.go:822] green-k8s-test-65bb774986-rv9l7_default -> ip-172-20-58-134.ec2.internal: http://localhost:80, Score: (10)
I1220 21:37:38.739652       1 generic_scheduler.go:822] green-k8s-test-65bb774986-rv9l7_default -> ip-172-20-45-201.ec2.internal: http://localhost:80, Score: (0)
I1220 21:37:38.739659       1 generic_scheduler.go:822] green-k8s-test-65bb774986-rv9l7_default -> ip-172-20-49-41.ec2.internal: http://localhost:80, Score: (10)
I1220 21:37:38.739664       1 generic_scheduler.go:822] green-k8s-test-65bb774986-rv9l7_default -> ip-172-20-61-178.ec2.internal: http://localhost:80, Score: (6)
I1220 21:37:38.739811       1 generic_scheduler.go:838] Host ip-172-20-58-134.ec2.internal => Score 25
I1220 21:37:38.739825       1 generic_scheduler.go:838] Host ip-172-20-45-201.ec2.internal => Score 19
I1220 21:37:38.739831       1 generic_scheduler.go:838] Host ip-172-20-49-41.ec2.internal => Score 23
I1220 21:37:38.739836       1 generic_scheduler.go:838] Host ip-172-20-61-178.ec2.internal => Score 25
I1220 21:37:38.739960       1 scheduler_binder.go:256] AssumePodVolumes for pod "default/green-k8s-test-65bb774986-rv9l7", node "ip-172-20-58-134.ec2.internal"
I1220 21:37:38.739983       1 scheduler_binder.go:266] AssumePodVolumes for pod "default/green-k8s-test-65bb774986-rv9l7", node "ip-172-20-58-134.ec2.internal": all PVCs bound and nothing to do
I1220 21:37:38.740038       1 factory.go:610] Attempting to bind green-k8s-test-65bb774986-rv9l7 to ip-172-20-58-134.ec2.internal
I1220 21:37:38.740081       1 request.go:966] Request Body:
00000000  6b 38 73 00 0a 0d 0a 02  76 31 12 07 42 69 6e 64  |k8s.....v1..Bind|
00000010  69 6e 67 12 8f 01 0a 5c  0a 1f 67 72 65 65 6e 2d  |ing....\..green-|
00000020  6b 38 73 2d 74 65 73 74  2d 36 35 62 62 37 37 34  |k8s-test-65bb774|
00000030  39 38 36 2d 72 76 39 6c  37 12 00 1a 07 64 65 66  |986-rv9l7....def|
00000040  61 75 6c 74 22 00 2a 24  61 37 61 33 35 62 63 62  |ault".*$a7a35bcb|
00000050  2d 61 64 33 31 2d 34 35  65 33 2d 61 61 36 61 2d  |-ad31-45e3-aa6a-|
00000060  39 36 36 33 33 33 65 32  30 38 63 33 32 00 38 00  |966333e208c32.8.|
00000070  42 00 7a 00 12 2f 0a 04  4e 6f 64 65 12 00 1a 1d  |B.z../..Node....|
00000080  69 70 2d 31 37 32 2d 32  30 2d 35 38 2d 31 33 34  |ip-172-20-58-134|
00000090  2e 65 63 32 2e 69 6e 74  65 72 6e 61 6c 22 00 2a  |.ec2.internal".*|
000000a0  00 32 00 3a 00 1a 00 22  00                       |.2.:...".|
I1220 21:37:38.740205       1 round_trippers.go:423] curl -k -v -XPOST  -H "Content-Type: application/vnd.kubernetes.protobuf" -H "User-Agent: kube-scheduler/v1.16.3 (linux/amd64) kubernetes/b3cbbae/scheduler" -H "Accept: application/vnd.kubernetes.protobuf, */*" -H "Authorization: Bearer eyJhbGciOiJSUzI1NiIsImtpZCI6IkI2d0Zpc0Q2S2pFdmhUX3hsRG5GZFdLemMtRkhWWmxiQmszcGVmc3RsdjQifQ.eyJhdWQiOlsia3ViZXJuZXRlcy5zdmMuZGVmYXVsdCJdLCJleHAiOjE2NzE1NzE2OTYsImlhdCI6MTY0MDAzNTY5NiwiaXNzIjoiaHR0cHM6Ly9hcGkuaW50ZXJuYWwuaGEuZ3JlZW5rOHMuY29tIiwia3ViZXJuZXRlcy5pbyI6eyJuYW1lc3BhY2UiOiJrdWJlLXN5c3RlbSIsInBvZCI6eyJuYW1lIjoiZ3JlZW4tazhzLXNjaGVkdWxlci04Y2I3Zjc3NzktN2M0ZGwiLCJ1aWQiOiIyODMwY2IxNS05OTM2LTQ3YjAtYTlhOS0wNjVlOTdmZDU2NGIifSwic2VydmljZWFjY291bnQiOnsibmFtZSI6ImdyZWVuLWs4cy1zY2hlZHVsZXIiLCJ1aWQiOiI2NzgyMTEwNC01NGFiLTQ2YzctYTQ3NC00YjhlODI3M2UyZWYifSwid2FybmFmdGVyIjoxNjQwMDM5MzAzfSwibmJmIjoxNjQwMDM1Njk2LCJzdWIiOiJzeXN0ZW06c2VydmljZWFjY291bnQ6a3ViZS1zeXN0ZW06Z3JlZW4tazhzLXNjaGVkdWxlciJ9.QzO_AZGr2BvZ_-W2I_yCM5mU-rv4-LxvAuo3IXheOxojip-51tgqkELWPgYJgclwuIc5ftd3gEq-qU2_O5xtFjARjpRcNzgwZedg4Yl9ZTelqQG5ZpHsE2DpvOTBB8QlcKNAYkinz7g0SSnfBJsIa8ypV9k5eSwKNSH8-2xikYWnfE0tKV9fsJiQAO1BBDZt0L8eiChCiCh3yeR7cPykyfCSSdeLfG0Ycs7yTyo0rKEMWArzdw4ZqJzqtlyuof8EGT-lpcTkv2uHaX2qNfj_43700o-XR9H6N3mAJqgSQFPaZmN0b7VrokNngHR5PhPSzBUvcX0FYEvmV4qUAWsFuw" 'https://100.64.0.1:443/api/v1/namespaces/default/pods/green-k8s-test-65bb774986-rv9l7/binding'
I1220 21:37:38.740432       1 scheduling_queue.go:830] About to try and schedule pod default/green-k8s-test-65bb774986-cnxmz
I1220 21:37:38.740453       1 scheduler.go:530] Attempting to schedule pod: default/green-k8s-test-65bb774986-cnxmz
I1220 21:37:38.740503       1 metadata.go:238] Precompute: PredicateWithExtendedResourceOptions
I1220 21:37:38.740558       1 predicates.go:908] Schedule Pod default/green-k8s-test-65bb774986-cnxmz on Node ip-172-20-40-148.ec2.internal is allowed, Node is running only 9 out of 110 Pods.
I1220 21:37:38.740577       1 generic_scheduler.go:667] since alwaysCheckAllPredicates has not been set, the predicate evaluation is short circuited and there are chances of other predicates failing as well.
I1220 21:37:38.740591       1 predicates.go:908] Schedule Pod default/green-k8s-test-65bb774986-cnxmz on Node ip-172-20-58-134.ec2.internal is allowed, Node is running only 4 out of 110 Pods.
I1220 21:37:38.740640       1 predicates.go:908] Schedule Pod default/green-k8s-test-65bb774986-cnxmz on Node ip-172-20-45-201.ec2.internal is allowed, Node is running only 2 out of 110 Pods.
I1220 21:37:38.740661       1 predicates.go:908] Schedule Pod default/green-k8s-test-65bb774986-cnxmz on Node ip-172-20-49-41.ec2.internal is allowed, Node is running only 3 out of 110 Pods.
I1220 21:37:38.740673       1 predicates.go:908] Schedule Pod default/green-k8s-test-65bb774986-cnxmz on Node ip-172-20-61-178.ec2.internal is allowed, Node is running only 3 out of 110 Pods.
I1220 21:37:38.740778       1 resource_allocation.go:84] green-k8s-test-65bb774986-cnxmz -> ip-172-20-58-134.ec2.internal: BalancedResourceAllocation, map of allocatable resources map[cpu:1000 memory:1966559232], map of requested resources map[cpu:650 memory:912261120] ,score 8,
I1220 21:37:38.740849       1 resource_allocation.go:84] green-k8s-test-65bb774986-cnxmz -> ip-172-20-58-134.ec2.internal: LeastResourceAllocation, map of allocatable resources map[cpu:1000 memory:1966559232], map of requested resources map[cpu:650 memory:912261120] ,score 4,
I1220 21:37:38.742561       1 resource_allocation.go:84] green-k8s-test-65bb774986-cnxmz -> ip-172-20-45-201.ec2.internal: BalancedResourceAllocation, map of allocatable resources map[cpu:1000 memory:1966559232], map of requested resources map[cpu:350 memory:492830720] ,score 9,
I1220 21:37:38.742599       1 resource_allocation.go:84] green-k8s-test-65bb774986-cnxmz -> ip-172-20-45-201.ec2.internal: LeastResourceAllocation, map of allocatable resources map[cpu:1000 memory:1966559232], map of requested resources map[cpu:350 memory:492830720] ,score 6,
I1220 21:37:38.742614       1 resource_allocation.go:84] green-k8s-test-65bb774986-cnxmz -> ip-172-20-49-41.ec2.internal: BalancedResourceAllocation, map of allocatable resources map[cpu:1000 memory:1966559232], map of requested resources map[cpu:550 memory:838860800] ,score 8,
I1220 21:37:38.742628       1 resource_allocation.go:84] green-k8s-test-65bb774986-cnxmz -> ip-172-20-49-41.ec2.internal: LeastResourceAllocation, map of allocatable resources map[cpu:1000 memory:1966559232], map of requested resources map[cpu:550 memory:838860800] ,score 4,
I1220 21:37:38.742642       1 resource_allocation.go:84] green-k8s-test-65bb774986-cnxmz -> ip-172-20-61-178.ec2.internal: BalancedResourceAllocation, map of allocatable resources map[cpu:1000 memory:1966559232], map of requested resources map[cpu:370 memory:639631360] ,score 9,
I1220 21:37:38.742655       1 resource_allocation.go:84] green-k8s-test-65bb774986-cnxmz -> ip-172-20-61-178.ec2.internal: LeastResourceAllocation, map of allocatable resources map[cpu:1000 memory:1966559232], map of requested resources map[cpu:370 memory:639631360] ,score 6,
I1220 21:37:38.742990       1 selector_spreading.go:146] green-k8s-test-65bb774986-cnxmz -> ip-172-20-58-134.ec2.internal: SelectorSpreadPriority, Score: (0)
I1220 21:37:38.743070       1 selector_spreading.go:146] green-k8s-test-65bb774986-cnxmz -> ip-172-20-45-201.ec2.internal: SelectorSpreadPriority, Score: (3)
I1220 21:37:38.743088       1 selector_spreading.go:146] green-k8s-test-65bb774986-cnxmz -> ip-172-20-49-41.ec2.internal: SelectorSpreadPriority, Score: (0)
I1220 21:37:38.743094       1 selector_spreading.go:146] green-k8s-test-65bb774986-cnxmz -> ip-172-20-61-178.ec2.internal: SelectorSpreadPriority, Score: (3)
I1220 21:37:38.743100       1 generic_scheduler.go:773] green-k8s-test-65bb774986-cnxmz_default -> ip-172-20-58-134.ec2.internal: ServiceSpreadingPriority, Score: (0)
I1220 21:37:38.743188       1 generic_scheduler.go:773] green-k8s-test-65bb774986-cnxmz_default -> ip-172-20-45-201.ec2.internal: ServiceSpreadingPriority, Score: (3)
I1220 21:37:38.743204       1 generic_scheduler.go:773] green-k8s-test-65bb774986-cnxmz_default -> ip-172-20-49-41.ec2.internal: ServiceSpreadingPriority, Score: (0)
I1220 21:37:38.743209       1 generic_scheduler.go:773] green-k8s-test-65bb774986-cnxmz_default -> ip-172-20-61-178.ec2.internal: ServiceSpreadingPriority, Score: (3)
I1220 21:37:38.750502       1 round_trippers.go:443] POST https://100.64.0.1:443/api/v1/namespaces/default/pods/green-k8s-test-65bb774986-rv9l7/binding 201 Created in 10 milliseconds
I1220 21:37:38.750525       1 round_trippers.go:449] Response Headers:
I1220 21:37:38.750532       1 round_trippers.go:452]     Cache-Control: no-cache, private
I1220 21:37:38.750537       1 round_trippers.go:452]     Content-Type: application/vnd.kubernetes.protobuf
I1220 21:37:38.750542       1 round_trippers.go:452]     X-Kubernetes-Pf-Flowschema-Uid: 9fb2dc3c-3c29-42f2-bb88-3d0896e45310
I1220 21:37:38.751407       1 round_trippers.go:452]     X-Kubernetes-Pf-Prioritylevel-Uid: 0d11ff8b-ca59-4914-b971-4d6f623f711b
I1220 21:37:38.751425       1 round_trippers.go:452]     Content-Length: 48
I1220 21:37:38.751430       1 round_trippers.go:452]     Date: Mon, 20 Dec 2021 21:37:38 GMT
I1220 21:37:38.752422       1 request.go:966] Response Body:
00000000  6b 38 73 00 0a 0c 0a 02  76 31 12 06 53 74 61 74  |k8s.....v1..Stat|
00000010  75 73 12 18 0a 06 0a 00  12 00 1a 00 12 07 53 75  |us............Su|
00000020  63 63 65 73 73 1a 00 22  00 30 c9 01 1a 00 22 00  |ccess..".0....".|
I1220 21:37:38.752544       1 cache.go:305] Finished binding for pod a7a35bcb-ad31-45e3-aa6a-966333e208c3. Can be expired.
I1220 21:37:38.756660       1 event_recorder.go:54] Could not construct reference to: '<nil>' due to: 'can't reference a nil object'.
I1220 21:37:38.756703       1 scheduler.go:667] pod default/green-k8s-test-65bb774986-rv9l7 is bound successfully on node "ip-172-20-58-134.ec2.internal", 5 nodes evaluated, 4 nodes were found feasible. Bound node resource: "Capacity: CPU<1>|Memory<2022868Ki>|Pods<110>|StorageEphemeral<130045936Ki>; Allocatable: CPU<1>|Memory<1920468Ki>|Pods<110>|StorageEphemeral<119850334420>.".
I1220 21:37:38.759717       1 request.go:966] Request Body:
00000000  6b 38 73 00 0a 1e 0a 15  65 76 65 6e 74 73 2e 6b  |k8s.....events.k|
00000010  38 73 2e 69 6f 2f 76 31  62 65 74 61 31 12 05 45  |8s.io/v1beta1..E|
00000020  76 65 6e 74 12 a8 03 0a  49 0a 30 67 72 65 65 6e  |vent....I.0green|
00000030  2d 6b 38 73 2d 74 65 73  74 2d 36 35 62 62 37 37  |-k8s-test-65bb77|
00000040  34 39 38 36 2d 72 76 39  6c 37 2e 31 36 63 32 39  |4986-rv9l7.16c29|
00000050  34 34 39 62 64 66 33 64  37 61 38 12 00 1a 07 64  |449bdf3d7a8....d|
00000060  65 66 61 75 6c 74 22 00  2a 00 32 00 38 00 42 00  |efault".*.2.8.B.|
00000070  7a 00 12 0c 08 a2 ef 83  8e 06 10 cb 87 e6 e8 02  |z...............|
00000080  22 13 67 72 65 65 6e 2d  6b 38 73 2d 73 63 68 65  |".green-k8s-sche|
00000090  64 75 6c 65 72 2a 37 67  72 65 65 6e 2d 6b 38 73  |duler*7green-k8s|
000000a0  2d 73 63 68 65 64 75 6c  65 72 2d 67 72 65 65 6e  |-scheduler-green|
000000b0  2d 6b 38 73 2d 73 63 68  65 64 75 6c 65 72 2d 38  |-k8s-scheduler-8|
000000c0  63 62 37 66 37 37 37 39  2d 37 63 34 64 6c 32 07  |cb7f7779-7c4dl2.|
000000d0  42 69 6e 64 69 6e 67 3a  09 53 63 68 65 64 75 6c  |Binding:.Schedul|
000000e0  65 64 42 64 0a 03 50 6f  64 12 07 64 65 66 61 75  |edBd..Pod..defau|
000000f0  6c 74 1a 1f 67 72 65 65  6e 2d 6b 38 73 2d 74 65  |lt..green-k8s-te|
00000100  73 74 2d 36 35 62 62 37  37 34 39 38 36 2d 72 76  |st-65bb774986-rv|
00000110  39 6c 37 22 24 61 37 61  33 35 62 63 62 2d 61 64  |9l7"$a7a35bcb-ad|
00000120  33 31 2d 34 35 65 33 2d  61 61 36 61 2d 39 36 36  |31-45e3-aa6a-966|
00000130  33 33 33 65 32 30 38 63  33 2a 02 76 31 32 07 31  |333e208c3*.v12.1|
00000140  34 31 37 32 35 34 3a 00  52 5e 53 75 63 63 65 73  |417254:.R^Succes|
00000150  73 66 75 6c 6c 79 20 61  73 73 69 67 6e 65 64 20  |sfully assigned |
00000160  64 65 66 61 75 6c 74 2f  67 72 65 65 6e 2d 6b 38  |default/green-k8|
00000170  73 2d 74 65 73 74 2d 36  35 62 62 37 37 34 39 38  |s-test-65bb77498|
00000180  36 2d 72 76 39 6c 37 20  74 6f 20 69 70 2d 31 37  |6-rv9l7 to ip-17|
00000190  32 2d 32 30 2d 35 38 2d  31 33 34 2e 65 63 32 2e  |2-20-58-134.ec2.|
000001a0  69 6e 74 65 72 6e 61 6c  5a 06 4e 6f 72 6d 61 6c  |internalZ.Normal|
000001b0  62 17 0a 13 67 72 65 65  6e 2d 6b 38 73 2d 73 63  |b...green-k8s-sc|
000001c0  68 65 64 75 6c 65 72 12  00 6a 00 72 00 78 00 1a  |heduler..j.r.x..|
000001d0  00 22 00                                          |.".|
I1220 21:37:38.761708       1 round_trippers.go:423] curl -k -v -XPOST  -H "Content-Type: application/vnd.kubernetes.protobuf" -H "User-Agent: kube-scheduler/v1.16.3 (linux/amd64) kubernetes/b3cbbae/scheduler" -H "Authorization: Bearer eyJhbGciOiJSUzI1NiIsImtpZCI6IkI2d0Zpc0Q2S2pFdmhUX3hsRG5GZFdLemMtRkhWWmxiQmszcGVmc3RsdjQifQ.eyJhdWQiOlsia3ViZXJuZXRlcy5zdmMuZGVmYXVsdCJdLCJleHAiOjE2NzE1NzE2OTYsImlhdCI6MTY0MDAzNTY5NiwiaXNzIjoiaHR0cHM6Ly9hcGkuaW50ZXJuYWwuaGEuZ3JlZW5rOHMuY29tIiwia3ViZXJuZXRlcy5pbyI6eyJuYW1lc3BhY2UiOiJrdWJlLXN5c3RlbSIsInBvZCI6eyJuYW1lIjoiZ3JlZW4tazhzLXNjaGVkdWxlci04Y2I3Zjc3NzktN2M0ZGwiLCJ1aWQiOiIyODMwY2IxNS05OTM2LTQ3YjAtYTlhOS0wNjVlOTdmZDU2NGIifSwic2VydmljZWFjY291bnQiOnsibmFtZSI6ImdyZWVuLWs4cy1zY2hlZHVsZXIiLCJ1aWQiOiI2NzgyMTEwNC01NGFiLTQ2YzctYTQ3NC00YjhlODI3M2UyZWYifSwid2FybmFmdGVyIjoxNjQwMDM5MzAzfSwibmJmIjoxNjQwMDM1Njk2LCJzdWIiOiJzeXN0ZW06c2VydmljZWFjY291bnQ6a3ViZS1zeXN0ZW06Z3JlZW4tazhzLXNjaGVkdWxlciJ9.QzO_AZGr2BvZ_-W2I_yCM5mU-rv4-LxvAuo3IXheOxojip-51tgqkELWPgYJgclwuIc5ftd3gEq-qU2_O5xtFjARjpRcNzgwZedg4Yl9ZTelqQG5ZpHsE2DpvOTBB8QlcKNAYkinz7g0SSnfBJsIa8ypV9k5eSwKNSH8-2xikYWnfE0tKV9fsJiQAO1BBDZt0L8eiChCiCh3yeR7cPykyfCSSdeLfG0Ycs7yTyo0rKEMWArzdw4ZqJzqtlyuof8EGT-lpcTkv2uHaX2qNfj_43700o-XR9H6N3mAJqgSQFPaZmN0b7VrokNngHR5PhPSzBUvcX0FYEvmV4qUAWsFuw" -H "Accept: application/vnd.kubernetes.protobuf, */*" 'https://100.64.0.1:443/apis/events.k8s.io/v1beta1/namespaces/default/events'
I1220 21:37:38.765656       1 round_trippers.go:443] POST https://100.64.0.1:443/apis/events.k8s.io/v1beta1/namespaces/default/events 201 Created in 3 milliseconds
I1220 21:37:38.765678       1 round_trippers.go:449] Response Headers:
I1220 21:37:38.765684       1 round_trippers.go:452]     X-Kubernetes-Pf-Flowschema-Uid: 9fb2dc3c-3c29-42f2-bb88-3d0896e45310
I1220 21:37:38.765690       1 round_trippers.go:452]     X-Kubernetes-Pf-Prioritylevel-Uid: 0d11ff8b-ca59-4914-b971-4d6f623f711b
I1220 21:37:38.765695       1 round_trippers.go:452]     Content-Length: 864
I1220 21:37:38.765700       1 round_trippers.go:452]     Date: Mon, 20 Dec 2021 21:37:38 GMT
I1220 21:37:38.766149       1 round_trippers.go:452]     Cache-Control: no-cache, private
I1220 21:37:38.766155       1 round_trippers.go:452]     Content-Type: application/vnd.kubernetes.protobuf
I1220 21:37:38.766286       1 request.go:966] Response Body:
00000000  6b 38 73 00 0a 1e 0a 15  65 76 65 6e 74 73 2e 6b  |k8s.....events.k|
00000010  38 73 2e 69 6f 2f 76 31  62 65 74 61 31 12 05 45  |8s.io/v1beta1..E|
00000020  76 65 6e 74 12 b5 06 0a  d5 03 0a 30 67 72 65 65  |vent.......0gree|
00000030  6e 2d 6b 38 73 2d 74 65  73 74 2d 36 35 62 62 37  |n-k8s-test-65bb7|
00000040  37 34 39 38 36 2d 72 76  39 6c 37 2e 31 36 63 32  |74986-rv9l7.16c2|
00000050  39 34 34 39 62 64 66 33  64 37 61 38 12 00 1a 07  |9449bdf3d7a8....|
00000060  64 65 66 61 75 6c 74 22  00 2a 24 37 31 36 63 63  |default".*$716cc|
00000070  39 64 63 2d 66 37 64 64  2d 34 39 66 36 2d 38 37  |9dc-f7dd-49f6-87|
00000080  37 34 2d 37 38 64 31 63  37 31 62 64 32 65 64 32  |74-78d1c71bd2ed2|
00000090  04 32 37 31 30 38 00 42  08 08 a2 ef 83 8e 06 10  |.27108.B........|
000000a0  00 7a 00 8a 01 d8 02 0a  0e 6b 75 62 65 2d 73 63  |.z.......kube-sc|
000000b0  68 65 64 75 6c 65 72 12  06 55 70 64 61 74 65 1a  |heduler..Update.|
000000c0  15 65 76 65 6e 74 73 2e  6b 38 73 2e 69 6f 2f 76  |.events.k8s.io/v|
000000d0  31 62 65 74 61 31 22 08  08 a2 ef 83 8e 06 10 00  |1beta1".........|
000000e0  32 08 46 69 65 6c 64 73  56 31 3a 92 02 0a 8f 02  |2.FieldsV1:.....|
000000f0  7b 22 66 3a 61 63 74 69  6f 6e 22 3a 7b 7d 2c 22  |{"f:action":{},"|
00000100  66 3a 64 65 70 72 65 63  61 74 65 64 53 6f 75 72  |f:deprecatedSour|
00000110  63 65 22 3a 7b 22 66 3a  63 6f 6d 70 6f 6e 65 6e  |ce":{"f:componen|
00000120  74 22 3a 7b 7d 7d 2c 22  66 3a 65 76 65 6e 74 54  |t":{}},"f:eventT|
00000130  69 6d 65 22 3a 7b 7d 2c  22 66 3a 6e 6f 74 65 22  |ime":{},"f:note"|
00000140  3a 7b 7d 2c 22 66 3a 72  65 61 73 6f 6e 22 3a 7b  |:{},"f:reason":{|
00000150  7d 2c 22 66 3a 72 65 67  61 72 64 69 6e 67 22 3a  |},"f:regarding":|
00000160  7b 22 66 3a 61 70 69 56  65 72 73 69 6f 6e 22 3a  |{"f:apiVersion":|
00000170  7b 7d 2c 22 66 3a 6b 69  6e 64 22 3a 7b 7d 2c 22  |{},"f:kind":{},"|
00000180  66 3a 6e 61 6d 65 22 3a  7b 7d 2c 22 66 3a 6e 61  |f:name":{},"f:na|
00000190  6d 65 73 70 61 63 65 22  3a 7b 7d 2c 22 66 3a 72  |mespace":{},"f:r|
000001a0  65 73 6f 75 72 63 65 56  65 72 73 69 6f 6e 22 3a  |esourceVersion":|
000001b0  7b 7d 2c 22 66 3a 75 69  64 22 3a 7b 7d 7d 2c 22  |{},"f:uid":{}},"|
000001c0  66 3a 72 65 70 6f 72 74  69 6e 67 43 6f 6e 74 72  |f:reportingContr|
000001d0  6f 6c 6c 65 72 22 3a 7b  7d 2c 22 66 3a 72 65 70  |oller":{},"f:rep|
000001e0  6f 72 74 69 6e 67 49 6e  73 74 61 6e 63 65 22 3a  |ortingInstance":|
000001f0  7b 7d 2c 22 66 3a 74 79  70 65 22 3a 7b 7d 7d 12  |{},"f:type":{}}.|
00000200  0c 08 a2 ef 83 8e 06 10  cb 87 e6 e8 02 22 13 67  |.............".g|
00000210  72 65 65 6e 2d 6b 38 73  2d 73 63 68 65 64 75 6c  |reen-k8s-schedul|
00000220  65 72 2a 37 67 72 65 65  6e 2d 6b 38 73 2d 73 63  |er*7green-k8s-sc|
00000230  68 65 64 75 6c 65 72 2d  67 72 65 65 6e 2d 6b 38  |heduler-green-k8|
00000240  73 2d 73 63 68 65 64 75  6c 65 72 2d 38 63 62 37  |s-scheduler-8cb7|
00000250  66 37 37 37 39 2d 37 63  34 64 6c 32 07 42 69 6e  |f7779-7c4dl2.Bin|
00000260  64 69 6e 67 3a 09 53 63  68 65 64 75 6c 65 64 42  |ding:.ScheduledB|
00000270  64 0a 03 50 6f 64 12 07  64 65 66 61 75 6c 74 1a  |d..Pod..default.|
00000280  1f 67 72 65 65 6e 2d 6b  38 73 2d 74 65 73 74 2d  |.green-k8s-test-|
00000290  36 35 62 62 37 37 34 39  38 36 2d 72 76 39 6c 37  |65bb774986-rv9l7|
000002a0  22 24 61 37 61 33 35 62  63 62 2d 61 64 33 31 2d  |"$a7a35bcb-ad31-|
000002b0  34 35 65 33 2d 61 61 36  61 2d 39 36 36 33 33 33  |45e3-aa6a-966333|
000002c0  65 32 30 38 63 33 2a 02  76 31 32 07 31 34 31 37  |e208c3*.v12.1417|
000002d0  32 35 34 3a 00 52 5e 53  75 63 63 65 73 73 66 75  |254:.R^Successfu|
000002e0  6c 6c 79 20 61 73 73 69  67 6e 65 64 20 64 65 66  |lly assigned def|
000002f0  61 75 6c 74 2f 67 72 65  65 6e 2d 6b 38 73 2d 74  |ault/green-k8s-t|
00000300  65 73 74 2d 36 35 62 62  37 37 34 39 38 36 2d 72  |est-65bb774986-r|
00000310  76 39 6c 37 20 74 6f 20  69 70 2d 31 37 32 2d 32  |v9l7 to ip-172-2|
00000320  30 2d 35 38 2d 31 33 34  2e 65 63 32 2e 69 6e 74  |0-58-134.ec2.int|
00000330  65 72 6e 61 6c 5a 06 4e  6f 72 6d 61 6c 62 17 0a  |ernalZ.Normalb..|
00000340  13 67 72 65 65 6e 2d 6b  38 73 2d 73 63 68 65 64  |.green-k8s-sched|
00000350  75 6c 65 72 12 00 6a 00  72 00 78 00 1a 00 22 00  |uler..j.r.x...".|
I1220 21:37:38.780223       1 generic_scheduler.go:822] green-k8s-test-65bb774986-cnxmz_default -> ip-172-20-58-134.ec2.internal: http://localhost:80, Score: (10)
I1220 21:37:38.780244       1 generic_scheduler.go:822] green-k8s-test-65bb774986-cnxmz_default -> ip-172-20-45-201.ec2.internal: http://localhost:80, Score: (0)
I1220 21:37:38.780250       1 generic_scheduler.go:822] green-k8s-test-65bb774986-cnxmz_default -> ip-172-20-49-41.ec2.internal: http://localhost:80, Score: (10)
I1220 21:37:38.780255       1 generic_scheduler.go:822] green-k8s-test-65bb774986-cnxmz_default -> ip-172-20-61-178.ec2.internal: http://localhost:80, Score: (6)
I1220 21:37:38.780397       1 generic_scheduler.go:838] Host ip-172-20-58-134.ec2.internal => Score 23
I1220 21:37:38.780417       1 generic_scheduler.go:838] Host ip-172-20-45-201.ec2.internal => Score 19
I1220 21:37:38.780423       1 generic_scheduler.go:838] Host ip-172-20-49-41.ec2.internal => Score 23
I1220 21:37:38.780428       1 generic_scheduler.go:838] Host ip-172-20-61-178.ec2.internal => Score 25
I1220 21:37:38.780566       1 scheduler_binder.go:256] AssumePodVolumes for pod "default/green-k8s-test-65bb774986-cnxmz", node "ip-172-20-61-178.ec2.internal"
I1220 21:37:38.780589       1 scheduler_binder.go:266] AssumePodVolumes for pod "default/green-k8s-test-65bb774986-cnxmz", node "ip-172-20-61-178.ec2.internal": all PVCs bound and nothing to do
I1220 21:37:38.780748       1 factory.go:610] Attempting to bind green-k8s-test-65bb774986-cnxmz to ip-172-20-61-178.ec2.internal
I1220 21:37:38.780874       1 request.go:966] Request Body:
00000000  6b 38 73 00 0a 0d 0a 02  76 31 12 07 42 69 6e 64  |k8s.....v1..Bind|
00000010  69 6e 67 12 8f 01 0a 5c  0a 1f 67 72 65 65 6e 2d  |ing....\..green-|
00000020  6b 38 73 2d 74 65 73 74  2d 36 35 62 62 37 37 34  |k8s-test-65bb774|
00000030  39 38 36 2d 63 6e 78 6d  7a 12 00 1a 07 64 65 66  |986-cnxmz....def|
00000040  61 75 6c 74 22 00 2a 24  62 32 34 32 61 66 32 30  |ault".*$b242af20|
00000050  2d 66 36 36 32 2d 34 35  32 39 2d 61 36 39 62 2d  |-f662-4529-a69b-|
00000060  64 66 63 35 31 38 64 32  61 35 63 31 32 00 38 00  |dfc518d2a5c12.8.|
00000070  42 00 7a 00 12 2f 0a 04  4e 6f 64 65 12 00 1a 1d  |B.z../..Node....|
00000080  69 70 2d 31 37 32 2d 32  30 2d 36 31 2d 31 37 38  |ip-172-20-61-178|
00000090  2e 65 63 32 2e 69 6e 74  65 72 6e 61 6c 22 00 2a  |.ec2.internal".*|
000000a0  00 32 00 3a 00 1a 00 22  00                       |.2.:...".|
I1220 21:37:38.781097       1 round_trippers.go:423] curl -k -v -XPOST  -H "Authorization: Bearer eyJhbGciOiJSUzI1NiIsImtpZCI6IkI2d0Zpc0Q2S2pFdmhUX3hsRG5GZFdLemMtRkhWWmxiQmszcGVmc3RsdjQifQ.eyJhdWQiOlsia3ViZXJuZXRlcy5zdmMuZGVmYXVsdCJdLCJleHAiOjE2NzE1NzE2OTYsImlhdCI6MTY0MDAzNTY5NiwiaXNzIjoiaHR0cHM6Ly9hcGkuaW50ZXJuYWwuaGEuZ3JlZW5rOHMuY29tIiwia3ViZXJuZXRlcy5pbyI6eyJuYW1lc3BhY2UiOiJrdWJlLXN5c3RlbSIsInBvZCI6eyJuYW1lIjoiZ3JlZW4tazhzLXNjaGVkdWxlci04Y2I3Zjc3NzktN2M0ZGwiLCJ1aWQiOiIyODMwY2IxNS05OTM2LTQ3YjAtYTlhOS0wNjVlOTdmZDU2NGIifSwic2VydmljZWFjY291bnQiOnsibmFtZSI6ImdyZWVuLWs4cy1zY2hlZHVsZXIiLCJ1aWQiOiI2NzgyMTEwNC01NGFiLTQ2YzctYTQ3NC00YjhlODI3M2UyZWYifSwid2FybmFmdGVyIjoxNjQwMDM5MzAzfSwibmJmIjoxNjQwMDM1Njk2LCJzdWIiOiJzeXN0ZW06c2VydmljZWFjY291bnQ6a3ViZS1zeXN0ZW06Z3JlZW4tazhzLXNjaGVkdWxlciJ9.QzO_AZGr2BvZ_-W2I_yCM5mU-rv4-LxvAuo3IXheOxojip-51tgqkELWPgYJgclwuIc5ftd3gEq-qU2_O5xtFjARjpRcNzgwZedg4Yl9ZTelqQG5ZpHsE2DpvOTBB8QlcKNAYkinz7g0SSnfBJsIa8ypV9k5eSwKNSH8-2xikYWnfE0tKV9fsJiQAO1BBDZt0L8eiChCiCh3yeR7cPykyfCSSdeLfG0Ycs7yTyo0rKEMWArzdw4ZqJzqtlyuof8EGT-lpcTkv2uHaX2qNfj_43700o-XR9H6N3mAJqgSQFPaZmN0b7VrokNngHR5PhPSzBUvcX0FYEvmV4qUAWsFuw" -H "Content-Type: application/vnd.kubernetes.protobuf" -H "Accept: application/vnd.kubernetes.protobuf, */*" -H "User-Agent: kube-scheduler/v1.16.3 (linux/amd64) kubernetes/b3cbbae/scheduler" 'https://100.64.0.1:443/api/v1/namespaces/default/pods/green-k8s-test-65bb774986-cnxmz/binding'
I1220 21:37:38.781368       1 scheduling_queue.go:830] About to try and schedule pod default/green-k8s-test-65bb774986-s7tzx
I1220 21:37:38.781490       1 scheduler.go:530] Attempting to schedule pod: default/green-k8s-test-65bb774986-s7tzx
I1220 21:37:38.781689       1 metadata.go:238] Precompute: PredicateWithExtendedResourceOptions
I1220 21:37:38.781851       1 predicates.go:908] Schedule Pod default/green-k8s-test-65bb774986-s7tzx on Node ip-172-20-40-148.ec2.internal is allowed, Node is running only 9 out of 110 Pods.
I1220 21:37:38.781988       1 generic_scheduler.go:667] since alwaysCheckAllPredicates has not been set, the predicate evaluation is short circuited and there are chances of other predicates failing as well.
I1220 21:37:38.782127       1 predicates.go:908] Schedule Pod default/green-k8s-test-65bb774986-s7tzx on Node ip-172-20-58-134.ec2.internal is allowed, Node is running only 4 out of 110 Pods.
I1220 21:37:38.782196       1 predicates.go:908] Schedule Pod default/green-k8s-test-65bb774986-s7tzx on Node ip-172-20-45-201.ec2.internal is allowed, Node is running only 2 out of 110 Pods.
I1220 21:37:38.782242       1 predicates.go:908] Schedule Pod default/green-k8s-test-65bb774986-s7tzx on Node ip-172-20-49-41.ec2.internal is allowed, Node is running only 3 out of 110 Pods.
I1220 21:37:38.782331       1 predicates.go:908] Schedule Pod default/green-k8s-test-65bb774986-s7tzx on Node ip-172-20-61-178.ec2.internal is allowed, Node is running only 4 out of 110 Pods.
I1220 21:37:38.782555       1 resource_allocation.go:84] green-k8s-test-65bb774986-s7tzx -> ip-172-20-58-134.ec2.internal: BalancedResourceAllocation, map of allocatable resources map[cpu:1000 memory:1966559232], map of requested resources map[cpu:650 memory:912261120] ,score 8,
I1220 21:37:38.782635       1 resource_allocation.go:84] green-k8s-test-65bb774986-s7tzx -> ip-172-20-58-134.ec2.internal: LeastResourceAllocation, map of allocatable resources map[cpu:1000 memory:1966559232], map of requested resources map[cpu:650 memory:912261120] ,score 4,
I1220 21:37:38.782732       1 resource_allocation.go:84] green-k8s-test-65bb774986-s7tzx -> ip-172-20-45-201.ec2.internal: BalancedResourceAllocation, map of allocatable resources map[cpu:1000 memory:1966559232], map of requested resources map[cpu:350 memory:492830720] ,score 9,
I1220 21:37:38.782789       1 resource_allocation.go:84] green-k8s-test-65bb774986-s7tzx -> ip-172-20-45-201.ec2.internal: LeastResourceAllocation, map of allocatable resources map[cpu:1000 memory:1966559232], map of requested resources map[cpu:350 memory:492830720] ,score 6,
I1220 21:37:38.782823       1 resource_allocation.go:84] green-k8s-test-65bb774986-s7tzx -> ip-172-20-49-41.ec2.internal: BalancedResourceAllocation, map of allocatable resources map[cpu:1000 memory:1966559232], map of requested resources map[cpu:550 memory:838860800] ,score 8,
I1220 21:37:38.782916       1 resource_allocation.go:84] green-k8s-test-65bb774986-s7tzx -> ip-172-20-49-41.ec2.internal: LeastResourceAllocation, map of allocatable resources map[cpu:1000 memory:1966559232], map of requested resources map[cpu:550 memory:838860800] ,score 4,
I1220 21:37:38.783150       1 resource_allocation.go:84] green-k8s-test-65bb774986-s7tzx -> ip-172-20-61-178.ec2.internal: BalancedResourceAllocation, map of allocatable resources map[cpu:1000 memory:1966559232], map of requested resources map[cpu:520 memory:849346560] ,score 9,
I1220 21:37:38.783278       1 resource_allocation.go:84] green-k8s-test-65bb774986-s7tzx -> ip-172-20-61-178.ec2.internal: LeastResourceAllocation, map of allocatable resources map[cpu:1000 memory:1966559232], map of requested resources map[cpu:520 memory:849346560] ,score 4,
I1220 21:37:38.783364       1 selector_spreading.go:146] green-k8s-test-65bb774986-s7tzx -> ip-172-20-58-134.ec2.internal: SelectorSpreadPriority, Score: (0)
I1220 21:37:38.783516       1 selector_spreading.go:146] green-k8s-test-65bb774986-s7tzx -> ip-172-20-45-201.ec2.internal: SelectorSpreadPriority, Score: (3)
I1220 21:37:38.783725       1 selector_spreading.go:146] green-k8s-test-65bb774986-s7tzx -> ip-172-20-49-41.ec2.internal: SelectorSpreadPriority, Score: (0)
I1220 21:37:38.785322       1 selector_spreading.go:146] green-k8s-test-65bb774986-s7tzx -> ip-172-20-61-178.ec2.internal: SelectorSpreadPriority, Score: (1)
I1220 21:37:38.785504       1 generic_scheduler.go:773] green-k8s-test-65bb774986-s7tzx_default -> ip-172-20-58-134.ec2.internal: ServiceSpreadingPriority, Score: (0)
I1220 21:37:38.785698       1 generic_scheduler.go:773] green-k8s-test-65bb774986-s7tzx_default -> ip-172-20-45-201.ec2.internal: ServiceSpreadingPriority, Score: (3)
I1220 21:37:38.785816       1 generic_scheduler.go:773] green-k8s-test-65bb774986-s7tzx_default -> ip-172-20-49-41.ec2.internal: ServiceSpreadingPriority, Score: (0)
I1220 21:37:38.785832       1 generic_scheduler.go:773] green-k8s-test-65bb774986-s7tzx_default -> ip-172-20-61-178.ec2.internal: ServiceSpreadingPriority, Score: (1)
I1220 21:37:38.785620       1 round_trippers.go:443] POST https://100.64.0.1:443/api/v1/namespaces/default/pods/green-k8s-test-65bb774986-cnxmz/binding 201 Created in 4 milliseconds
I1220 21:37:38.785918       1 round_trippers.go:449] Response Headers:
I1220 21:37:38.786014       1 round_trippers.go:452]     Cache-Control: no-cache, private
I1220 21:37:38.786032       1 round_trippers.go:452]     Content-Type: application/vnd.kubernetes.protobuf
I1220 21:37:38.786038       1 round_trippers.go:452]     X-Kubernetes-Pf-Flowschema-Uid: 9fb2dc3c-3c29-42f2-bb88-3d0896e45310
I1220 21:37:38.786045       1 round_trippers.go:452]     X-Kubernetes-Pf-Prioritylevel-Uid: 0d11ff8b-ca59-4914-b971-4d6f623f711b
I1220 21:37:38.786136       1 round_trippers.go:452]     Content-Length: 48
I1220 21:37:38.786143       1 round_trippers.go:452]     Date: Mon, 20 Dec 2021 21:37:38 GMT
I1220 21:37:38.786166       1 request.go:966] Response Body:
00000000  6b 38 73 00 0a 0c 0a 02  76 31 12 06 53 74 61 74  |k8s.....v1..Stat|
00000010  75 73 12 18 0a 06 0a 00  12 00 1a 00 12 07 53 75  |us............Su|
00000020  63 63 65 73 73 1a 00 22  00 30 c9 01 1a 00 22 00  |ccess..".0....".|
I1220 21:37:38.786225       1 cache.go:305] Finished binding for pod b242af20-f662-4529-a69b-dfc518d2a5c1. Can be expired.
I1220 21:37:38.786251       1 event_recorder.go:54] Could not construct reference to: '<nil>' due to: 'can't reference a nil object'.
I1220 21:37:38.786319       1 scheduler.go:667] pod default/green-k8s-test-65bb774986-cnxmz is bound successfully on node "ip-172-20-61-178.ec2.internal", 5 nodes evaluated, 4 nodes were found feasible. Bound node resource: "Capacity: CPU<1>|Memory<2022868Ki>|Pods<110>|StorageEphemeral<130045936Ki>; Allocatable: CPU<1>|Memory<1920468Ki>|Pods<110>|StorageEphemeral<119850334420>.".
I1220 21:37:38.786424       1 request.go:966] Request Body:
00000000  6b 38 73 00 0a 1e 0a 15  65 76 65 6e 74 73 2e 6b  |k8s.....events.k|
00000010  38 73 2e 69 6f 2f 76 31  62 65 74 61 31 12 05 45  |8s.io/v1beta1..E|
00000020  76 65 6e 74 12 a8 03 0a  49 0a 30 67 72 65 65 6e  |vent....I.0green|
00000030  2d 6b 38 73 2d 74 65 73  74 2d 36 35 62 62 37 37  |-k8s-test-65bb77|
00000040  34 39 38 36 2d 63 6e 78  6d 7a 2e 31 36 63 32 39  |4986-cnxmz.16c29|
00000050  34 34 39 62 66 62 37 33  36 33 65 12 00 1a 07 64  |449bfb7363e....d|
00000060  65 66 61 75 6c 74 22 00  2a 00 32 00 38 00 42 00  |efault".*.2.8.B.|
00000070  7a 00 12 0c 08 a2 ef 83  8e 06 10 8a b6 f4 f6 02  |z...............|
00000080  22 13 67 72 65 65 6e 2d  6b 38 73 2d 73 63 68 65  |".green-k8s-sche|
00000090  64 75 6c 65 72 2a 37 67  72 65 65 6e 2d 6b 38 73  |duler*7green-k8s|
000000a0  2d 73 63 68 65 64 75 6c  65 72 2d 67 72 65 65 6e  |-scheduler-green|
000000b0  2d 6b 38 73 2d 73 63 68  65 64 75 6c 65 72 2d 38  |-k8s-scheduler-8|
000000c0  63 62 37 66 37 37 37 39  2d 37 63 34 64 6c 32 07  |cb7f7779-7c4dl2.|
000000d0  42 69 6e 64 69 6e 67 3a  09 53 63 68 65 64 75 6c  |Binding:.Schedul|
000000e0  65 64 42 64 0a 03 50 6f  64 12 07 64 65 66 61 75  |edBd..Pod..defau|
000000f0  6c 74 1a 1f 67 72 65 65  6e 2d 6b 38 73 2d 74 65  |lt..green-k8s-te|
00000100  73 74 2d 36 35 62 62 37  37 34 39 38 36 2d 63 6e  |st-65bb774986-cn|
00000110  78 6d 7a 22 24 62 32 34  32 61 66 32 30 2d 66 36  |xmz"$b242af20-f6|
00000120  36 32 2d 34 35 32 39 2d  61 36 39 62 2d 64 66 63  |62-4529-a69b-dfc|
00000130  35 31 38 64 32 61 35 63  31 2a 02 76 31 32 07 31  |518d2a5c1*.v12.1|
00000140  34 31 37 32 35 35 3a 00  52 5e 53 75 63 63 65 73  |417255:.R^Succes|
00000150  73 66 75 6c 6c 79 20 61  73 73 69 67 6e 65 64 20  |sfully assigned |
00000160  64 65 66 61 75 6c 74 2f  67 72 65 65 6e 2d 6b 38  |default/green-k8|
00000170  73 2d 74 65 73 74 2d 36  35 62 62 37 37 34 39 38  |s-test-65bb77498|
00000180  36 2d 63 6e 78 6d 7a 20  74 6f 20 69 70 2d 31 37  |6-cnxmz to ip-17|
00000190  32 2d 32 30 2d 36 31 2d  31 37 38 2e 65 63 32 2e  |2-20-61-178.ec2.|
000001a0  69 6e 74 65 72 6e 61 6c  5a 06 4e 6f 72 6d 61 6c  |internalZ.Normal|
000001b0  62 17 0a 13 67 72 65 65  6e 2d 6b 38 73 2d 73 63  |b...green-k8s-sc|
000001c0  68 65 64 75 6c 65 72 12  00 6a 00 72 00 78 00 1a  |heduler..j.r.x..|
000001d0  00 22 00                                          |.".|
I1220 21:37:38.786540       1 round_trippers.go:423] curl -k -v -XPOST  -H "User-Agent: kube-scheduler/v1.16.3 (linux/amd64) kubernetes/b3cbbae/scheduler" -H "Accept: application/vnd.kubernetes.protobuf, */*" -H "Content-Type: application/vnd.kubernetes.protobuf" -H "Authorization: Bearer eyJhbGciOiJSUzI1NiIsImtpZCI6IkI2d0Zpc0Q2S2pFdmhUX3hsRG5GZFdLemMtRkhWWmxiQmszcGVmc3RsdjQifQ.eyJhdWQiOlsia3ViZXJuZXRlcy5zdmMuZGVmYXVsdCJdLCJleHAiOjE2NzE1NzE2OTYsImlhdCI6MTY0MDAzNTY5NiwiaXNzIjoiaHR0cHM6Ly9hcGkuaW50ZXJuYWwuaGEuZ3JlZW5rOHMuY29tIiwia3ViZXJuZXRlcy5pbyI6eyJuYW1lc3BhY2UiOiJrdWJlLXN5c3RlbSIsInBvZCI6eyJuYW1lIjoiZ3JlZW4tazhzLXNjaGVkdWxlci04Y2I3Zjc3NzktN2M0ZGwiLCJ1aWQiOiIyODMwY2IxNS05OTM2LTQ3YjAtYTlhOS0wNjVlOTdmZDU2NGIifSwic2VydmljZWFjY291bnQiOnsibmFtZSI6ImdyZWVuLWs4cy1zY2hlZHVsZXIiLCJ1aWQiOiI2NzgyMTEwNC01NGFiLTQ2YzctYTQ3NC00YjhlODI3M2UyZWYifSwid2FybmFmdGVyIjoxNjQwMDM5MzAzfSwibmJmIjoxNjQwMDM1Njk2LCJzdWIiOiJzeXN0ZW06c2VydmljZWFjY291bnQ6a3ViZS1zeXN0ZW06Z3JlZW4tazhzLXNjaGVkdWxlciJ9.QzO_AZGr2BvZ_-W2I_yCM5mU-rv4-LxvAuo3IXheOxojip-51tgqkELWPgYJgclwuIc5ftd3gEq-qU2_O5xtFjARjpRcNzgwZedg4Yl9ZTelqQG5ZpHsE2DpvOTBB8QlcKNAYkinz7g0SSnfBJsIa8ypV9k5eSwKNSH8-2xikYWnfE0tKV9fsJiQAO1BBDZt0L8eiChCiCh3yeR7cPykyfCSSdeLfG0Ycs7yTyo0rKEMWArzdw4ZqJzqtlyuof8EGT-lpcTkv2uHaX2qNfj_43700o-XR9H6N3mAJqgSQFPaZmN0b7VrokNngHR5PhPSzBUvcX0FYEvmV4qUAWsFuw" 'https://100.64.0.1:443/apis/events.k8s.io/v1beta1/namespaces/default/events'
I1220 21:37:38.790275       1 round_trippers.go:443] POST https://100.64.0.1:443/apis/events.k8s.io/v1beta1/namespaces/default/events 201 Created in 3 milliseconds
I1220 21:37:38.790297       1 round_trippers.go:449] Response Headers:
I1220 21:37:38.790303       1 round_trippers.go:452]     Date: Mon, 20 Dec 2021 21:37:38 GMT
I1220 21:37:38.790308       1 round_trippers.go:452]     Cache-Control: no-cache, private
I1220 21:37:38.791341       1 round_trippers.go:452]     Content-Type: application/vnd.kubernetes.protobuf
I1220 21:37:38.791354       1 round_trippers.go:452]     X-Kubernetes-Pf-Flowschema-Uid: 9fb2dc3c-3c29-42f2-bb88-3d0896e45310
I1220 21:37:38.791359       1 round_trippers.go:452]     X-Kubernetes-Pf-Prioritylevel-Uid: 0d11ff8b-ca59-4914-b971-4d6f623f711b
I1220 21:37:38.791365       1 round_trippers.go:452]     Content-Length: 864
I1220 21:37:38.791443       1 request.go:966] Response Body:
00000000  6b 38 73 00 0a 1e 0a 15  65 76 65 6e 74 73 2e 6b  |k8s.....events.k|
00000010  38 73 2e 69 6f 2f 76 31  62 65 74 61 31 12 05 45  |8s.io/v1beta1..E|
00000020  76 65 6e 74 12 b5 06 0a  d5 03 0a 30 67 72 65 65  |vent.......0gree|
00000030  6e 2d 6b 38 73 2d 74 65  73 74 2d 36 35 62 62 37  |n-k8s-test-65bb7|
00000040  37 34 39 38 36 2d 63 6e  78 6d 7a 2e 31 36 63 32  |74986-cnxmz.16c2|
00000050  39 34 34 39 62 66 62 37  33 36 33 65 12 00 1a 07  |9449bfb7363e....|
00000060  64 65 66 61 75 6c 74 22  00 2a 24 35 31 64 64 34  |default".*$51dd4|
00000070  66 64 32 2d 32 36 65 36  2d 34 30 64 64 2d 62 66  |fd2-26e6-40dd-bf|
00000080  39 39 2d 30 36 65 32 36  35 31 30 39 30 38 36 32  |99-06e2651090862|
00000090  04 32 37 31 31 38 00 42  08 08 a2 ef 83 8e 06 10  |.27118.B........|
000000a0  00 7a 00 8a 01 d8 02 0a  0e 6b 75 62 65 2d 73 63  |.z.......kube-sc|
000000b0  68 65 64 75 6c 65 72 12  06 55 70 64 61 74 65 1a  |heduler..Update.|
000000c0  15 65 76 65 6e 74 73 2e  6b 38 73 2e 69 6f 2f 76  |.events.k8s.io/v|
000000d0  31 62 65 74 61 31 22 08  08 a2 ef 83 8e 06 10 00  |1beta1".........|
000000e0  32 08 46 69 65 6c 64 73  56 31 3a 92 02 0a 8f 02  |2.FieldsV1:.....|
000000f0  7b 22 66 3a 61 63 74 69  6f 6e 22 3a 7b 7d 2c 22  |{"f:action":{},"|
00000100  66 3a 64 65 70 72 65 63  61 74 65 64 53 6f 75 72  |f:deprecatedSour|
00000110  63 65 22 3a 7b 22 66 3a  63 6f 6d 70 6f 6e 65 6e  |ce":{"f:componen|
00000120  74 22 3a 7b 7d 7d 2c 22  66 3a 65 76 65 6e 74 54  |t":{}},"f:eventT|
00000130  69 6d 65 22 3a 7b 7d 2c  22 66 3a 6e 6f 74 65 22  |ime":{},"f:note"|
00000140  3a 7b 7d 2c 22 66 3a 72  65 61 73 6f 6e 22 3a 7b  |:{},"f:reason":{|
00000150  7d 2c 22 66 3a 72 65 67  61 72 64 69 6e 67 22 3a  |},"f:regarding":|
00000160  7b 22 66 3a 61 70 69 56  65 72 73 69 6f 6e 22 3a  |{"f:apiVersion":|
00000170  7b 7d 2c 22 66 3a 6b 69  6e 64 22 3a 7b 7d 2c 22  |{},"f:kind":{},"|
00000180  66 3a 6e 61 6d 65 22 3a  7b 7d 2c 22 66 3a 6e 61  |f:name":{},"f:na|
00000190  6d 65 73 70 61 63 65 22  3a 7b 7d 2c 22 66 3a 72  |mespace":{},"f:r|
000001a0  65 73 6f 75 72 63 65 56  65 72 73 69 6f 6e 22 3a  |esourceVersion":|
000001b0  7b 7d 2c 22 66 3a 75 69  64 22 3a 7b 7d 7d 2c 22  |{},"f:uid":{}},"|
000001c0  66 3a 72 65 70 6f 72 74  69 6e 67 43 6f 6e 74 72  |f:reportingContr|
000001d0  6f 6c 6c 65 72 22 3a 7b  7d 2c 22 66 3a 72 65 70  |oller":{},"f:rep|
000001e0  6f 72 74 69 6e 67 49 6e  73 74 61 6e 63 65 22 3a  |ortingInstance":|
000001f0  7b 7d 2c 22 66 3a 74 79  70 65 22 3a 7b 7d 7d 12  |{},"f:type":{}}.|
00000200  0c 08 a2 ef 83 8e 06 10  8a b6 f4 f6 02 22 13 67  |.............".g|
00000210  72 65 65 6e 2d 6b 38 73  2d 73 63 68 65 64 75 6c  |reen-k8s-schedul|
00000220  65 72 2a 37 67 72 65 65  6e 2d 6b 38 73 2d 73 63  |er*7green-k8s-sc|
00000230  68 65 64 75 6c 65 72 2d  67 72 65 65 6e 2d 6b 38  |heduler-green-k8|
00000240  73 2d 73 63 68 65 64 75  6c 65 72 2d 38 63 62 37  |s-scheduler-8cb7|
00000250  66 37 37 37 39 2d 37 63  34 64 6c 32 07 42 69 6e  |f7779-7c4dl2.Bin|
00000260  64 69 6e 67 3a 09 53 63  68 65 64 75 6c 65 64 42  |ding:.ScheduledB|
00000270  64 0a 03 50 6f 64 12 07  64 65 66 61 75 6c 74 1a  |d..Pod..default.|
00000280  1f 67 72 65 65 6e 2d 6b  38 73 2d 74 65 73 74 2d  |.green-k8s-test-|
00000290  36 35 62 62 37 37 34 39  38 36 2d 63 6e 78 6d 7a  |65bb774986-cnxmz|
000002a0  22 24 62 32 34 32 61 66  32 30 2d 66 36 36 32 2d  |"$b242af20-f662-|
000002b0  34 35 32 39 2d 61 36 39  62 2d 64 66 63 35 31 38  |4529-a69b-dfc518|
000002c0  64 32 61 35 63 31 2a 02  76 31 32 07 31 34 31 37  |d2a5c1*.v12.1417|
000002d0  32 35 35 3a 00 52 5e 53  75 63 63 65 73 73 66 75  |255:.R^Successfu|
000002e0  6c 6c 79 20 61 73 73 69  67 6e 65 64 20 64 65 66  |lly assigned def|
000002f0  61 75 6c 74 2f 67 72 65  65 6e 2d 6b 38 73 2d 74  |ault/green-k8s-t|
00000300  65 73 74 2d 36 35 62 62  37 37 34 39 38 36 2d 63  |est-65bb774986-c|
00000310  6e 78 6d 7a 20 74 6f 20  69 70 2d 31 37 32 2d 32  |nxmz to ip-172-2|
00000320  30 2d 36 31 2d 31 37 38  2e 65 63 32 2e 69 6e 74  |0-61-178.ec2.int|
00000330  65 72 6e 61 6c 5a 06 4e  6f 72 6d 61 6c 62 17 0a  |ernalZ.Normalb..|
00000340  13 67 72 65 65 6e 2d 6b  38 73 2d 73 63 68 65 64  |.green-k8s-sched|
00000350  75 6c 65 72 12 00 6a 00  72 00 78 00 1a 00 22 00  |uler..j.r.x...".|
I1220 21:37:38.804402       1 generic_scheduler.go:822] green-k8s-test-65bb774986-s7tzx_default -> ip-172-20-58-134.ec2.internal: http://localhost:80, Score: (10)
I1220 21:37:38.804426       1 generic_scheduler.go:822] green-k8s-test-65bb774986-s7tzx_default -> ip-172-20-45-201.ec2.internal: http://localhost:80, Score: (0)
I1220 21:37:38.804433       1 generic_scheduler.go:822] green-k8s-test-65bb774986-s7tzx_default -> ip-172-20-49-41.ec2.internal: http://localhost:80, Score: (10)
I1220 21:37:38.804506       1 generic_scheduler.go:822] green-k8s-test-65bb774986-s7tzx_default -> ip-172-20-61-178.ec2.internal: http://localhost:80, Score: (6)
I1220 21:37:38.804524       1 generic_scheduler.go:838] Host ip-172-20-58-134.ec2.internal => Score 23
I1220 21:37:38.804531       1 generic_scheduler.go:838] Host ip-172-20-45-201.ec2.internal => Score 19
I1220 21:37:38.804537       1 generic_scheduler.go:838] Host ip-172-20-49-41.ec2.internal => Score 23
I1220 21:37:38.804542       1 generic_scheduler.go:838] Host ip-172-20-61-178.ec2.internal => Score 21
I1220 21:37:38.804646       1 scheduler_binder.go:256] AssumePodVolumes for pod "default/green-k8s-test-65bb774986-s7tzx", node "ip-172-20-58-134.ec2.internal"
I1220 21:37:38.804669       1 scheduler_binder.go:266] AssumePodVolumes for pod "default/green-k8s-test-65bb774986-s7tzx", node "ip-172-20-58-134.ec2.internal": all PVCs bound and nothing to do
I1220 21:37:38.804735       1 factory.go:610] Attempting to bind green-k8s-test-65bb774986-s7tzx to ip-172-20-58-134.ec2.internal
I1220 21:37:38.804844       1 scheduling_queue.go:830] About to try and schedule pod default/green-k8s-test-65bb774986-bhlzx
I1220 21:37:38.804971       1 scheduler.go:530] Attempting to schedule pod: default/green-k8s-test-65bb774986-bhlzx
I1220 21:37:38.804853       1 request.go:966] Request Body:
00000000  6b 38 73 00 0a 0d 0a 02  76 31 12 07 42 69 6e 64  |k8s.....v1..Bind|
00000010  69 6e 67 12 8f 01 0a 5c  0a 1f 67 72 65 65 6e 2d  |ing....\..green-|
00000020  6b 38 73 2d 74 65 73 74  2d 36 35 62 62 37 37 34  |k8s-test-65bb774|
00000030  39 38 36 2d 73 37 74 7a  78 12 00 1a 07 64 65 66  |986-s7tzx....def|
00000040  61 75 6c 74 22 00 2a 24  66 38 38 32 63 61 37 37  |ault".*$f882ca77|
00000050  2d 65 63 66 61 2d 34 31  33 37 2d 61 63 61 31 2d  |-ecfa-4137-aca1-|
00000060  64 61 64 38 32 65 39 66  30 62 61 65 32 00 38 00  |dad82e9f0bae2.8.|
00000070  42 00 7a 00 12 2f 0a 04  4e 6f 64 65 12 00 1a 1d  |B.z../..Node....|
00000080  69 70 2d 31 37 32 2d 32  30 2d 35 38 2d 31 33 34  |ip-172-20-58-134|
00000090  2e 65 63 32 2e 69 6e 74  65 72 6e 61 6c 22 00 2a  |.ec2.internal".*|
000000a0  00 32 00 3a 00 1a 00 22  00                       |.2.:...".|
I1220 21:37:38.805237       1 metadata.go:238] Precompute: PredicateWithExtendedResourceOptions
I1220 21:37:38.805341       1 predicates.go:908] Schedule Pod default/green-k8s-test-65bb774986-bhlzx on Node ip-172-20-40-148.ec2.internal is allowed, Node is running only 9 out of 110 Pods.
I1220 21:37:38.805393       1 generic_scheduler.go:667] since alwaysCheckAllPredicates has not been set, the predicate evaluation is short circuited and there are chances of other predicates failing as well.
I1220 21:37:38.805427       1 predicates.go:908] Schedule Pod default/green-k8s-test-65bb774986-bhlzx on Node ip-172-20-58-134.ec2.internal is allowed, Node is running only 5 out of 110 Pods.
I1220 21:37:38.805492       1 predicates.go:908] Schedule Pod default/green-k8s-test-65bb774986-bhlzx on Node ip-172-20-49-41.ec2.internal is allowed, Node is running only 3 out of 110 Pods.
I1220 21:37:38.805537       1 predicates.go:908] Schedule Pod default/green-k8s-test-65bb774986-bhlzx on Node ip-172-20-61-178.ec2.internal is allowed, Node is running only 4 out of 110 Pods.
I1220 21:37:38.805253       1 round_trippers.go:423] curl -k -v -XPOST  -H "User-Agent: kube-scheduler/v1.16.3 (linux/amd64) kubernetes/b3cbbae/scheduler" -H "Authorization: Bearer eyJhbGciOiJSUzI1NiIsImtpZCI6IkI2d0Zpc0Q2S2pFdmhUX3hsRG5GZFdLemMtRkhWWmxiQmszcGVmc3RsdjQifQ.eyJhdWQiOlsia3ViZXJuZXRlcy5zdmMuZGVmYXVsdCJdLCJleHAiOjE2NzE1NzE2OTYsImlhdCI6MTY0MDAzNTY5NiwiaXNzIjoiaHR0cHM6Ly9hcGkuaW50ZXJuYWwuaGEuZ3JlZW5rOHMuY29tIiwia3ViZXJuZXRlcy5pbyI6eyJuYW1lc3BhY2UiOiJrdWJlLXN5c3RlbSIsInBvZCI6eyJuYW1lIjoiZ3JlZW4tazhzLXNjaGVkdWxlci04Y2I3Zjc3NzktN2M0ZGwiLCJ1aWQiOiIyODMwY2IxNS05OTM2LTQ3YjAtYTlhOS0wNjVlOTdmZDU2NGIifSwic2VydmljZWFjY291bnQiOnsibmFtZSI6ImdyZWVuLWs4cy1zY2hlZHVsZXIiLCJ1aWQiOiI2NzgyMTEwNC01NGFiLTQ2YzctYTQ3NC00YjhlODI3M2UyZWYifSwid2FybmFmdGVyIjoxNjQwMDM5MzAzfSwibmJmIjoxNjQwMDM1Njk2LCJzdWIiOiJzeXN0ZW06c2VydmljZWFjY291bnQ6a3ViZS1zeXN0ZW06Z3JlZW4tazhzLXNjaGVkdWxlciJ9.QzO_AZGr2BvZ_-W2I_yCM5mU-rv4-LxvAuo3IXheOxojip-51tgqkELWPgYJgclwuIc5ftd3gEq-qU2_O5xtFjARjpRcNzgwZedg4Yl9ZTelqQG5ZpHsE2DpvOTBB8QlcKNAYkinz7g0SSnfBJsIa8ypV9k5eSwKNSH8-2xikYWnfE0tKV9fsJiQAO1BBDZt0L8eiChCiCh3yeR7cPykyfCSSdeLfG0Ycs7yTyo0rKEMWArzdw4ZqJzqtlyuof8EGT-lpcTkv2uHaX2qNfj_43700o-XR9H6N3mAJqgSQFPaZmN0b7VrokNngHR5PhPSzBUvcX0FYEvmV4qUAWsFuw" -H "Accept: application/vnd.kubernetes.protobuf, */*" -H "Content-Type: application/vnd.kubernetes.protobuf" 'https://100.64.0.1:443/api/v1/namespaces/default/pods/green-k8s-test-65bb774986-s7tzx/binding'
I1220 21:37:38.805686       1 predicates.go:908] Schedule Pod default/green-k8s-test-65bb774986-bhlzx on Node ip-172-20-45-201.ec2.internal is allowed, Node is running only 2 out of 110 Pods.
I1220 21:37:38.805927       1 resource_allocation.go:84] green-k8s-test-65bb774986-bhlzx -> ip-172-20-58-134.ec2.internal: BalancedResourceAllocation, map of allocatable resources map[cpu:1000 memory:1966559232], map of requested resources map[cpu:800 memory:1121976320] ,score 7,
I1220 21:37:38.805958       1 resource_allocation.go:84] green-k8s-test-65bb774986-bhlzx -> ip-172-20-58-134.ec2.internal: LeastResourceAllocation, map of allocatable resources map[cpu:1000 memory:1966559232], map of requested resources map[cpu:800 memory:1121976320] ,score 3,
I1220 21:37:38.806066       1 resource_allocation.go:84] green-k8s-test-65bb774986-bhlzx -> ip-172-20-61-178.ec2.internal: BalancedResourceAllocation, map of allocatable resources map[cpu:1000 memory:1966559232], map of requested resources map[cpu:520 memory:849346560] ,score 9,
I1220 21:37:38.806093       1 resource_allocation.go:84] green-k8s-test-65bb774986-bhlzx -> ip-172-20-61-178.ec2.internal: LeastResourceAllocation, map of allocatable resources map[cpu:1000 memory:1966559232], map of requested resources map[cpu:520 memory:849346560] ,score 4,
I1220 21:37:38.806108       1 resource_allocation.go:84] green-k8s-test-65bb774986-bhlzx -> ip-172-20-45-201.ec2.internal: BalancedResourceAllocation, map of allocatable resources map[cpu:1000 memory:1966559232], map of requested resources map[cpu:350 memory:492830720] ,score 9,
I1220 21:37:38.806123       1 resource_allocation.go:84] green-k8s-test-65bb774986-bhlzx -> ip-172-20-45-201.ec2.internal: LeastResourceAllocation, map of allocatable resources map[cpu:1000 memory:1966559232], map of requested resources map[cpu:350 memory:492830720] ,score 6,
I1220 21:37:38.805975       1 resource_allocation.go:84] green-k8s-test-65bb774986-bhlzx -> ip-172-20-49-41.ec2.internal: BalancedResourceAllocation, map of allocatable resources map[cpu:1000 memory:1966559232], map of requested resources map[cpu:550 memory:838860800] ,score 8,
I1220 21:37:38.806146       1 resource_allocation.go:84] green-k8s-test-65bb774986-bhlzx -> ip-172-20-49-41.ec2.internal: LeastResourceAllocation, map of allocatable resources map[cpu:1000 memory:1966559232], map of requested resources map[cpu:550 memory:838860800] ,score 4,
I1220 21:37:38.806371       1 selector_spreading.go:146] green-k8s-test-65bb774986-bhlzx -> ip-172-20-58-134.ec2.internal: SelectorSpreadPriority, Score: (0)
I1220 21:37:38.806389       1 selector_spreading.go:146] green-k8s-test-65bb774986-bhlzx -> ip-172-20-49-41.ec2.internal: SelectorSpreadPriority, Score: (1)
I1220 21:37:38.806395       1 selector_spreading.go:146] green-k8s-test-65bb774986-bhlzx -> ip-172-20-61-178.ec2.internal: SelectorSpreadPriority, Score: (2)
I1220 21:37:38.806401       1 selector_spreading.go:146] green-k8s-test-65bb774986-bhlzx -> ip-172-20-45-201.ec2.internal: SelectorSpreadPriority, Score: (3)
I1220 21:37:38.806432       1 generic_scheduler.go:773] green-k8s-test-65bb774986-bhlzx_default -> ip-172-20-58-134.ec2.internal: ServiceSpreadingPriority, Score: (0)
I1220 21:37:38.806438       1 generic_scheduler.go:773] green-k8s-test-65bb774986-bhlzx_default -> ip-172-20-49-41.ec2.internal: ServiceSpreadingPriority, Score: (1)
I1220 21:37:38.806471       1 generic_scheduler.go:773] green-k8s-test-65bb774986-bhlzx_default -> ip-172-20-61-178.ec2.internal: ServiceSpreadingPriority, Score: (2)
I1220 21:37:38.806476       1 generic_scheduler.go:773] green-k8s-test-65bb774986-bhlzx_default -> ip-172-20-45-201.ec2.internal: ServiceSpreadingPriority, Score: (3)
I1220 21:37:38.809887       1 round_trippers.go:443] POST https://100.64.0.1:443/api/v1/namespaces/default/pods/green-k8s-test-65bb774986-s7tzx/binding 201 Created in 4 milliseconds
I1220 21:37:38.809908       1 round_trippers.go:449] Response Headers:
I1220 21:37:38.809914       1 round_trippers.go:452]     Cache-Control: no-cache, private
I1220 21:37:38.809920       1 round_trippers.go:452]     Content-Type: application/vnd.kubernetes.protobuf
I1220 21:37:38.810427       1 round_trippers.go:452]     X-Kubernetes-Pf-Flowschema-Uid: 9fb2dc3c-3c29-42f2-bb88-3d0896e45310
I1220 21:37:38.810444       1 round_trippers.go:452]     X-Kubernetes-Pf-Prioritylevel-Uid: 0d11ff8b-ca59-4914-b971-4d6f623f711b
I1220 21:37:38.810449       1 round_trippers.go:452]     Content-Length: 48
I1220 21:37:38.810454       1 round_trippers.go:452]     Date: Mon, 20 Dec 2021 21:37:38 GMT
I1220 21:37:38.810833       1 request.go:966] Response Body:
00000000  6b 38 73 00 0a 0c 0a 02  76 31 12 06 53 74 61 74  |k8s.....v1..Stat|
00000010  75 73 12 18 0a 06 0a 00  12 00 1a 00 12 07 53 75  |us............Su|
00000020  63 63 65 73 73 1a 00 22  00 30 c9 01 1a 00 22 00  |ccess..".0....".|
I1220 21:37:38.810882       1 cache.go:305] Finished binding for pod f882ca77-ecfa-4137-aca1-dad82e9f0bae. Can be expired.
I1220 21:37:38.810911       1 event_recorder.go:54] Could not construct reference to: '<nil>' due to: 'can't reference a nil object'.
I1220 21:37:38.810944       1 scheduler.go:667] pod default/green-k8s-test-65bb774986-s7tzx is bound successfully on node "ip-172-20-58-134.ec2.internal", 5 nodes evaluated, 4 nodes were found feasible. Bound node resource: "Capacity: CPU<1>|Memory<2022868Ki>|Pods<110>|StorageEphemeral<130045936Ki>; Allocatable: CPU<1>|Memory<1920468Ki>|Pods<110>|StorageEphemeral<119850334420>.".
I1220 21:37:38.811022       1 request.go:966] Request Body:
00000000  6b 38 73 00 0a 1e 0a 15  65 76 65 6e 74 73 2e 6b  |k8s.....events.k|
00000010  38 73 2e 69 6f 2f 76 31  62 65 74 61 31 12 05 45  |8s.io/v1beta1..E|
00000020  76 65 6e 74 12 a8 03 0a  49 0a 30 67 72 65 65 6e  |vent....I.0green|
00000030  2d 6b 38 73 2d 74 65 73  74 2d 36 35 62 62 37 37  |-k8s-test-65bb77|
00000040  34 39 38 36 2d 73 37 74  7a 78 2e 31 36 63 32 39  |4986-s7tzx.16c29|
00000050  34 34 39 63 31 32 66 38  36 62 63 12 00 1a 07 64  |449c12f86bc....d|
00000060  65 66 61 75 6c 74 22 00  2a 00 32 00 38 00 42 00  |efault".*.2.8.B.|
00000070  7a 00 12 0c 08 a2 ef 83  8e 06 10 ea be d5 82 03  |z...............|
00000080  22 13 67 72 65 65 6e 2d  6b 38 73 2d 73 63 68 65  |".green-k8s-sche|
00000090  64 75 6c 65 72 2a 37 67  72 65 65 6e 2d 6b 38 73  |duler*7green-k8s|
000000a0  2d 73 63 68 65 64 75 6c  65 72 2d 67 72 65 65 6e  |-scheduler-green|
000000b0  2d 6b 38 73 2d 73 63 68  65 64 75 6c 65 72 2d 38  |-k8s-scheduler-8|
000000c0  63 62 37 66 37 37 37 39  2d 37 63 34 64 6c 32 07  |cb7f7779-7c4dl2.|
000000d0  42 69 6e 64 69 6e 67 3a  09 53 63 68 65 64 75 6c  |Binding:.Schedul|
000000e0  65 64 42 64 0a 03 50 6f  64 12 07 64 65 66 61 75  |edBd..Pod..defau|
000000f0  6c 74 1a 1f 67 72 65 65  6e 2d 6b 38 73 2d 74 65  |lt..green-k8s-te|
00000100  73 74 2d 36 35 62 62 37  37 34 39 38 36 2d 73 37  |st-65bb774986-s7|
00000110  74 7a 78 22 24 66 38 38  32 63 61 37 37 2d 65 63  |tzx"$f882ca77-ec|
00000120  66 61 2d 34 31 33 37 2d  61 63 61 31 2d 64 61 64  |fa-4137-aca1-dad|
00000130  38 32 65 39 66 30 62 61  65 2a 02 76 31 32 07 31  |82e9f0bae*.v12.1|
00000140  34 31 37 32 35 36 3a 00  52 5e 53 75 63 63 65 73  |417256:.R^Succes|
00000150  73 66 75 6c 6c 79 20 61  73 73 69 67 6e 65 64 20  |sfully assigned |
00000160  64 65 66 61 75 6c 74 2f  67 72 65 65 6e 2d 6b 38  |default/green-k8|
00000170  73 2d 74 65 73 74 2d 36  35 62 62 37 37 34 39 38  |s-test-65bb77498|
00000180  36 2d 73 37 74 7a 78 20  74 6f 20 69 70 2d 31 37  |6-s7tzx to ip-17|
00000190  32 2d 32 30 2d 35 38 2d  31 33 34 2e 65 63 32 2e  |2-20-58-134.ec2.|
000001a0  69 6e 74 65 72 6e 61 6c  5a 06 4e 6f 72 6d 61 6c  |internalZ.Normal|
000001b0  62 17 0a 13 67 72 65 65  6e 2d 6b 38 73 2d 73 63  |b...green-k8s-sc|
000001c0  68 65 64 75 6c 65 72 12  00 6a 00 72 00 78 00 1a  |heduler..j.r.x..|
000001d0  00 22 00                                          |.".|
I1220 21:37:38.811098       1 round_trippers.go:423] curl -k -v -XPOST  -H "Content-Type: application/vnd.kubernetes.protobuf" -H "User-Agent: kube-scheduler/v1.16.3 (linux/amd64) kubernetes/b3cbbae/scheduler" -H "Accept: application/vnd.kubernetes.protobuf, */*" -H "Authorization: Bearer eyJhbGciOiJSUzI1NiIsImtpZCI6IkI2d0Zpc0Q2S2pFdmhUX3hsRG5GZFdLemMtRkhWWmxiQmszcGVmc3RsdjQifQ.eyJhdWQiOlsia3ViZXJuZXRlcy5zdmMuZGVmYXVsdCJdLCJleHAiOjE2NzE1NzE2OTYsImlhdCI6MTY0MDAzNTY5NiwiaXNzIjoiaHR0cHM6Ly9hcGkuaW50ZXJuYWwuaGEuZ3JlZW5rOHMuY29tIiwia3ViZXJuZXRlcy5pbyI6eyJuYW1lc3BhY2UiOiJrdWJlLXN5c3RlbSIsInBvZCI6eyJuYW1lIjoiZ3JlZW4tazhzLXNjaGVkdWxlci04Y2I3Zjc3NzktN2M0ZGwiLCJ1aWQiOiIyODMwY2IxNS05OTM2LTQ3YjAtYTlhOS0wNjVlOTdmZDU2NGIifSwic2VydmljZWFjY291bnQiOnsibmFtZSI6ImdyZWVuLWs4cy1zY2hlZHVsZXIiLCJ1aWQiOiI2NzgyMTEwNC01NGFiLTQ2YzctYTQ3NC00YjhlODI3M2UyZWYifSwid2FybmFmdGVyIjoxNjQwMDM5MzAzfSwibmJmIjoxNjQwMDM1Njk2LCJzdWIiOiJzeXN0ZW06c2VydmljZWFjY291bnQ6a3ViZS1zeXN0ZW06Z3JlZW4tazhzLXNjaGVkdWxlciJ9.QzO_AZGr2BvZ_-W2I_yCM5mU-rv4-LxvAuo3IXheOxojip-51tgqkELWPgYJgclwuIc5ftd3gEq-qU2_O5xtFjARjpRcNzgwZedg4Yl9ZTelqQG5ZpHsE2DpvOTBB8QlcKNAYkinz7g0SSnfBJsIa8ypV9k5eSwKNSH8-2xikYWnfE0tKV9fsJiQAO1BBDZt0L8eiChCiCh3yeR7cPykyfCSSdeLfG0Ycs7yTyo0rKEMWArzdw4ZqJzqtlyuof8EGT-lpcTkv2uHaX2qNfj_43700o-XR9H6N3mAJqgSQFPaZmN0b7VrokNngHR5PhPSzBUvcX0FYEvmV4qUAWsFuw" 'https://100.64.0.1:443/apis/events.k8s.io/v1beta1/namespaces/default/events'
I1220 21:37:38.815853       1 round_trippers.go:443] POST https://100.64.0.1:443/apis/events.k8s.io/v1beta1/namespaces/default/events 201 Created in 4 milliseconds
I1220 21:37:38.816034       1 round_trippers.go:449] Response Headers:
I1220 21:37:38.816566       1 round_trippers.go:452]     X-Kubernetes-Pf-Prioritylevel-Uid: 0d11ff8b-ca59-4914-b971-4d6f623f711b
I1220 21:37:38.816585       1 round_trippers.go:452]     Content-Length: 864
I1220 21:37:38.816590       1 round_trippers.go:452]     Date: Mon, 20 Dec 2021 21:37:38 GMT
I1220 21:37:38.816595       1 round_trippers.go:452]     Cache-Control: no-cache, private
I1220 21:37:38.816600       1 round_trippers.go:452]     Content-Type: application/vnd.kubernetes.protobuf
I1220 21:37:38.816604       1 round_trippers.go:452]     X-Kubernetes-Pf-Flowschema-Uid: 9fb2dc3c-3c29-42f2-bb88-3d0896e45310
I1220 21:37:38.816818       1 request.go:966] Response Body:
00000000  6b 38 73 00 0a 1e 0a 15  65 76 65 6e 74 73 2e 6b  |k8s.....events.k|
00000010  38 73 2e 69 6f 2f 76 31  62 65 74 61 31 12 05 45  |8s.io/v1beta1..E|
00000020  76 65 6e 74 12 b5 06 0a  d5 03 0a 30 67 72 65 65  |vent.......0gree|
00000030  6e 2d 6b 38 73 2d 74 65  73 74 2d 36 35 62 62 37  |n-k8s-test-65bb7|
00000040  37 34 39 38 36 2d 73 37  74 7a 78 2e 31 36 63 32  |74986-s7tzx.16c2|
00000050  39 34 34 39 63 31 32 66  38 36 62 63 12 00 1a 07  |9449c12f86bc....|
00000060  64 65 66 61 75 6c 74 22  00 2a 24 34 38 37 62 33  |default".*$487b3|
00000070  61 63 30 2d 34 38 38 38  2d 34 33 63 30 2d 61 63  |ac0-4888-43c0-ac|
00000080  39 63 2d 65 31 30 36 63  33 39 62 36 30 32 39 32  |9c-e106c39b60292|
00000090  04 32 37 31 32 38 00 42  08 08 a2 ef 83 8e 06 10  |.27128.B........|
000000a0  00 7a 00 8a 01 d8 02 0a  0e 6b 75 62 65 2d 73 63  |.z.......kube-sc|
000000b0  68 65 64 75 6c 65 72 12  06 55 70 64 61 74 65 1a  |heduler..Update.|
000000c0  15 65 76 65 6e 74 73 2e  6b 38 73 2e 69 6f 2f 76  |.events.k8s.io/v|
000000d0  31 62 65 74 61 31 22 08  08 a2 ef 83 8e 06 10 00  |1beta1".........|
000000e0  32 08 46 69 65 6c 64 73  56 31 3a 92 02 0a 8f 02  |2.FieldsV1:.....|
000000f0  7b 22 66 3a 61 63 74 69  6f 6e 22 3a 7b 7d 2c 22  |{"f:action":{},"|
00000100  66 3a 64 65 70 72 65 63  61 74 65 64 53 6f 75 72  |f:deprecatedSour|
00000110  63 65 22 3a 7b 22 66 3a  63 6f 6d 70 6f 6e 65 6e  |ce":{"f:componen|
00000120  74 22 3a 7b 7d 7d 2c 22  66 3a 65 76 65 6e 74 54  |t":{}},"f:eventT|
00000130  69 6d 65 22 3a 7b 7d 2c  22 66 3a 6e 6f 74 65 22  |ime":{},"f:note"|
00000140  3a 7b 7d 2c 22 66 3a 72  65 61 73 6f 6e 22 3a 7b  |:{},"f:reason":{|
00000150  7d 2c 22 66 3a 72 65 67  61 72 64 69 6e 67 22 3a  |},"f:regarding":|
00000160  7b 22 66 3a 61 70 69 56  65 72 73 69 6f 6e 22 3a  |{"f:apiVersion":|
00000170  7b 7d 2c 22 66 3a 6b 69  6e 64 22 3a 7b 7d 2c 22  |{},"f:kind":{},"|
00000180  66 3a 6e 61 6d 65 22 3a  7b 7d 2c 22 66 3a 6e 61  |f:name":{},"f:na|
00000190  6d 65 73 70 61 63 65 22  3a 7b 7d 2c 22 66 3a 72  |mespace":{},"f:r|
000001a0  65 73 6f 75 72 63 65 56  65 72 73 69 6f 6e 22 3a  |esourceVersion":|
000001b0  7b 7d 2c 22 66 3a 75 69  64 22 3a 7b 7d 7d 2c 22  |{},"f:uid":{}},"|
000001c0  66 3a 72 65 70 6f 72 74  69 6e 67 43 6f 6e 74 72  |f:reportingContr|
000001d0  6f 6c 6c 65 72 22 3a 7b  7d 2c 22 66 3a 72 65 70  |oller":{},"f:rep|
000001e0  6f 72 74 69 6e 67 49 6e  73 74 61 6e 63 65 22 3a  |ortingInstance":|
000001f0  7b 7d 2c 22 66 3a 74 79  70 65 22 3a 7b 7d 7d 12  |{},"f:type":{}}.|
00000200  0c 08 a2 ef 83 8e 06 10  ea be d5 82 03 22 13 67  |.............".g|
00000210  72 65 65 6e 2d 6b 38 73  2d 73 63 68 65 64 75 6c  |reen-k8s-schedul|
00000220  65 72 2a 37 67 72 65 65  6e 2d 6b 38 73 2d 73 63  |er*7green-k8s-sc|
00000230  68 65 64 75 6c 65 72 2d  67 72 65 65 6e 2d 6b 38  |heduler-green-k8|
00000240  73 2d 73 63 68 65 64 75  6c 65 72 2d 38 63 62 37  |s-scheduler-8cb7|
00000250  66 37 37 37 39 2d 37 63  34 64 6c 32 07 42 69 6e  |f7779-7c4dl2.Bin|
00000260  64 69 6e 67 3a 09 53 63  68 65 64 75 6c 65 64 42  |ding:.ScheduledB|
00000270  64 0a 03 50 6f 64 12 07  64 65 66 61 75 6c 74 1a  |d..Pod..default.|
00000280  1f 67 72 65 65 6e 2d 6b  38 73 2d 74 65 73 74 2d  |.green-k8s-test-|
00000290  36 35 62 62 37 37 34 39  38 36 2d 73 37 74 7a 78  |65bb774986-s7tzx|
000002a0  22 24 66 38 38 32 63 61  37 37 2d 65 63 66 61 2d  |"$f882ca77-ecfa-|
000002b0  34 31 33 37 2d 61 63 61  31 2d 64 61 64 38 32 65  |4137-aca1-dad82e|
000002c0  39 66 30 62 61 65 2a 02  76 31 32 07 31 34 31 37  |9f0bae*.v12.1417|
000002d0  32 35 36 3a 00 52 5e 53  75 63 63 65 73 73 66 75  |256:.R^Successfu|
000002e0  6c 6c 79 20 61 73 73 69  67 6e 65 64 20 64 65 66  |lly assigned def|
000002f0  61 75 6c 74 2f 67 72 65  65 6e 2d 6b 38 73 2d 74  |ault/green-k8s-t|
00000300  65 73 74 2d 36 35 62 62  37 37 34 39 38 36 2d 73  |est-65bb774986-s|
00000310  37 74 7a 78 20 74 6f 20  69 70 2d 31 37 32 2d 32  |7tzx to ip-172-2|
00000320  30 2d 35 38 2d 31 33 34  2e 65 63 32 2e 69 6e 74  |0-58-134.ec2.int|
00000330  65 72 6e 61 6c 5a 06 4e  6f 72 6d 61 6c 62 17 0a  |ernalZ.Normalb..|
00000340  13 67 72 65 65 6e 2d 6b  38 73 2d 73 63 68 65 64  |.green-k8s-sched|
00000350  75 6c 65 72 12 00 6a 00  72 00 78 00 1a 00 22 00  |uler..j.r.x...".|
I1220 21:37:38.823275       1 generic_scheduler.go:822] green-k8s-test-65bb774986-bhlzx_default -> ip-172-20-58-134.ec2.internal: http://localhost:80, Score: (10)
I1220 21:37:38.823297       1 generic_scheduler.go:822] green-k8s-test-65bb774986-bhlzx_default -> ip-172-20-49-41.ec2.internal: http://localhost:80, Score: (10)
I1220 21:37:38.823303       1 generic_scheduler.go:822] green-k8s-test-65bb774986-bhlzx_default -> ip-172-20-61-178.ec2.internal: http://localhost:80, Score: (6)
I1220 21:37:38.823308       1 generic_scheduler.go:822] green-k8s-test-65bb774986-bhlzx_default -> ip-172-20-45-201.ec2.internal: http://localhost:80, Score: (0)
I1220 21:37:38.823321       1 generic_scheduler.go:838] Host ip-172-20-58-134.ec2.internal => Score 21
I1220 21:37:38.823327       1 generic_scheduler.go:838] Host ip-172-20-49-41.ec2.internal => Score 24
I1220 21:37:38.823487       1 generic_scheduler.go:838] Host ip-172-20-61-178.ec2.internal => Score 22
I1220 21:37:38.823493       1 generic_scheduler.go:838] Host ip-172-20-45-201.ec2.internal => Score 19
I1220 21:37:38.823626       1 scheduler_binder.go:256] AssumePodVolumes for pod "default/green-k8s-test-65bb774986-bhlzx", node "ip-172-20-49-41.ec2.internal"
I1220 21:37:38.823645       1 scheduler_binder.go:266] AssumePodVolumes for pod "default/green-k8s-test-65bb774986-bhlzx", node "ip-172-20-49-41.ec2.internal": all PVCs bound and nothing to do
I1220 21:37:38.823780       1 factory.go:610] Attempting to bind green-k8s-test-65bb774986-bhlzx to ip-172-20-49-41.ec2.internal
I1220 21:37:38.823889       1 request.go:966] Request Body:
00000000  6b 38 73 00 0a 0d 0a 02  76 31 12 07 42 69 6e 64  |k8s.....v1..Bind|
00000010  69 6e 67 12 8e 01 0a 5c  0a 1f 67 72 65 65 6e 2d  |ing....\..green-|
00000020  6b 38 73 2d 74 65 73 74  2d 36 35 62 62 37 37 34  |k8s-test-65bb774|
00000030  39 38 36 2d 62 68 6c 7a  78 12 00 1a 07 64 65 66  |986-bhlzx....def|
00000040  61 75 6c 74 22 00 2a 24  36 31 33 39 31 39 33 37  |ault".*$61391937|
00000050  2d 30 33 32 35 2d 34 35  30 61 2d 61 38 66 35 2d  |-0325-450a-a8f5-|
00000060  30 39 35 35 63 61 34 38  34 36 62 37 32 00 38 00  |0955ca4846b72.8.|
00000070  42 00 7a 00 12 2e 0a 04  4e 6f 64 65 12 00 1a 1c  |B.z.....Node....|
00000080  69 70 2d 31 37 32 2d 32  30 2d 34 39 2d 34 31 2e  |ip-172-20-49-41.|
00000090  65 63 32 2e 69 6e 74 65  72 6e 61 6c 22 00 2a 00  |ec2.internal".*.|
000000a0  32 00 3a 00 1a 00 22 00                           |2.:...".|
I1220 21:37:38.824104       1 round_trippers.go:423] curl -k -v -XPOST  -H "Authorization: Bearer eyJhbGciOiJSUzI1NiIsImtpZCI6IkI2d0Zpc0Q2S2pFdmhUX3hsRG5GZFdLemMtRkhWWmxiQmszcGVmc3RsdjQifQ.eyJhdWQiOlsia3ViZXJuZXRlcy5zdmMuZGVmYXVsdCJdLCJleHAiOjE2NzE1NzE2OTYsImlhdCI6MTY0MDAzNTY5NiwiaXNzIjoiaHR0cHM6Ly9hcGkuaW50ZXJuYWwuaGEuZ3JlZW5rOHMuY29tIiwia3ViZXJuZXRlcy5pbyI6eyJuYW1lc3BhY2UiOiJrdWJlLXN5c3RlbSIsInBvZCI6eyJuYW1lIjoiZ3JlZW4tazhzLXNjaGVkdWxlci04Y2I3Zjc3NzktN2M0ZGwiLCJ1aWQiOiIyODMwY2IxNS05OTM2LTQ3YjAtYTlhOS0wNjVlOTdmZDU2NGIifSwic2VydmljZWFjY291bnQiOnsibmFtZSI6ImdyZWVuLWs4cy1zY2hlZHVsZXIiLCJ1aWQiOiI2NzgyMTEwNC01NGFiLTQ2YzctYTQ3NC00YjhlODI3M2UyZWYifSwid2FybmFmdGVyIjoxNjQwMDM5MzAzfSwibmJmIjoxNjQwMDM1Njk2LCJzdWIiOiJzeXN0ZW06c2VydmljZWFjY291bnQ6a3ViZS1zeXN0ZW06Z3JlZW4tazhzLXNjaGVkdWxlciJ9.QzO_AZGr2BvZ_-W2I_yCM5mU-rv4-LxvAuo3IXheOxojip-51tgqkELWPgYJgclwuIc5ftd3gEq-qU2_O5xtFjARjpRcNzgwZedg4Yl9ZTelqQG5ZpHsE2DpvOTBB8QlcKNAYkinz7g0SSnfBJsIa8ypV9k5eSwKNSH8-2xikYWnfE0tKV9fsJiQAO1BBDZt0L8eiChCiCh3yeR7cPykyfCSSdeLfG0Ycs7yTyo0rKEMWArzdw4ZqJzqtlyuof8EGT-lpcTkv2uHaX2qNfj_43700o-XR9H6N3mAJqgSQFPaZmN0b7VrokNngHR5PhPSzBUvcX0FYEvmV4qUAWsFuw" -H "Accept: application/vnd.kubernetes.protobuf, */*" -H "Content-Type: application/vnd.kubernetes.protobuf" -H "User-Agent: kube-scheduler/v1.16.3 (linux/amd64) kubernetes/b3cbbae/scheduler" 'https://100.64.0.1:443/api/v1/namespaces/default/pods/green-k8s-test-65bb774986-bhlzx/binding'
I1220 21:37:38.824723       1 scheduling_queue.go:830] About to try and schedule pod default/green-k8s-test-65bb774986-zln6t
I1220 21:37:38.824744       1 scheduler.go:530] Attempting to schedule pod: default/green-k8s-test-65bb774986-zln6t
I1220 21:37:38.824804       1 metadata.go:238] Precompute: PredicateWithExtendedResourceOptions
I1220 21:37:38.824838       1 predicates.go:908] Schedule Pod default/green-k8s-test-65bb774986-zln6t on Node ip-172-20-40-148.ec2.internal is allowed, Node is running only 9 out of 110 Pods.
I1220 21:37:38.824849       1 generic_scheduler.go:667] since alwaysCheckAllPredicates has not been set, the predicate evaluation is short circuited and there are chances of other predicates failing as well.
I1220 21:37:38.824865       1 predicates.go:908] Schedule Pod default/green-k8s-test-65bb774986-zln6t on Node ip-172-20-58-134.ec2.internal is allowed, Node is running only 5 out of 110 Pods.
I1220 21:37:38.824876       1 predicates.go:908] Schedule Pod default/green-k8s-test-65bb774986-zln6t on Node ip-172-20-45-201.ec2.internal is allowed, Node is running only 2 out of 110 Pods.
I1220 21:37:38.824886       1 predicates.go:908] Schedule Pod default/green-k8s-test-65bb774986-zln6t on Node ip-172-20-49-41.ec2.internal is allowed, Node is running only 4 out of 110 Pods.
I1220 21:37:38.824900       1 predicates.go:908] Schedule Pod default/green-k8s-test-65bb774986-zln6t on Node ip-172-20-61-178.ec2.internal is allowed, Node is running only 4 out of 110 Pods.
I1220 21:37:38.824992       1 resource_allocation.go:84] green-k8s-test-65bb774986-zln6t -> ip-172-20-58-134.ec2.internal: BalancedResourceAllocation, map of allocatable resources map[cpu:1000 memory:1966559232], map of requested resources map[cpu:800 memory:1121976320] ,score 7,
I1220 21:37:38.825015       1 resource_allocation.go:84] green-k8s-test-65bb774986-zln6t -> ip-172-20-58-134.ec2.internal: LeastResourceAllocation, map of allocatable resources map[cpu:1000 memory:1966559232], map of requested resources map[cpu:800 memory:1121976320] ,score 3,
I1220 21:37:38.825030       1 resource_allocation.go:84] green-k8s-test-65bb774986-zln6t -> ip-172-20-45-201.ec2.internal: BalancedResourceAllocation, map of allocatable resources map[cpu:1000 memory:1966559232], map of requested resources map[cpu:350 memory:492830720] ,score 9,
I1220 21:37:38.825041       1 resource_allocation.go:84] green-k8s-test-65bb774986-zln6t -> ip-172-20-45-201.ec2.internal: LeastResourceAllocation, map of allocatable resources map[cpu:1000 memory:1966559232], map of requested resources map[cpu:350 memory:492830720] ,score 6,
I1220 21:37:38.825053       1 resource_allocation.go:84] green-k8s-test-65bb774986-zln6t -> ip-172-20-49-41.ec2.internal: BalancedResourceAllocation, map of allocatable resources map[cpu:1000 memory:1966559232], map of requested resources map[cpu:700 memory:1048576000] ,score 8,
I1220 21:37:38.825067       1 resource_allocation.go:84] green-k8s-test-65bb774986-zln6t -> ip-172-20-49-41.ec2.internal: LeastResourceAllocation, map of allocatable resources map[cpu:1000 memory:1966559232], map of requested resources map[cpu:700 memory:1048576000] ,score 3,
I1220 21:37:38.825080       1 resource_allocation.go:84] green-k8s-test-65bb774986-zln6t -> ip-172-20-61-178.ec2.internal: BalancedResourceAllocation, map of allocatable resources map[cpu:1000 memory:1966559232], map of requested resources map[cpu:520 memory:849346560] ,score 9,
I1220 21:37:38.825091       1 resource_allocation.go:84] green-k8s-test-65bb774986-zln6t -> ip-172-20-61-178.ec2.internal: LeastResourceAllocation, map of allocatable resources map[cpu:1000 memory:1966559232], map of requested resources map[cpu:520 memory:849346560] ,score 4,
I1220 21:37:38.825120       1 selector_spreading.go:146] green-k8s-test-65bb774986-zln6t -> ip-172-20-58-134.ec2.internal: SelectorSpreadPriority, Score: (0)
I1220 21:37:38.825127       1 selector_spreading.go:146] green-k8s-test-65bb774986-zln6t -> ip-172-20-45-201.ec2.internal: SelectorSpreadPriority, Score: (3)
I1220 21:37:38.825133       1 selector_spreading.go:146] green-k8s-test-65bb774986-zln6t -> ip-172-20-49-41.ec2.internal: SelectorSpreadPriority, Score: (0)
I1220 21:37:38.825139       1 selector_spreading.go:146] green-k8s-test-65bb774986-zln6t -> ip-172-20-61-178.ec2.internal: SelectorSpreadPriority, Score: (2)
I1220 21:37:38.825144       1 generic_scheduler.go:773] green-k8s-test-65bb774986-zln6t_default -> ip-172-20-58-134.ec2.internal: ServiceSpreadingPriority, Score: (0)
I1220 21:37:38.825149       1 generic_scheduler.go:773] green-k8s-test-65bb774986-zln6t_default -> ip-172-20-45-201.ec2.internal: ServiceSpreadingPriority, Score: (3)
I1220 21:37:38.825155       1 generic_scheduler.go:773] green-k8s-test-65bb774986-zln6t_default -> ip-172-20-49-41.ec2.internal: ServiceSpreadingPriority, Score: (0)
I1220 21:37:38.825160       1 generic_scheduler.go:773] green-k8s-test-65bb774986-zln6t_default -> ip-172-20-61-178.ec2.internal: ServiceSpreadingPriority, Score: (2)
I1220 21:37:38.829122       1 round_trippers.go:443] POST https://100.64.0.1:443/api/v1/namespaces/default/pods/green-k8s-test-65bb774986-bhlzx/binding 201 Created in 4 milliseconds
I1220 21:37:38.829138       1 round_trippers.go:449] Response Headers:
I1220 21:37:38.829144       1 round_trippers.go:452]     Cache-Control: no-cache, private
I1220 21:37:38.829149       1 round_trippers.go:452]     Content-Type: application/vnd.kubernetes.protobuf
I1220 21:37:38.829154       1 round_trippers.go:452]     X-Kubernetes-Pf-Flowschema-Uid: 9fb2dc3c-3c29-42f2-bb88-3d0896e45310
I1220 21:37:38.829158       1 round_trippers.go:452]     X-Kubernetes-Pf-Prioritylevel-Uid: 0d11ff8b-ca59-4914-b971-4d6f623f711b
I1220 21:37:38.829179       1 round_trippers.go:452]     Content-Length: 48
I1220 21:37:38.829188       1 round_trippers.go:452]     Date: Mon, 20 Dec 2021 21:37:38 GMT
I1220 21:37:38.829208       1 request.go:966] Response Body:
00000000  6b 38 73 00 0a 0c 0a 02  76 31 12 06 53 74 61 74  |k8s.....v1..Stat|
00000010  75 73 12 18 0a 06 0a 00  12 00 1a 00 12 07 53 75  |us............Su|
00000020  63 63 65 73 73 1a 00 22  00 30 c9 01 1a 00 22 00  |ccess..".0....".|
I1220 21:37:38.829238       1 cache.go:305] Finished binding for pod 61391937-0325-450a-a8f5-0955ca4846b7. Can be expired.
I1220 21:37:38.829263       1 event_recorder.go:54] Could not construct reference to: '<nil>' due to: 'can't reference a nil object'.
I1220 21:37:38.829290       1 scheduler.go:667] pod default/green-k8s-test-65bb774986-bhlzx is bound successfully on node "ip-172-20-49-41.ec2.internal", 5 nodes evaluated, 4 nodes were found feasible. Bound node resource: "Capacity: CPU<1>|Memory<2022868Ki>|Pods<110>|StorageEphemeral<130045936Ki>; Allocatable: CPU<1>|Memory<1920468Ki>|Pods<110>|StorageEphemeral<119850334420>.".
I1220 21:37:38.829373       1 request.go:966] Request Body:
00000000  6b 38 73 00 0a 1e 0a 15  65 76 65 6e 74 73 2e 6b  |k8s.....events.k|
00000010  38 73 2e 69 6f 2f 76 31  62 65 74 61 31 12 05 45  |8s.io/v1beta1..E|
00000020  76 65 6e 74 12 a7 03 0a  49 0a 30 67 72 65 65 6e  |vent....I.0green|
00000030  2d 6b 38 73 2d 74 65 73  74 2d 36 35 62 62 37 37  |-k8s-test-65bb77|
00000040  34 39 38 36 2d 62 68 6c  7a 78 2e 31 36 63 32 39  |4986-bhlzx.16c29|
00000050  34 34 39 63 32 34 37 37  39 62 36 12 00 1a 07 64  |449c24779b6....d|
00000060  65 66 61 75 6c 74 22 00  2a 00 32 00 38 00 42 00  |efault".*.2.8.B.|
00000070  7a 00 12 0c 08 a2 ef 83  8e 06 10 bb da b5 8b 03  |z...............|
00000080  22 13 67 72 65 65 6e 2d  6b 38 73 2d 73 63 68 65  |".green-k8s-sche|
00000090  64 75 6c 65 72 2a 37 67  72 65 65 6e 2d 6b 38 73  |duler*7green-k8s|
000000a0  2d 73 63 68 65 64 75 6c  65 72 2d 67 72 65 65 6e  |-scheduler-green|
000000b0  2d 6b 38 73 2d 73 63 68  65 64 75 6c 65 72 2d 38  |-k8s-scheduler-8|
000000c0  63 62 37 66 37 37 37 39  2d 37 63 34 64 6c 32 07  |cb7f7779-7c4dl2.|
000000d0  42 69 6e 64 69 6e 67 3a  09 53 63 68 65 64 75 6c  |Binding:.Schedul|
000000e0  65 64 42 64 0a 03 50 6f  64 12 07 64 65 66 61 75  |edBd..Pod..defau|
000000f0  6c 74 1a 1f 67 72 65 65  6e 2d 6b 38 73 2d 74 65  |lt..green-k8s-te|
00000100  73 74 2d 36 35 62 62 37  37 34 39 38 36 2d 62 68  |st-65bb774986-bh|
00000110  6c 7a 78 22 24 36 31 33  39 31 39 33 37 2d 30 33  |lzx"$61391937-03|
00000120  32 35 2d 34 35 30 61 2d  61 38 66 35 2d 30 39 35  |25-450a-a8f5-095|
00000130  35 63 61 34 38 34 36 62  37 2a 02 76 31 32 07 31  |5ca4846b7*.v12.1|
00000140  34 31 37 32 35 37 3a 00  52 5d 53 75 63 63 65 73  |417257:.R]Succes|
00000150  73 66 75 6c 6c 79 20 61  73 73 69 67 6e 65 64 20  |sfully assigned |
00000160  64 65 66 61 75 6c 74 2f  67 72 65 65 6e 2d 6b 38  |default/green-k8|
00000170  73 2d 74 65 73 74 2d 36  35 62 62 37 37 34 39 38  |s-test-65bb77498|
00000180  36 2d 62 68 6c 7a 78 20  74 6f 20 69 70 2d 31 37  |6-bhlzx to ip-17|
00000190  32 2d 32 30 2d 34 39 2d  34 31 2e 65 63 32 2e 69  |2-20-49-41.ec2.i|
000001a0  6e 74 65 72 6e 61 6c 5a  06 4e 6f 72 6d 61 6c 62  |nternalZ.Normalb|
000001b0  17 0a 13 67 72 65 65 6e  2d 6b 38 73 2d 73 63 68  |...green-k8s-sch|
000001c0  65 64 75 6c 65 72 12 00  6a 00 72 00 78 00 1a 00  |eduler..j.r.x...|
000001d0  22 00                                             |".|
I1220 21:37:38.829440       1 round_trippers.go:423] curl -k -v -XPOST  -H "User-Agent: kube-scheduler/v1.16.3 (linux/amd64) kubernetes/b3cbbae/scheduler" -H "Authorization: Bearer eyJhbGciOiJSUzI1NiIsImtpZCI6IkI2d0Zpc0Q2S2pFdmhUX3hsRG5GZFdLemMtRkhWWmxiQmszcGVmc3RsdjQifQ.eyJhdWQiOlsia3ViZXJuZXRlcy5zdmMuZGVmYXVsdCJdLCJleHAiOjE2NzE1NzE2OTYsImlhdCI6MTY0MDAzNTY5NiwiaXNzIjoiaHR0cHM6Ly9hcGkuaW50ZXJuYWwuaGEuZ3JlZW5rOHMuY29tIiwia3ViZXJuZXRlcy5pbyI6eyJuYW1lc3BhY2UiOiJrdWJlLXN5c3RlbSIsInBvZCI6eyJuYW1lIjoiZ3JlZW4tazhzLXNjaGVkdWxlci04Y2I3Zjc3NzktN2M0ZGwiLCJ1aWQiOiIyODMwY2IxNS05OTM2LTQ3YjAtYTlhOS0wNjVlOTdmZDU2NGIifSwic2VydmljZWFjY291bnQiOnsibmFtZSI6ImdyZWVuLWs4cy1zY2hlZHVsZXIiLCJ1aWQiOiI2NzgyMTEwNC01NGFiLTQ2YzctYTQ3NC00YjhlODI3M2UyZWYifSwid2FybmFmdGVyIjoxNjQwMDM5MzAzfSwibmJmIjoxNjQwMDM1Njk2LCJzdWIiOiJzeXN0ZW06c2VydmljZWFjY291bnQ6a3ViZS1zeXN0ZW06Z3JlZW4tazhzLXNjaGVkdWxlciJ9.QzO_AZGr2BvZ_-W2I_yCM5mU-rv4-LxvAuo3IXheOxojip-51tgqkELWPgYJgclwuIc5ftd3gEq-qU2_O5xtFjARjpRcNzgwZedg4Yl9ZTelqQG5ZpHsE2DpvOTBB8QlcKNAYkinz7g0SSnfBJsIa8ypV9k5eSwKNSH8-2xikYWnfE0tKV9fsJiQAO1BBDZt0L8eiChCiCh3yeR7cPykyfCSSdeLfG0Ycs7yTyo0rKEMWArzdw4ZqJzqtlyuof8EGT-lpcTkv2uHaX2qNfj_43700o-XR9H6N3mAJqgSQFPaZmN0b7VrokNngHR5PhPSzBUvcX0FYEvmV4qUAWsFuw" -H "Content-Type: application/vnd.kubernetes.protobuf" -H "Accept: application/vnd.kubernetes.protobuf, */*" 'https://100.64.0.1:443/apis/events.k8s.io/v1beta1/namespaces/default/events'
I1220 21:37:38.832089       1 round_trippers.go:443] POST https://100.64.0.1:443/apis/events.k8s.io/v1beta1/namespaces/default/events 201 Created in 2 milliseconds
I1220 21:37:38.832175       1 round_trippers.go:449] Response Headers:
I1220 21:37:38.832189       1 round_trippers.go:452]     Content-Type: application/vnd.kubernetes.protobuf
I1220 21:37:38.832195       1 round_trippers.go:452]     X-Kubernetes-Pf-Flowschema-Uid: 9fb2dc3c-3c29-42f2-bb88-3d0896e45310
I1220 21:37:38.832199       1 round_trippers.go:452]     X-Kubernetes-Pf-Prioritylevel-Uid: 0d11ff8b-ca59-4914-b971-4d6f623f711b
I1220 21:37:38.832204       1 round_trippers.go:452]     Content-Length: 863
I1220 21:37:38.832208       1 round_trippers.go:452]     Date: Mon, 20 Dec 2021 21:37:38 GMT
I1220 21:37:38.832213       1 round_trippers.go:452]     Cache-Control: no-cache, private
I1220 21:37:38.832259       1 request.go:966] Response Body:
00000000  6b 38 73 00 0a 1e 0a 15  65 76 65 6e 74 73 2e 6b  |k8s.....events.k|
00000010  38 73 2e 69 6f 2f 76 31  62 65 74 61 31 12 05 45  |8s.io/v1beta1..E|
00000020  76 65 6e 74 12 b4 06 0a  d5 03 0a 30 67 72 65 65  |vent.......0gree|
00000030  6e 2d 6b 38 73 2d 74 65  73 74 2d 36 35 62 62 37  |n-k8s-test-65bb7|
00000040  37 34 39 38 36 2d 62 68  6c 7a 78 2e 31 36 63 32  |74986-bhlzx.16c2|
00000050  39 34 34 39 63 32 34 37  37 39 62 36 12 00 1a 07  |9449c24779b6....|
00000060  64 65 66 61 75 6c 74 22  00 2a 24 34 35 65 33 35  |default".*$45e35|
00000070  33 33 31 2d 31 35 66 30  2d 34 64 31 62 2d 38 61  |331-15f0-4d1b-8a|
00000080  33 38 2d 30 64 36 30 32  64 30 38 65 34 32 30 32  |38-0d602d08e4202|
00000090  04 32 37 31 33 38 00 42  08 08 a2 ef 83 8e 06 10  |.27138.B........|
000000a0  00 7a 00 8a 01 d8 02 0a  0e 6b 75 62 65 2d 73 63  |.z.......kube-sc|
000000b0  68 65 64 75 6c 65 72 12  06 55 70 64 61 74 65 1a  |heduler..Update.|
000000c0  15 65 76 65 6e 74 73 2e  6b 38 73 2e 69 6f 2f 76  |.events.k8s.io/v|
000000d0  31 62 65 74 61 31 22 08  08 a2 ef 83 8e 06 10 00  |1beta1".........|
000000e0  32 08 46 69 65 6c 64 73  56 31 3a 92 02 0a 8f 02  |2.FieldsV1:.....|
000000f0  7b 22 66 3a 61 63 74 69  6f 6e 22 3a 7b 7d 2c 22  |{"f:action":{},"|
00000100  66 3a 64 65 70 72 65 63  61 74 65 64 53 6f 75 72  |f:deprecatedSour|
00000110  63 65 22 3a 7b 22 66 3a  63 6f 6d 70 6f 6e 65 6e  |ce":{"f:componen|
00000120  74 22 3a 7b 7d 7d 2c 22  66 3a 65 76 65 6e 74 54  |t":{}},"f:eventT|
00000130  69 6d 65 22 3a 7b 7d 2c  22 66 3a 6e 6f 74 65 22  |ime":{},"f:note"|
00000140  3a 7b 7d 2c 22 66 3a 72  65 61 73 6f 6e 22 3a 7b  |:{},"f:reason":{|
00000150  7d 2c 22 66 3a 72 65 67  61 72 64 69 6e 67 22 3a  |},"f:regarding":|
00000160  7b 22 66 3a 61 70 69 56  65 72 73 69 6f 6e 22 3a  |{"f:apiVersion":|
00000170  7b 7d 2c 22 66 3a 6b 69  6e 64 22 3a 7b 7d 2c 22  |{},"f:kind":{},"|
00000180  66 3a 6e 61 6d 65 22 3a  7b 7d 2c 22 66 3a 6e 61  |f:name":{},"f:na|
00000190  6d 65 73 70 61 63 65 22  3a 7b 7d 2c 22 66 3a 72  |mespace":{},"f:r|
000001a0  65 73 6f 75 72 63 65 56  65 72 73 69 6f 6e 22 3a  |esourceVersion":|
000001b0  7b 7d 2c 22 66 3a 75 69  64 22 3a 7b 7d 7d 2c 22  |{},"f:uid":{}},"|
000001c0  66 3a 72 65 70 6f 72 74  69 6e 67 43 6f 6e 74 72  |f:reportingContr|
000001d0  6f 6c 6c 65 72 22 3a 7b  7d 2c 22 66 3a 72 65 70  |oller":{},"f:rep|
000001e0  6f 72 74 69 6e 67 49 6e  73 74 61 6e 63 65 22 3a  |ortingInstance":|
000001f0  7b 7d 2c 22 66 3a 74 79  70 65 22 3a 7b 7d 7d 12  |{},"f:type":{}}.|
00000200  0c 08 a2 ef 83 8e 06 10  bb da b5 8b 03 22 13 67  |.............".g|
00000210  72 65 65 6e 2d 6b 38 73  2d 73 63 68 65 64 75 6c  |reen-k8s-schedul|
00000220  65 72 2a 37 67 72 65 65  6e 2d 6b 38 73 2d 73 63  |er*7green-k8s-sc|
00000230  68 65 64 75 6c 65 72 2d  67 72 65 65 6e 2d 6b 38  |heduler-green-k8|
00000240  73 2d 73 63 68 65 64 75  6c 65 72 2d 38 63 62 37  |s-scheduler-8cb7|
00000250  66 37 37 37 39 2d 37 63  34 64 6c 32 07 42 69 6e  |f7779-7c4dl2.Bin|
00000260  64 69 6e 67 3a 09 53 63  68 65 64 75 6c 65 64 42  |ding:.ScheduledB|
00000270  64 0a 03 50 6f 64 12 07  64 65 66 61 75 6c 74 1a  |d..Pod..default.|
00000280  1f 67 72 65 65 6e 2d 6b  38 73 2d 74 65 73 74 2d  |.green-k8s-test-|
00000290  36 35 62 62 37 37 34 39  38 36 2d 62 68 6c 7a 78  |65bb774986-bhlzx|
000002a0  22 24 36 31 33 39 31 39  33 37 2d 30 33 32 35 2d  |"$61391937-0325-|
000002b0  34 35 30 61 2d 61 38 66  35 2d 30 39 35 35 63 61  |450a-a8f5-0955ca|
000002c0  34 38 34 36 62 37 2a 02  76 31 32 07 31 34 31 37  |4846b7*.v12.1417|
000002d0  32 35 37 3a 00 52 5d 53  75 63 63 65 73 73 66 75  |257:.R]Successfu|
000002e0  6c 6c 79 20 61 73 73 69  67 6e 65 64 20 64 65 66  |lly assigned def|
000002f0  61 75 6c 74 2f 67 72 65  65 6e 2d 6b 38 73 2d 74  |ault/green-k8s-t|
00000300  65 73 74 2d 36 35 62 62  37 37 34 39 38 36 2d 62  |est-65bb774986-b|
00000310  68 6c 7a 78 20 74 6f 20  69 70 2d 31 37 32 2d 32  |hlzx to ip-172-2|
00000320  30 2d 34 39 2d 34 31 2e  65 63 32 2e 69 6e 74 65  |0-49-41.ec2.inte|
00000330  72 6e 61 6c 5a 06 4e 6f  72 6d 61 6c 62 17 0a 13  |rnalZ.Normalb...|
00000340  67 72 65 65 6e 2d 6b 38  73 2d 73 63 68 65 64 75  |green-k8s-schedu|
00000350  6c 65 72 12 00 6a 00 72  00 78 00 1a 00 22 00     |ler..j.r.x...".|
I1220 21:37:38.842672       1 generic_scheduler.go:822] green-k8s-test-65bb774986-zln6t_default -> ip-172-20-58-134.ec2.internal: http://localhost:80, Score: (10)
I1220 21:37:38.842696       1 generic_scheduler.go:822] green-k8s-test-65bb774986-zln6t_default -> ip-172-20-45-201.ec2.internal: http://localhost:80, Score: (0)
I1220 21:37:38.842703       1 generic_scheduler.go:822] green-k8s-test-65bb774986-zln6t_default -> ip-172-20-49-41.ec2.internal: http://localhost:80, Score: (10)
I1220 21:37:38.842708       1 generic_scheduler.go:822] green-k8s-test-65bb774986-zln6t_default -> ip-172-20-61-178.ec2.internal: http://localhost:80, Score: (6)
I1220 21:37:38.842719       1 generic_scheduler.go:838] Host ip-172-20-58-134.ec2.internal => Score 21
I1220 21:37:38.842725       1 generic_scheduler.go:838] Host ip-172-20-45-201.ec2.internal => Score 19
I1220 21:37:38.842845       1 generic_scheduler.go:838] Host ip-172-20-49-41.ec2.internal => Score 22
I1220 21:37:38.842851       1 generic_scheduler.go:838] Host ip-172-20-61-178.ec2.internal => Score 22
I1220 21:37:38.842897       1 scheduler_binder.go:256] AssumePodVolumes for pod "default/green-k8s-test-65bb774986-zln6t", node "ip-172-20-61-178.ec2.internal"
I1220 21:37:38.842913       1 scheduler_binder.go:266] AssumePodVolumes for pod "default/green-k8s-test-65bb774986-zln6t", node "ip-172-20-61-178.ec2.internal": all PVCs bound and nothing to do
I1220 21:37:38.842977       1 factory.go:610] Attempting to bind green-k8s-test-65bb774986-zln6t to ip-172-20-61-178.ec2.internal
I1220 21:37:38.843078       1 request.go:966] Request Body:
00000000  6b 38 73 00 0a 0d 0a 02  76 31 12 07 42 69 6e 64  |k8s.....v1..Bind|
00000010  69 6e 67 12 8f 01 0a 5c  0a 1f 67 72 65 65 6e 2d  |ing....\..green-|
00000020  6b 38 73 2d 74 65 73 74  2d 36 35 62 62 37 37 34  |k8s-test-65bb774|
00000030  39 38 36 2d 7a 6c 6e 36  74 12 00 1a 07 64 65 66  |986-zln6t....def|
00000040  61 75 6c 74 22 00 2a 24  65 64 39 32 66 62 64 62  |ault".*$ed92fbdb|
00000050  2d 65 66 34 37 2d 34 64  36 37 2d 38 61 31 32 2d  |-ef47-4d67-8a12-|
00000060  66 61 31 36 33 33 62 35  65 35 34 35 32 00 38 00  |fa1633b5e5452.8.|
00000070  42 00 7a 00 12 2f 0a 04  4e 6f 64 65 12 00 1a 1d  |B.z../..Node....|
00000080  69 70 2d 31 37 32 2d 32  30 2d 36 31 2d 31 37 38  |ip-172-20-61-178|
00000090  2e 65 63 32 2e 69 6e 74  65 72 6e 61 6c 22 00 2a  |.ec2.internal".*|
000000a0  00 32 00 3a 00 1a 00 22  00                       |.2.:...".|
I1220 21:37:38.843318       1 round_trippers.go:423] curl -k -v -XPOST  -H "Content-Type: application/vnd.kubernetes.protobuf" -H "Accept: application/vnd.kubernetes.protobuf, */*" -H "User-Agent: kube-scheduler/v1.16.3 (linux/amd64) kubernetes/b3cbbae/scheduler" -H "Authorization: Bearer eyJhbGciOiJSUzI1NiIsImtpZCI6IkI2d0Zpc0Q2S2pFdmhUX3hsRG5GZFdLemMtRkhWWmxiQmszcGVmc3RsdjQifQ.eyJhdWQiOlsia3ViZXJuZXRlcy5zdmMuZGVmYXVsdCJdLCJleHAiOjE2NzE1NzE2OTYsImlhdCI6MTY0MDAzNTY5NiwiaXNzIjoiaHR0cHM6Ly9hcGkuaW50ZXJuYWwuaGEuZ3JlZW5rOHMuY29tIiwia3ViZXJuZXRlcy5pbyI6eyJuYW1lc3BhY2UiOiJrdWJlLXN5c3RlbSIsInBvZCI6eyJuYW1lIjoiZ3JlZW4tazhzLXNjaGVkdWxlci04Y2I3Zjc3NzktN2M0ZGwiLCJ1aWQiOiIyODMwY2IxNS05OTM2LTQ3YjAtYTlhOS0wNjVlOTdmZDU2NGIifSwic2VydmljZWFjY291bnQiOnsibmFtZSI6ImdyZWVuLWs4cy1zY2hlZHVsZXIiLCJ1aWQiOiI2NzgyMTEwNC01NGFiLTQ2YzctYTQ3NC00YjhlODI3M2UyZWYifSwid2FybmFmdGVyIjoxNjQwMDM5MzAzfSwibmJmIjoxNjQwMDM1Njk2LCJzdWIiOiJzeXN0ZW06c2VydmljZWFjY291bnQ6a3ViZS1zeXN0ZW06Z3JlZW4tazhzLXNjaGVkdWxlciJ9.QzO_AZGr2BvZ_-W2I_yCM5mU-rv4-LxvAuo3IXheOxojip-51tgqkELWPgYJgclwuIc5ftd3gEq-qU2_O5xtFjARjpRcNzgwZedg4Yl9ZTelqQG5ZpHsE2DpvOTBB8QlcKNAYkinz7g0SSnfBJsIa8ypV9k5eSwKNSH8-2xikYWnfE0tKV9fsJiQAO1BBDZt0L8eiChCiCh3yeR7cPykyfCSSdeLfG0Ycs7yTyo0rKEMWArzdw4ZqJzqtlyuof8EGT-lpcTkv2uHaX2qNfj_43700o-XR9H6N3mAJqgSQFPaZmN0b7VrokNngHR5PhPSzBUvcX0FYEvmV4qUAWsFuw" 'https://100.64.0.1:443/api/v1/namespaces/default/pods/green-k8s-test-65bb774986-zln6t/binding'
I1220 21:37:38.847621       1 round_trippers.go:443] POST https://100.64.0.1:443/api/v1/namespaces/default/pods/green-k8s-test-65bb774986-zln6t/binding 201 Created in 4 milliseconds
I1220 21:37:38.847693       1 round_trippers.go:449] Response Headers:
I1220 21:37:38.847798       1 round_trippers.go:452]     Cache-Control: no-cache, private
I1220 21:37:38.847888       1 round_trippers.go:452]     Content-Type: application/vnd.kubernetes.protobuf
I1220 21:37:38.847930       1 round_trippers.go:452]     X-Kubernetes-Pf-Flowschema-Uid: 9fb2dc3c-3c29-42f2-bb88-3d0896e45310
I1220 21:37:38.851347       1 round_trippers.go:452]     X-Kubernetes-Pf-Prioritylevel-Uid: 0d11ff8b-ca59-4914-b971-4d6f623f711b
I1220 21:37:38.851367       1 round_trippers.go:452]     Content-Length: 48
I1220 21:37:38.851373       1 round_trippers.go:452]     Date: Mon, 20 Dec 2021 21:37:38 GMT
I1220 21:37:38.851519       1 request.go:966] Response Body:
00000000  6b 38 73 00 0a 0c 0a 02  76 31 12 06 53 74 61 74  |k8s.....v1..Stat|
00000010  75 73 12 18 0a 06 0a 00  12 00 1a 00 12 07 53 75  |us............Su|
00000020  63 63 65 73 73 1a 00 22  00 30 c9 01 1a 00 22 00  |ccess..".0....".|
I1220 21:37:38.851691       1 cache.go:305] Finished binding for pod ed92fbdb-ef47-4d67-8a12-fa1633b5e545. Can be expired.
I1220 21:37:38.851733       1 event_recorder.go:54] Could not construct reference to: '<nil>' due to: 'can't reference a nil object'.
I1220 21:37:38.851817       1 scheduler.go:667] pod default/green-k8s-test-65bb774986-zln6t is bound successfully on node "ip-172-20-61-178.ec2.internal", 5 nodes evaluated, 4 nodes were found feasible. Bound node resource: "Capacity: CPU<1>|Memory<2022868Ki>|Pods<110>|StorageEphemeral<130045936Ki>; Allocatable: CPU<1>|Memory<1920468Ki>|Pods<110>|StorageEphemeral<119850334420>.".
I1220 21:37:38.851944       1 request.go:966] Request Body: